Workbook
Name ________________________________________________________________________________________________________ERR1: {#N/A,#N/A,FALSE,"M.42"}
Name ________________________________________________________________________________________________________ERR1: {#N/A,#N/A,FALSE,"M.42"}
Name ________________________________________________________________________________________________________ERR1: {#N/A,#N/A,FALSE,"M.42"}
Name ________________________________________________________________________________________________________ERR1: {#N/A,#N/A,FALSE,"M.42"}
Name ________________________________________________________________________________________________________ERR1: {#N/A,#N/A,FALSE,"M.42"}
Name ________________________________________________________________________________________________________ERR1: {#N/A,#N/A,FALSE,"M.42"}
Name ________________________________________________________________________________________________________ERR1: {#N/A,#N/A,FALSE,"M.42"}
Name ________________________________________________________________________________________________________ERR1: {#N/A,#N/A,FALSE,"M.42"}
Name ________________________________________________________________________________________________________ERR1: {#N/A,#N/A,FALSE,"M.42"}
Name ________________________________________________________________________________________________________ERR1: {#N/A,#N/A,FALSE,"M.42"}
Name ________________________________________________________________________________________________________ERR1: {#N/A,#N/A,FALSE,"M.42"}
Name ________________________________________________________________________________________________________ERR1: {#N/A,#N/A,FALSE,"M.42"}
Name ________________________________________________________________________________________________________ERR1: {#N/A,#N/A,FALSE,"M.42"}
Name ________________________________________________________________________________________________________ERR1: {#N/A,#N/A,FALSE,"M.42"}
Name ________________________________________________________________________________________________________ERR1: {#N/A,#N/A,FALSE,"M.42"}
Name ________________________________________________________________________________________________________ERR1: {#N/A,#N/A,FALSE,"M.42"}
Name ________________________________________________________________________________________________________ERR1: {#N/A,#N/A,FALSE,"M.42"}
Name ______________________________________________________________________________________________________ERR1: {#N/A,#N/A,FALSE,"M.42"}
Name ______________________________________________________________________________________________________ERR1: {#N/A,#N/A,FALSE,"M.42"}
Name ______________________________________________________________________________________________________ERR1: {#N/A,#N/A,FALSE,"M.42"}
Name ______________________________________________________________________________________________________ERR1: {#N/A,#N/A,FALSE,"M.42"}
Name ______________________________________________________________________________________________________ERR1: {#N/A,#N/A,FALSE,"M.42"}
Name ______________________________________________________________________________________________________ERR1: {#N/A,#N/A,FALSE,"M.42"}
Name ______________________________________________________________________________________________________ERR1: {#N/A,#N/A,FALSE,"M.42"}
Name ______________________________________________________________________________________________________ERR1: {#N/A,#N/A,FALSE,"M.42"}
Name ______________________________________________________________________________________________________ERR1: {#N/A,#N/A,FALSE,"M.42"}
Name ______________________________________________________________________________________________________ERR1: {#N/A,#N/A,FALSE,"M.42"}
Name ______________________________________________________________________________________________________ERR1: {#N/A,#N/A,FALSE,"M.42"}
Name ______________________________________________________________________________________________________ERR1: {#N/A,#N/A,FALSE,"M.42"}
Name ______________________________________________________________________________________________________ERR1: {#N/A,#N/A,FALSE,"M.42"}
Name ______________________________________________________________________________________________________ERR1: {#N/A,#N/A,FALSE,"M.42"}
Name ______________________________________________________________________________________________________ERR1: {#N/A,#N/A,FALSE,"M.42"}
Name ______________________________________________________________________________________________________ERR1: {#N/A,#N/A,FALSE,"M.42"}
Name ______________________________________________________________________________________________________ERR1: {#N/A,#N/A,FALSE,"M.42"}
Name ____________________________________________________________________________________________________ERR1: {#N/A,#N/A,FALSE,"M.42"}
Name ____________________________________________________________________________________________________ERR1: {#N/A,#N/A,FALSE,"M.42"}
Name ____________________________________________________________________________________________________ERR1: {#N/A,#N/A,FALSE,"M.42"}
Name ____________________________________________________________________________________________________ERR1: {#N/A,#N/A,FALSE,"M.42"}
Name ____________________________________________________________________________________________________ERR1: {#N/A,#N/A,FALSE,"M.42"}
Name ____________________________________________________________________________________________________ERR1: {#N/A,#N/A,FALSE,"M.42"}
Name ____________________________________________________________________________________________________ERR1: {#N/A,#N/A,FALSE,"M.42"}
Name ____________________________________________________________________________________________________ERR1: {#N/A,#N/A,FALSE,"M.42"}
Name ____________________________________________________________________________________________________ERR1: {#N/A,#N/A,FALSE,"M.42"}
Name ____________________________________________________________________________________________________ERR1: {#N/A,#N/A,FALSE,"M.42"}
Name ____________________________________________________________________________________________________ERR1: {#N/A,#N/A,FALSE,"M.42"}
Name ____________________________________________________________________________________________________ERR1: {#N/A,#N/A,FALSE,"M.42"}
Name ____________________________________________________________________________________________________ERR1: {#N/A,#N/A,FALSE,"M.42"}
Name ____________________________________________________________________________________________________ERR1: {#N/A,#N/A,FALSE,"M.42"}
Name ____________________________________________________________________________________________________ERR1: {#N/A,#N/A,FALSE,"M.42"}
Name ____________________________________________________________________________________________________ERR1: {#N/A,#N/A,FALSE,"M.42"}
Name ____________________________________________________________________________________________________ERR1: {#N/A,#N/A,FALSE,"M.42"}
Name __________________________________________________________________________________________________ERR1: {#N/A,#N/A,FALSE,"M.42"}
Name __________________________________________________________________________________________________ERR1: {#N/A,#N/A,FALSE,"M.42"}
Name __________________________________________________________________________________________________ERR1: {#N/A,#N/A,FALSE,"M.42"}
Name __________________________________________________________________________________________________ERR1: {#N/A,#N/A,FALSE,"M.42"}
Name __________________________________________________________________________________________________ERR1: {#N/A,#N/A,FALSE,"M.42"}
Name __________________________________________________________________________________________________ERR1: {#N/A,#N/A,FALSE,"M.42"}
Name __________________________________________________________________________________________________ERR1: {#N/A,#N/A,FALSE,"M.42"}
Name __________________________________________________________________________________________________ERR1: {#N/A,#N/A,FALSE,"M.42"}
Name __________________________________________________________________________________________________ERR1: {#N/A,#N/A,FALSE,"M.42"}

Sheet RKA 2024
C1: MENJADI
A2: LEMBAGA LAYANAN PENDIDIKAN TINGGI WILAYAH III | F2: =F5+F253 -> 464536956000
A3: KODE | B3: DESKRIPSI | C3: Volume | D3: SATUAN | E3: Harga Satuan | F3: Jumlah Biaya
A5: 023.01.DK | B5: Program Pendidikan Tinggi | F5: =F6 -> 378437225000
A6: 4472 | B6: Pembinaan Kelembagaan Pendidikan Tinggi | F6: =F7+F211 -> 378437225000
A7: 4472.BDB | B7: Fasilitasi dan Pembinaan Lembaga[Base Line] | F7: =F8+F175 -> 7180935000
A8: 4472.BDB.001 | B8: Lembaga Pendidikan Tinggi Akademik dan Vokasi yang mendapatkan layanan pembinaan peningkatan mutu | F8: =F9+F19+F133+F154 -> 6630583000
A9: 051 | B9: Pembinaan dan Evaluasi Lapangan Pengendalian Perguruan Tinggi | F9: =F10 -> 515996000
A10: A | B10: Monitoring, Evaluasi, dan Penataan Legalitas PTS | F10: =F11+F13+F15+F17 -> 515996000
A11: 521211 | B11: Belanja Bahan | F11: =F12 -> 789000
B12: - Konsumsi/Snack/Seminar Kit/Penjlidan dan Penggandaan/Spanduk/Sertifikat | C12: 1 | D12: KEG | E12: 789000 | F12: =C12*E12 -> 789000
A13: 521213 | B13: Belanja Honor Output Kegiatan | F13: =F14 -> 6707000
B14: - Honorarium Panitia | C14: 19 | D14: OK | E14: 353000 | F14: =C14*E14 -> 6707000
A15: 522151 | B15: Belanja Jasa Profesi | F15: =F16 -> 1000000
B16: - Honorarium Narasumber/Moderator | C16: 1 | D16: OJ | E16: 1000000 | F16: =C16*E16 -> 1000000
A17: 524113 | B17: Belanja Perjalanan Dinas Dalam Kota | F17: =F18 -> 507500000
B18: - Biaya Perjalanan Dinas Dalam Kota | C18: 1450 | D18: OK | E18: 350000 | F18: =C18*E18 -> 507500000
A19: 052 | B19: Workshop/Sosialisasi/Bimbingan Teknis Peningkatan Mutu Perguruan Tinggi | F19: =F20+F32+F38+F55+F71+F89+F105+F118 -> 3272979000
A20: A | B20: Workshop/Sosialisasi/Bimbingan Teknis Peningkatan Mutu Perguruan Tinggi | F20: =F21+F24+F26+F28+F30 -> 42582000
A21: 521211 | B21: Belanja Bahan | F21: =SUM(F22:F23) -> 26712000
B22: - Konsumsi/Snack/Seminar Kit/Penjlidan dan Penggandaan/Spanduk/Sertifikat | C22: 1 | D22: KEG | E22: 21360000 | F22: =C22*E22 -> 21360000
B23: - Konsumsi/Snack | C23: 223 | D23: OK | E23: 24000 | F23: =C23*E23 -> 5352000
A24: 521213 | B24: Belanja Honor Output Kegiatan | F24: =F25 -> 3850000
B25: - Honorarium Panitia | C25: 10 | D25: OB | E25: 385000 | F25: =C25*E25 -> 3850000
A26: 521219 | B26: Belanja Barang Non Operasional Lainnya | F26: =F27 -> 2000000
B27: - Penggantian biaya pemeliharaan gedung kampus | C27: 1 | D27: KEG | E27: 2000000 | F27: =C27*E27 -> 2000000
A28: 522151 | B28: Belanja Jasa Profesi | F28: =F29 -> 3600000
B29: - Honorarium Narasumber/Moderator | C29: 4 | D29: OJ | E29: 900000 | F29: =C29*E29 -> 3600000
A30: 524113 | B30: Belanja Perjalanan Dinas Dalam Kota | F30: =F31 -> 6420000
B31: - Biaya Perjalanan Dinas Dalam Kota | C31: 20 | D31: OK | E31: 321000 | F31: =C31*E31 -> 6420000
A32: B | B32: Penilaian Angka Kredit Dosen dan Kegiatan Pendukung Karir Dosen | F32: =F33+F35 -> 570668000
A33: 521211 | B33: Belanja Bahan | F33: =SUM(F34:F34) -> 668000
B34: - Konsumsi/Snack/Seminar Kit/Penjlidan dan Penggandaan/Spanduk/Sertifikat | C34: 1 | D34: KEG | E34: 668000 | F34: =C34*E34 -> 668000
A35: 522151 | B35: Belanja Jasa Profesi | F35: =SUM(F36:F37) -> 570000000
B36: - Honorarium Tim PAK Nasional (LK) [72 ORG x 12 KEG] | C36: 1080 | D36: OJ | E36: 250000 | F36: =C36*E36 -> 270000000
B37: - Honorarium Tim PAK Nasional (GB) [50 ORG x 12 KEG] | C37: 600 | D37: OJ | E37: 500000 | F37: =C37*E37 -> 300000000
A38: C | B38: Penguatan Kemandirian Merdeka Belajar Kampus Merdeka | F38: =F39+F42+F44+F47+F49+F51+F53 -> 873613000
A39: 521211 | B39: Belanja Bahan | F39: =SUM(F40:F41) -> 255442000
B40: - Konsumsi/Snack/Seminar Kit/Penjlidan dan Penggandaan/Spanduk/Sertifikat | C40: 6 | D40: KEG | E40: 42265000 | F40: =C40*E40 -> 253590000
B41: - Spanduk dan Media Publikasi Lainnya | C41: 1 | D41: PKT | E41: 1852000 | F41: =C41*E41 -> 1852000
...

Sheet RAB Full 2026
C1: MENJADI
A2: LEMBAGA LAYANAN PENDIDIKAN TINGGI WILAYAH III | F2: =F5+F402 -> 462058409000
A3: KODE | B3: DESKRIPSI | C3: Volume | D3: SATUAN | E3: Harga Satuan | F3: Jumlah Biaya
A5: 023.01.DK | B5: Program Pendidikan Tinggi | F5: =F6 -> 374468798000
A6: 4472 | B6: Pembinaan Kelembagaan Pendidikan Tinggi | F6: =F7+F360 -> 374468798000
A7: 4472.BDB | B7: Fasilitasi dan Pembinaan Lembaga[Base Line] | F7: =F8+F301 -> 6610725000
A8: 4472.BDB.001 | B8: Lembaga Pendidikan Tinggi Akademik dan Vokasi yang mendapatkan layanan pembinaan peningkatan mutu | F8: =F9+F36+F203+F250 -> 6200373000 | G8: =#REF!-F8 -> #REF!
A9: 051 | B9: Pembinaan dan Evaluasi Lapangan Pengendalian Perguruan Tinggi | F9: =F10 -> 527592000
A10: A | B10: Monitoring, Evaluasi, dan Penataan Legalitas PTS | F10: =F11+F17+F22+F25+F33 -> 527592000
A11: 521211 | B11: Belanja Bahan | F11: =SUM(F12:F16) -> 71420000
B12: - 01 Makan Rapat Biasa D.K.I. JAKARTA [150 ORG x 5KL] | C12: 750 | D12: OK | E12: 57000 | F12: =C12*E12 -> 42750000
B13: - 02 Snack Rapat Biasa D.K.I. JAKARTA [150 ORG x 5 KL] | C13: 750 | D13: OK | E13: 24000 | F13: =C13*E13 -> 18000000
B14: - 03 Bahan Habis Pakai | C14: 1 | D14: KEG | E14: =778000-108000 -> 670000 | F14: =C14*E14 -> 670000
B15: - 05 Spanduk dan Media Publikasi Lainnya | C15: 5 | D15: KEG | E15: 1000000 | F15: =C15*E15 -> 5000000
B16: - 06 Penggandaan dan Penjilidan Laporan | C16: 5 | D16: KEG | E16: 1000000 | F16: =C16*E16 -> 5000000
A17: 521213 | B17: Belanja Honor Output Kegiatan | F17: =SUM(F18:F21) -> 23750000
B18: - 01 Honorarium Penanggung Jawab Panitia Seminar/Rakor/Sosialisai/Diseminasi/FGD (1 ORG x 5 KL) | C18: 5 | D18: OK | E18: 450000 | F18: =C18*E18 -> 2250000
B19: - 02 Honorarium Ketua/Wakil ketua Panitia Seminar/Rakor/Sosialisai/Diseminasi/FGD (1 ORG x 5 KL) | C19: 5 | D19: OK | E19: 400000 | F19: =C19*E19 -> 2000000
B20: - 03 Honorarium Sekretaris Panitia Seminar/Rakor/Sosialisai/Diseminasi/FGD (1 ORG x 5 KL) | C20: 5 | D20: OK | E20: 300000 | F20: =C20*E20 -> 1500000
B21: - 04 Honorarium Anggota Panitia Seminar/Rakor/Sosialisai/Diseminasi/FGD (12 ORG x 5 KL) | C21: 60 | D21: OK | E21: 300000 | F21: =C21*E21 -> 18000000
A22: 522151 | B22: Belanja Jasa Profesi | F22: =SUM(F23:F24) -> 70500000
B23: - 01 Honorarium Narasumber (Pejabat Eselon II) [4 ORG x 3 JAM x 5 KEG] | C23: 60 | D23: OJ | E23: 1000000 | F23: =C23*E23 -> 60000000
B24: - 02 Honorarium Moderator [3 ORG x 5 KEG] | C24: 15 | D24: ORKAL | E24: 700000 | F24: =C24*E24 -> 10500000
A25: 524111 | B25: Belanja Perjalanan Dinas Biasa | F25: =SUM(F26:F32) -> 118722000
B26: - 01 Uang Harian Perjalanan Dinas Luar Kota (Jawa Barat) [8 ORG x 1 TIM x 1 HARI x 6 PT] | C26: 48 | D26: OH | E26: 430000 | F26: =C26*E26 -> 20640000
B27: - 02 Satuan biaya transportasi jakarta ke kota bekasi [8 ORG x 1 TIM x 2 KL x 6 PT] | C27: 96 | D27: OK | E27: 284000 | F27: =C27*E27 -> 27264000
B28: - 04 Satuan Biaya Tiket Pesawat Perjalanan Dinas Dalam Negeri (PP) Ekonomi JAKARTA - SEMARANG | C28: 8 | D28: OK | E28: 2182000 | F28: =C28*E28 -> 17456000
B29: - 07 Biaya Penginapan Perjalanan Dinas Pejabat Eselon III/Golongan IV (JAWA TENGAH) [8 ORG x 2 KL x 2 HR] | C29: 32 | D29: OH | E29: 1201000 | F29: =C29*E29 -> 38432000
B30: - 10 Uang Harian Perjalanan Dinas Luar Kota (Jawa Tengah) [5 ORG x 3 HR] | C30: 15 | D30: OH | E30: 370000 | F30: =C30*E30 -> 5550000
B31: - 12 Biaya Taksi Perjalanan Dinas (D.K.I. Jakarta) [5 ORG x 2 KL x 3 KEG] | C31: 30 | D31: OK | E31: 274000 | F31: =C31*E31 -> 8220000
B32: - 14 Biaya Taksi Perjalanan Dinas (Jawa Tengah) [5 ORG x 2 KL] | C32: 10 | D32: OK | E32: 116000 | F32: =C32*E32 -> 1160000
A33: 524113 | B33: Belanja Perjalanan Dinas Dalam Kota | F33: =SUM(F34:F35) -> 243200000
B34: - 01 Uang Harian Perjalanan Dinas Dalam Kota Lebih dari 8 Jam (D.K.I. Jakarta) [4 ORG x 10 TIM x 1 HR x 8 PT 2 x KL] | C34: 640 | D34: OH | E34: 210000 | F34: =C34*E34 -> 134400000
B35: - 02 Uang Transport Kegiatan Dalam Kabupaten/Kota Pergi Pulang (PP) [4 ORG x 10 TIM x 1 HR x 8 PT 2 x KL] | C35: 640 | D35: OK | E35: 170000 | F35: =C35*E35 -> 108800000
A36: 052 | B36: Workshop/Sosialisasi/Bimbingan Teknis Peningkatan Mutu Perguruan Tinggi | F36: =F37+F54+F60+F84+F105+F129+F153+F176 -> 3315633000
A37: A | B37: Workshop/Sosialisasi/Bimbingan Teknis Peningkatan Mutu Perguruan Tinggi | F37: =F38+F43+F48+F51 -> 53592000
A38: 521211 | B38: Belanja Bahan | F38: =SUM(F39:F42) -> 22442000
B39: - 01 Makan Rapat Biasa D.K.I. JAKARTA | C39: 250 | D39: OK | E39: 57000 | F39: =C39*E39 -> 14250000
B40: - 02 Snack Rapat Biasa D.K.I. JAKARTA | C40: 250 | D40: OK | E40: 24000 | F40: =C40*E40 -> 6000000
B41: - 04 Bahan Habis Pakai | C41: 1 | D41: KEG | E41: 1192000 | F41: =C41*E41 -> 1192000
...

Sheet RAB Rev Terakhir
C1: MENJADI | G1: Non Perjadin | H1: Perjadin
A2: LEMBAGA LAYANAN PENDIDIKAN TINGGI WILAYAH III | F2: =F5+F286 -> 533596997000 | G2: =SUM(G5:G513) -> 2235622000 | H2: =SUM(H5:H513) -> 2619862000
A3: KODE | B3: DESKRIPSI | C3: Volume | D3: SATUAN | E3: Harga Satuan | F3: Jumlah Biaya | G3: =G2/(G2+H2) -> 0.46043237 | H3: =H2/(G2+H2) -> 0.53956763
A5: 139.03.DK | B5: Program Pendidikan Tinggi | F5: =F6 -> 412713557000
A6: 7733 | B6: Pembinaan Kelembagaan Pendidikan Tinggi | F6: =F243+F7 -> 412713557000
A7: 7733.BDB | B7: Fasilitasi dan Pembinaan Lembaga[Base Line] | F7: =F8+F202 -> 4855484000
A8: 7733.BDB.001 | B8: Lembaga Pendidikan Tinggi Akademik dan Vokasi yang mendapatkan layanan pembinaan peningkatan mutu | C8: 245 | D8: Lembaga | F8: =F9+F26+F115+F138 -> 4594964000
A9: 051 | B9: Pembinaan dan Evaluasi Lapangan Pengendalian Perguruan Tinggi | F9: =F10 -> 52150000
A10: A | B10: Monitoring, Evaluasi, dan Penataan Legalitas PTS | F10: =F11+F15+F20+F23 -> 52150000
A11: 521211 | B11: Belanja Bahan | F11: =SUM(F12:F14) -> 8800000 | G11: =F11 -> 8800000
B12: - 01 Makan Rapat Biasa D.K.I. JAKARTA [150 ORG x 5KL] | C12: 100 | D12: OK | E12: 57000 | F12: =C12*E12 -> 5700000
B13: - 02 Snack Rapat Biasa D.K.I. JAKARTA [150 ORG x 5 KL] | C13: 100 | D13: OK | E13: 24000 | F13: =C13*E13 -> 2400000
B14: - 03 Bahan Habis Pakai | C14: 1 | D14: KEG | E14: =778000-108000+30000 -> 700000 | F14: =C14*E14 -> 700000
A15: 521213 | B15: Belanja Honor Output Kegiatan | F15: =SUM(F16:F19) -> 7750000 | G15: =F15 -> 7750000
B16: - 01 Honorarium Penanggung Jawab Panitia Seminar/Rakor/Sosialisai/Diseminasi/FGD | C16: 1 | D16: OK | E16: 450000 | F16: =C16*E16 -> 450000
B17: - 02 Honorarium Ketua/Wakil ketua Panitia Seminar/Rakor/Sosialisai/Diseminasi/FGD | C17: 1 | D17: OK | E17: 400000 | F17: =C17*E17 -> 400000
B18: - 03 Honorarium Sekretaris Panitia Seminar/Rakor/Sosialisai/Diseminasi/FGD | C18: 1 | D18: OK | E18: 300000 | F18: =C18*E18 -> 300000
B19: - 04 Honorarium Anggota Panitia Seminar/Rakor/Sosialisai/Diseminasi/FGD | C19: 22 | D19: OK | E19: 300000 | F19: =C19*E19 -> 6600000
A20: 522151 | B20: Belanja Jasa Profesi | F20: =SUM(F21:F22) -> 12800000 | G20: =F20 -> 12800000
B21: - 01 Honorarium Narasumber (Pejabat Eselon II) [4 ORG x 3 JAM x 5 KEG] | C21: 10 | D21: OJ | E21: 1000000 | F21: =C21*E21 -> 10000000
B22: - 02 Honorarium Moderator [3 ORG x 5 KEG] | C22: 4 | D22: ORKAL | E22: 700000 | F22: =C22*E22 -> 2800000
A23: 524113 | B23: Belanja Perjalanan Dinas Dalam Kota | F23: =SUM(F24:F25) -> 22800000 | H23: =F23 -> 22800000
B24: - 01 Uang Harian Perjalanan Dinas Dalam Kota Lebih dari 8 Jam (D.K.I. Jakarta) [5 ORG x 12 TIM x 1 HR x 8 PTS x 2 x KL] | C24: 60 | D24: OH | E24: 210000 | F24: =C24*E24 -> 12600000
B25: - 02 Uang Transport Kegiatan Dalam Kabupaten/Kota Pergi Pulang (PP) [5 ORG x 12 TIM x 1 HR x 8 PTS x 2 x KL] | C25: 60 | D25: OK | E25: 170000 | F25: =C25*E25 -> 10200000
A26: 052 | B26: Workshop/Sosialisasi/Bimbingan Teknis Peningkatan Mutu Perguruan Tinggi | F26: =F27+F49+F71+F93 -> 2355010000
A27: A | B27: Pembelajaran dan Prestasi Mahasiswa | F27: =F28+F32+F37+F41+F45 -> 622508000
A28: 521211 | B28: Belanja Bahan | F28: =SUM(F29:F31) -> 143060000 | G28: =F28 -> 143060000
B29: - 01 Makan Rapat Biasa D.K.I. JAKARTA [110 ORG x 2 HR x 2 KL x 4 KEG ] | C29: 1760 | D29: OK | E29: 57000 | F29: =C29*E29 -> 100320000
B30: - 02 Snack Rapat Biasa D.K.I. JAKARTA[110 ORG x 2 HR x 2 KL x 4 KEG ] | C30: 1760 | D30: OK | E30: 24000 | F30: =C30*E30 -> 42240000
B31: - 03 Bahan Habis Pakai | C31: 1 | D31: KEG | E31: 500000 | F31: =C31*E31 -> 500000
A32: 521213 | B32: Belanja Honor Output Kegiatan | F32: =SUM(F33:F36) -> 15400000 | G32: =F32 -> 15400000
B33: - 01 Honorarium Penanggung Jawab Panitia Seminar/Rakor/Sosialisai/Diseminasi/FGD | C33: 4 | D33: OK | E33: 450000 | F33: =C33*E33 -> 1800000
B34: - 02 Honorarium Ketua/Wakil ketua Panitia Seminar/Rakor/Sosialisai/Diseminasi/FGD | C34: 4 | D34: OK | E34: 400000 | F34: =C34*E34 -> 1600000
B35: - 03 Honorarium Sekretaris Panitia Seminar/Rakor/Sosialisai/Diseminasi/FGD | C35: 4 | D35: OK | E35: 300000 | F35: =C35*E35 -> 1200000
B36: - 04 Honorarium Anggota Panitia Seminar/Rakor/Sosialisai/Diseminasi/FGD | C36: 36 | D36: OK | E36: 300000 | F36: =C36*E36 -> 10800000
A37: 522151 | B37: Belanja Jasa Profesi | F37: =SUM(F38:F40) -> 148000000 | G37: =F37 -> 148000000
B38: - 01 Honorarium Narasumber (Pejabat Eselon II) [3 ORG x 3 JAM x 2 HR x 4 KEG] | C38: 72 | D38: OJ | E38: 1000000 | F38: =C38*E38 -> 72000000
B39: - 01 Honorarium Narasumber (Pejabat Eselon III) [3 ORG x 3 JAM x 2 HR x 4 KEG] | C39: 72 | D39: OJ | E39: 900000 | F39: =C39*E39 -> 64800000
B40: - 02 Honorarium Moderator [2 ORG x 2 KL x 4 KEG] | C40: 16 | D40: ORKAL | E40: 700000 | F40: =C40*E40 -> 11200000
A41: 524111 | B41: Belanja Perjalanan Dinas Biasa | F41: =SUM(F42:F44) -> 190368000 | H41: =F41 -> 190368000
...

Sheet RAB Semula Menjadi
C1: SEMULA | G1: Non Perjadin | H1: Perjadin | I1: Selisih Per Sub Komponen | J1: MENJADI | N1: Non Perjadin | O1: Perjadin | P1: Selisih Non Perjadin | Q1: Selisih Perjadin | R1: Total Selisih
A2: LEMBAGA LAYANAN PENDIDIKAN TINGGI WILAYAH III | F2: =F5+F320 -> 535833886000 | G2: =SUM(G5:G547) -> 3043307000 | H2: =SUM(H5:H547) -> 3567418000 | I2: =SUM(I5:I547) -> 2236889000 | M2: =M5+M320 -> 533596997000 | N2: =SUM(N5:N547) -> 2235622000 | O2: =SUM(O5:O547) -> 2619862000 | P2: =G2-N2 -> 807685000 | Q2: =H2-O2 -> 947556000 | R2: =P2+Q2 -> 1755241000
A3: KODE | B3: DESKRIPSI | C3: Volume | D3: SATUAN | E3: Harga Satuan | F3: Jumlah Biaya | G3: =G2/(G2+H2) -> 0.46035904 | H3: =H2/(G2+H2) -> 0.53964096 | J3: Volume | K3: SATUAN | L3: Harga Satuan | M3: Jumlah Biaya | N3: =N2/(N2+O2) -> 0.46043237 | O3: =O2/(N2+O2) -> 0.53956763 | P3: Selisih Pagu
P4: =F2-M2 -> 2236889000
A5: 139.03.DK | B5: Program Pendidikan Tinggi | F5: =F6 -> 414468798000 | M5: =M6 -> 412713557000
A6: 7733 | B6: Pembinaan Kelembagaan Pendidikan Tinggi | F6: =F277+F7 -> 414468798000 | M6: =M277+M7 -> 412713557000 | N6: =M7-4855484000 -> 0
A7: 7733.BDB | B7: Fasilitasi dan Pembinaan Lembaga[Base Line] | F7: =F8+F232 -> 6610725000 | M7: =M8+M232 -> 4855484000
A8: 7733.BDB.001 | B8: Lembaga Pendidikan Tinggi Akademik dan Vokasi yang mendapatkan layanan pembinaan peningkatan mutu | C8: 245 | D8: Lembaga | F8: =F9+F34+F123+F168 -> 6175115000 | J8: 245 | K8: Lembaga | M8: =M9+M34+M123+M168 -> 4594964000
A9: 051 | B9: Pembinaan dan Evaluasi Lapangan Pengendalian Perguruan Tinggi | F9: =F10 -> 623222000 | M9: =M10 -> 52150000
A10: A | B10: Monitoring, Evaluasi, dan Penataan Legalitas PTS | F10: =F11+F15+F20+F23+F31 -> 623222000 | I10: =F10-M10 -> 571072000 | M10: =M11+M15+M20+M23+M31 -> 52150000
A11: 521211 | B11: Belanja Bahan | F11: =SUM(F12:F14) -> 61450000 | G11: =F11 -> 61450000 | M11: =SUM(M12:M14) -> 8800000 | N11: =M11 -> 8800000
B12: - 01 Makan Rapat Biasa D.K.I. JAKARTA [150 ORG x 5KL] | C12: 750 | D12: OK | E12: 57000 | F12: =C12*E12 -> 42750000 | J12: 100 | K12: OK | L12: 57000 | M12: =J12*L12 -> 5700000
B13: - 02 Snack Rapat Biasa D.K.I. JAKARTA [150 ORG x 5 KL] | C13: 750 | D13: OK | E13: 24000 | F13: =C13*E13 -> 18000000 | J13: 100 | K13: OK | L13: 24000 | M13: =J13*L13 -> 2400000
B14: - 03 Bahan Habis Pakai | C14: 1 | D14: KEG | E14: =778000-108000+30000 -> 700000 | F14: =C14*E14 -> 700000 | J14: 1 | K14: KEG | L14: =778000-108000+30000 -> 700000 | M14: =J14*L14 -> 700000
A15: 521213 | B15: Belanja Honor Output Kegiatan | F15: =SUM(F16:F19) -> 7750000 | G15: =F15 -> 7750000 | M15: =SUM(M16:M19) -> 7750000 | N15: =M15 -> 7750000
B16: - 01 Honorarium Penanggung Jawab Panitia Seminar/Rakor/Sosialisai/Diseminasi/FGD | C16: 1 | D16: OK | E16: 450000 | F16: =C16*E16 -> 450000 | J16: 1 | K16: OK | L16: 450000 | M16: =J16*L16 -> 450000
B17: - 02 Honorarium Ketua/Wakil ketua Panitia Seminar/Rakor/Sosialisai/Diseminasi/FGD | C17: 1 | D17: OK | E17: 400000 | F17: =C17*E17 -> 400000 | J17: 1 | K17: OK | L17: 400000 | M17: =J17*L17 -> 400000
B18: - 03 Honorarium Sekretaris Panitia Seminar/Rakor/Sosialisai/Diseminasi/FGD | C18: 1 | D18: OK | E18: 300000 | F18: =C18*E18 -> 300000 | J18: 1 | K18: OK | L18: 300000 | M18: =J18*L18 -> 300000
B19: - 04 Honorarium Anggota Panitia Seminar/Rakor/Sosialisai/Diseminasi/FGD | C19: 22 | D19: OK | E19: 300000 | F19: =C19*E19 -> 6600000 | J19: 22 | K19: OK | L19: 300000 | M19: =J19*L19 -> 6600000
A20: 522151 | B20: Belanja Jasa Profesi | F20: =SUM(F21:F22) -> 70500000 | G20: =F20 -> 70500000 | M20: =SUM(M21:M22) -> 12800000 | N20: =M20 -> 12800000
B21: - 01 Honorarium Narasumber (Pejabat Eselon II) [4 ORG x 3 JAM x 5 KEG] | C21: 60 | D21: OJ | E21: 1000000 | F21: =C21*E21 -> 60000000 | J21: 10 | K21: OJ | L21: 1000000 | M21: =J21*L21 -> 10000000
B22: - 02 Honorarium Moderator [3 ORG x 5 KEG] | C22: 15 | D22: ORKAL | E22: 700000 | F22: =C22*E22 -> 10500000 | J22: 4 | K22: ORKAL | L22: 700000 | M22: =J22*L22 -> 2800000
A23: 524111 | B23: Belanja Perjalanan Dinas Biasa | F23: =SUM(F24:F30) -> 118722000 | H23: =F23 -> 118722000 | M23: =SUM(M24:M30) -> 0 | O23: =M23 -> 0
B24: - 01 Uang Harian Perjalanan Dinas Luar Kota (Jawa Barat) [8 ORG x 1 TIM x 1 HARI x 6 PT] | C24: 48 | D24: OH | E24: 430000 | F24: =C24*E24 -> 20640000 | J24: 0 | K24: OH | L24: 430000 | M24: =J24*L24 -> 0
B25: - 02 Satuan biaya transportasi jakarta ke kota bekasi [8 ORG x 1 TIM x 2 KL x 6 PT] | C25: 96 | D25: OK | E25: 284000 | F25: =C25*E25 -> 27264000 | J25: 0 | K25: OK | L25: 284000 | M25: =J25*L25 -> 0
B26: - 04 Satuan Biaya Tiket Pesawat Perjalanan Dinas Dalam Negeri (PP) Ekonomi JAKARTA - SEMARANG | C26: 8 | D26: OK | E26: 2182000 | F26: =C26*E26 -> 17456000 | J26: 0 | K26: OK | L26: 2182000 | M26: =J26*L26 -> 0
B27: - 07 Biaya Penginapan Perjalanan Dinas Pejabat Eselon III/Golongan IV (JAWA TENGAH) [8 ORG x 2 KL x 2 HR] | C27: 32 | D27: OH | E27: 1201000 | F27: =C27*E27 -> 38432000 | J27: 0 | K27: OH | L27: 1201000 | M27: =J27*L27 -> 0
B28: - 10 Uang Harian Perjalanan Dinas Luar Kota (Jawa Tengah) [5 ORG x 3 HR] | C28: 15 | D28: OH | E28: 370000 | F28: =C28*E28 -> 5550000 | J28: 0 | K28: OH | L28: 370000 | M28: =J28*L28 -> 0
B29: - 12 Biaya Taksi Perjalanan Dinas (D.K.I. Jakarta) [5 ORG x 2 KL x 3 KEG] | C29: 30 | D29: OK | E29: 274000 | F29: =C29*E29 -> 8220000 | J29: 0 | K29: OK | L29: 274000 | M29: =J29*L29 -> 0
B30: - 14 Biaya Taksi Perjalanan Dinas (Jawa Tengah) [5 ORG x 2 KL] | C30: 10 | D30: OK | E30: 116000 | F30: =C30*E30 -> 1160000 | J30: 0 | K30: OK | L30: 116000 | M30: =J30*L30 -> 0
A31: 524113 | B31: Belanja Perjalanan Dinas Dalam Kota | F31: =SUM(F32:F33) -> 364800000 | H31: =F31 -> 364800000 | M31: =SUM(M32:M33) -> 22800000 | O31: =M31 -> 22800000
B32: - 01 Uang Harian Perjalanan Dinas Dalam Kota Lebih dari 8 Jam (D.K.I. Jakarta) [5 ORG x 12 TIM x 1 HR x 8 PTS x 2 x KL] | C32: 960 | D32: OH | E32: 210000 | F32: =C32*E32 -> 201600000 | J32: 60 | K32: OH | L32: 210000 | M32: =J32*L32 -> 12600000
B33: - 02 Uang Transport Kegiatan Dalam Kabupaten/Kota Pergi Pulang (PP) [5 ORG x 12 TIM x 1 HR x 8 PTS x 2 x KL] | C33: 960 | D33: OK | E33: 170000 | F33: =C33*E33 -> 163200000 | J33: 60 | K33: OK | L33: 170000 | M33: =J33*L33 -> 10200000
A34: 052 | B34: Workshop/Sosialisasi/Bimbingan Teknis Peningkatan Mutu Perguruan Tinggi | F34: =F35+F57+F79+F101 -> 2490032000 | M34: =M35+M57+M79+M101 -> 2355010000
A35: A | B35: Pembelajaran dan Prestasi Mahasiswa | F35: =F36+F40+F45+F49+F53 -> 622508000 | I35: =F35-M35 -> 0 | M35: =M36+M40+M45+M49+M53 -> 622508000
A36: 521211 | B36: Belanja Bahan | F36: =SUM(F37:F39) -> 143060000 | G36: =F36 -> 143060000 | M36: =SUM(M37:M39) -> 143060000 | N36: =M36 -> 143060000
B37: - 01 Makan Rapat Biasa D.K.I. JAKARTA [110 ORG x 2 HR x 2 KL x 4 KEG ] | C37: 1760 | D37: OK | E37: 57000 | F37: =C37*E37 -> 100320000 | J37: 1760 | K37: OK | L37: 57000 | M37: =J37*L37 -> 100320000
B38: - 02 Snack Rapat Biasa D.K.I. JAKARTA[110 ORG x 2 HR x 2 KL x 4 KEG ] | C38: 1760 | D38: OK | E38: 24000 | F38: =C38*E38 -> 42240000 | J38: 1760 | K38: OK | L38: 24000 | M38: =J38*L38 -> 42240000
B39: - 03 Bahan Habis Pakai | C39: 1 | D39: KEG | E39: 500000 | F39: =C39*E39 -> 500000 | J39: 1 | K39: KEG | L39: 500000 | M39: =J39*L39 -> 500000
A40: 521213 | B40: Belanja Honor Output Kegiatan | F40: =SUM(F41:F44) -> 15400000 | G40: =F40 -> 15400000 | M40: =SUM(M41:M44) -> 15400000 | N40: =M40 -> 15400000
...

Sheet Rekap
E2: Jumlah PAGU | G2: ='RAB Semula Menjadi'!M7 -> 4855484000
B4: BDB.001 | C4: 051 | D4: A | E4: Monitoring, Evaluasi, dan Penataan Legalitas PTS | F4: ='RAB Semula Menjadi'!M10 -> 52150000
C5: 052 | D5: A | E5: Pembelajaran dan Prestasi Mahasiswa | F5: ='RAB Semula Menjadi'!M35 -> 622508000
D6: B | E6: Peningkatan Kinerja Dosen | F6: ='RAB Semula Menjadi'!M57 -> 622508000
D7: C | E7: Inovasi Dalam Rangka Meningkatkan Mutu Riset dan Pengabdian Masyarakat | F7: ='RAB Semula Menjadi'!M79 -> 487486000
D8: D | E8: Peningkatan Mutu Perguruan Tinggi | F8: ='RAB Semula Menjadi'!M101 -> 622508000
C9: 053 | D9: A | E9: Fasilitasi Kerjasama Perguruan Tinggi (Dalam Negeri) | F9: ='RAB Semula Menjadi'!M124 -> 622508000
D10: B | E10: Rapat Koordinasi Perguruan Tinggi | F10: =0 -> 0
C11: 054 | D11: A | E11: Kebijakan Anti Dosa Pendidikan dan Integritas Akademik | F11: ='RAB Semula Menjadi'!M169 -> 622508000
D12: B | E12: Fasilitasi Layanan LLDikti | F12: ='RAB Semula Menjadi'!M191 -> 320280000
D13: C | E13: Peningkatan Kualitas Layanan LLDikti | F13: ='RAB Semula Menjadi'!M210 -> 622508000
B15: BDB.002 | C15: 051 | D15: A | E15: Koordinasi dan Presentasi Pendirian, Pembukaan, Perubahan, dan Penutupan PT/Prodi (100 Rekomendasi) | F15: ='RAB Semula Menjadi'!M234 -> 92602000
D16: B | E16: Pelatihan PTS yang mendapat pelayanan rekomendasi | F16: ='RAB Semula Menjadi'!M245 -> 79298000
D17: C | E17: Visitasi dan Pleno Evaluasi Rekomendasi (20 Rekomendasi) | F17: ='RAB Semula Menjadi'!M266 -> 88620000
G18: =SUM(F4:F17) -> 4855484000
E19: Selisih | G19: =G2-G18 -> 0

Sheet Indikatif 2025
C1: 2024 | G1: 2025 | H1: Tambahan 2025 | I1: setelah Tambahan 2025
A2: LEMBAGA LAYANAN PENDIDIKAN TINGGI WILAYAH III | F2: =F5+F20 -> 464156186000 | G2: =G5+G20 -> 462058409000 | H2: =H5+H20 -> 57365211425 | I2: =I5+I20 -> 519423620425
A3: KODE | B3: DESKRIPSI | C3: Volume | D3: SATUAN | E3: Harga Satuan | F3: Jumlah Biaya | G3: Jumlah Biaya | H3: Jumlah Biaya | I3: Jumlah Biaya
A5: 023.01.DK | B5: Program Pendidikan Tinggi | F5: =F6 -> 378437225000 | G5: =G6 -> 374468798000 | H5: =H6 -> 57365211425 | I5: =G5+H5 -> 431834009425
A6: 4472 | B6: Pembinaan Kelembagaan Pendidikan Tinggi | F6: =F7+F17 -> 378437225000 | G6: =G7+G17 -> 374468798000 | H6: =H7+H17 -> 57365211425 | I6: =G6+H6 -> 431834009425
A7: 4472.BDB | B7: Fasilitasi dan Pembinaan Lembaga[Base Line] | F7: =F8+F13 -> 7180935000 | G7: =G8+G13 -> 6610725000 | H7: =H8+H13 -> 1389275000 | I7: =G7+H7 -> 8000000000 | J7: =G7-I7 -> -1389275000 | K7: 8000000000 | L7: =K7-F7 -> 819065000
A8: 4472.BDB.001 | B8: Lembaga Pendidikan Tinggi Akademik dan Vokasi yang mendapatkan layanan pembinaan peningkatan mutu | F8: =F9+F10+F11+F12 -> 6630583000 | G8: =G9+G10+G11+G12 -> 6200373000 | H8: =H9+H10+H11+H12 -> 1249275000 | I8: =G8+H8 -> 7449648000 | L8: =L7-H9-H10 -> 0
A9: 051 | B9: Pembinaan dan Evaluasi Lapangan Pengendalian Perguruan Tinggi | F9: 515996000 | G9: 515996000 | H9: 400000000 | I9: =G9+H9 -> 915996000
A10: 052 | B10: Workshop/Sosialisasi/Bimbingan Teknis Peningkatan Mutu Perguruan Tinggi | F10: 3272979000 | G10: 3272979000 | H10: 419065000 | I10: =G10+H10 -> 3692044000
A11: 053 | B11: peningkatan Kerjasama Perguruan Tinggi | F11: 557785000 | G11: 557785000 | I11: =G11+H11 -> 557785000
A12: 054 | B12: Fasilitasi Layanan LLDikti | F12: 2283823000 | G12: 1853613000 | H12: 430210000 | I12: =G12+H12 -> 2283823000 | J12: =F12-G12 -> 430210000
A13: 4472.BDB.002 | B13: Lembaga Pendidikan Tinggi Akademik dan Vokasi yang mendapat layanan rekomendasi | C13: 125.0 Lembaga | D13: Lembaga | F13: =F14+F15+F16 -> 550352000 | G13: =G14+G15+G16 -> 410352000 | H13: =H14+H15+H16 -> 140000000 | I13: =G13+H13 -> 550352000
A14: 051 | B14: Evaluasi Dokumen usulan Rekomendasi | F14: 83990000 | G14: 83990000 | I14: =G14+H14 -> 83990000
A15: 052 | B15: Bimtek dan Workshop layanan rekomendasi | F15: 396698000 | G15: 256698000 | H15: 140000000 | I15: =G15+H15 -> 396698000 | J15: =F15-G15 -> 140000000
A16: 053 | B16: Visitasi dan evaluasi Lapangan | F16: 69664000 | G16: 69664000 | I16: =G16+H16 -> 69664000
A17: 4472.BEJ | B17: Bantuan Pendidikan Tinggi[Base Line] | C17: 8825.0 Orang | D17: Orang | F17: =F18 -> 371256290000 | G17: =G18 -> 367858073000 | H17: =H18 -> 55975936425 | I17: =G17+H17 -> 423834009425
A18: 4472.BEJ.001 | B18: Dosen Non PNS yang Menerima Tunjangan Profesi | C18: 8825.0 Orang | D18: Orang | F18: =F19 -> 371256290000 | G18: =G19 -> 367858073000 | H18: =H19 -> 55975936425 | I18: =G18+H18 -> 423834009425
A19: 004 | B19: Dukungan Operasional Penyelenggaraan Pendidikan | F19: 371256290000 | G19: 367858073000 | H19: 55975936425 | I19: =G19+H19 -> 423834009425 | J19: 423834009425
A20: 023.01.WA | B20: Program Dukungan Manajemen | F20: =F21 -> 85718961000 | G20: =G21 -> 87589611000 | H20: =H21 -> 0 | I20: =G20+H20 -> 87589611000 | J20: =J19-G19 -> 55975936425
A21: 6392 | B21: Pengelolaan Lembaga Layanan Penddikan Tinggi | F21: =F22 -> 85718961000 | G21: =G22+G28 -> 87589611000 | I21: =G21+H21 -> 87589611000
A22: 6392.EBA | B22: Layanan Dukungan Manajemen Internal[Base Line] | C22: 2.0 Layanan, Laporan, Dokumen, Rekomendasi, Unit | D22: Layanan,Laporan,Dokumen,Rekomendasi,Unit | F22: =F23+F25 -> 85718961000 | G22: =G23+G25 -> 87589611000 | H22: =H23+H25 -> 0 | I22: =G22+H22 -> 87589611000
A23: 6392.EBA.962 | B23: Layanan Umum | C23: 1.0 Layanan | D23: Layanan | F23: =F24 -> 464230000 | G23: =G24 -> 648519000 | H23: =H24 -> 0 | I23: =G23+H23 -> 648519000 | J23: =G23-F23 -> 184289000
A24: 051 | B24: Umum dan Rumah Tangga Satker | F24: 464230000 | G24: 648519000 | I24: =G24+H24 -> 648519000
A25: 6392.EBA.994 | B25: Layanan Perkantoran | C25: 1.0 Layanan | D25: Layanan | F25: =F26+F27 -> 85254731000 | G25: =G26+G27 -> 86941092000 | H25: =H26+H27 -> 0 | I25: =G25+H25 -> 86941092000
A26: 001 | B26: Gaji dan Tunjangan | F26: 78534731000 | G26: 80060404000 | I26: =G26+H26 -> 80060404000
A27: 002 | B27: Operasional dan Pemeliharaan Kantor | F27: 6720000000 | G27: 6880688000 | I27: 464230000
A28: 6392.EBB | B28: Layanan Sarana dan Prasarana Internal[Base Line] | C28: 1 | D28: Unit,m,Paket | F28: =F30 -> 198200000 | I28: =I30 -> 184289000
B29: Lokasi : DKI JAKARTA
A30: 6392.EBB.951 | B30: Layanan Sarana Internal | C30: 1 | D30: Unit | F30: =F31 -> 198200000 | I30: =I31 -> 184289000
A31: 051 | B31: Alat Pengolah Data dan Komunikasi | F31: =F32 -> 198200000 | I31: =I32 -> 184289000
A32: A | B32: Alat Pengolah Data dan Komunikasi | F32: =F33 -> 198200000 | I32: =I33 -> 184289000
A33: 532111 | B33: Belanja Modal Peralatan dan Mesin | F33: =SUM(F34:F34) -> 198200000 | I33: =SUM(I34:I34) -> 184289000
B34: - Pengadaan Peralatan TIK | C34: 1 | D34: PAKET | E34: 198200000 | F34: =C34*E34 -> 198200000 | H34: 184289000 | I34: 184289000

Sheet RAB Pagu Tambahan
A1: RINCIAN ANGGARAN BELANJA
A3: Kementerian/Lembaga
A4: Unit eselon II/Satker
A5: Kegiatan
A6: Sasaran Kegiatan
A7: Indikator kinerja kegiatan
A8: Klasifikasi Rincian Output
A9: Indikator KRO
A11: Volume
A12: Satuan Ukur
A13: Alokasi Dana
C16: Baru
A17: LEMBAGA LAYANAN PENDIDIKAN TINGGI WILAYAH III | F17: =F20+F185 -> 57549500425 | G17: =G20+G185 -> 57549500425
A18: KODE | B18: DESKRIPSI | C18: Volume | D18: SATUAN | E18: Harga Satuan | F18: Jumlah Biaya
A20: 023.01.DK | B20: Program Pendidikan Tinggi | F20: =F21 -> 57365211425 | G20: =G21 -> 57365211425 | H20: =F20-G20 -> 0
A21: 4472 | B21: Pembinaan Kelembagaan Pendidikan Tinggi | F21: =F22+F141 -> 57365211425 | G21: =G22+G141 -> 57365211425 | H21: =F21-G21 -> 0
A22: 4472.BDB | B22: Fasilitasi dan Pembinaan Lembaga[Base Line] | F22: =F23+F120 -> 1389275000 | G22: =G23+G120 -> 1389275000 | H22: =F22-G22 -> 0
A23: 4472.BDB.001 | B23: Lembaga Pendidikan Tinggi Akademik dan Vokasi yang mendapatkan layanan pembinaan peningkatan mutu | F23: =F24+F50+F92 -> 1249275000 | G23: =G24+G50+G92 -> 1249275000 | H23: =F23-G23 -> 0
A24: 051 | B24: Pembinaan dan Evaluasi Lapangan Pengendalian Perguruan Tinggi | F24: =F25 -> 400000000 | G24: 400000000 | H24: =F24-G24 -> 0
A25: A | B25: Monitoring, Evaluasi, dan Penataan Legalitas PTS | F25: =F26+F31+F36+F39+F47 -> 400000000
A26: 521211 | B26: Belanja Bahan | F26: =SUM(F27:F30) -> 27564000
B27: - 01 Makan Rapat Biasa D.K.I. JAKARTA [150 ORG x 2KL] | C27: 300 | D27: OK | E27: 53000 | F27: =C27*E27 -> 15900000
B28: - 02 Snack Rapat Biasa D.K.I. JAKARTA [150 ORG x 2 KL] | C28: 300 | D28: OK | E28: 24000 | F28: =C28*E28 -> 7200000
B29: - 03 Bahan Habis Pakai | C29: 1 | D29: KEG | E29: 2464000 | F29: =C29*E29 -> 2464000
B30: - 05 Spanduk dan Media Publikasi Lainnya | C30: 2 | D30: KEG | E30: 1000000 | F30: =C30*E30 -> 2000000
A31: 521213 | B31: Belanja Honor Output Kegiatan | F31: =SUM(F32:F35) -> 5300000
B32: - 01 Honorarium Penanggung Jawab Panitia Seminar/Rakor/Sosialisai/Diseminasi/FGD (1 ORG x 2 KL) | C32: 2 | D32: OK | E32: 450000 | F32: =C32*E32 -> 900000
B33: - 02 Honorarium Ketua/Wakil ketua Panitia Seminar/Rakor/Sosialisai/Diseminasi/FGD (1 ORG x 2 KL) | C33: 2 | D33: OK | E33: 400000 | F33: =C33*E33 -> 800000
B34: - 03 Honorarium Sekretaris Panitia Seminar/Rakor/Sosialisai/Diseminasi/FGD (1 ORG x2 KL) | C34: 2 | D34: OK | E34: 300000 | F34: =C34*E34 -> 600000
B35: - 04 Honorarium Anggota Panitia Seminar/Rakor/Sosialisai/Diseminasi/FGD (5 ORG x 2 KL) | C35: 10 | D35: OK | E35: 300000 | F35: =C35*E35 -> 3000000
A36: 522151 | B36: Belanja Jasa Profesi | F36: =SUM(F37:F38) -> 20800000
B37: - 01 Honorarium Narasumber (Pejabat Eselon II) [3 ORG x 3 JAM x 2 KEG] | C37: 18 | D37: OJ | E37: 1000000 | F37: =C37*E37 -> 18000000
B38: - 02 Honorarium Moderator [1 ORG x 4 KL] | C38: 4 | D38: ORKAL | E38: 700000 | F38: =C38*E38 -> 2800000
A39: 524111 | B39: Belanja Perjalanan Dinas Biasa | F39: =SUM(F40:F46) -> 270336000
B40: - 01 Uang Harian Perjalanan Dinas Luar Kota (Jawa Barat) [8 ORG x 1 TIM x 1 HARI x 20 PT] | C40: 160 | D40: OH | E40: 430000 | F40: =C40*E40 -> 68800000
B41: - 02 Satuan biaya transportasi jakarta ke kota bekasi [8 ORG x 1 TIM x 2 KL x 20 PT] | C41: 320 | D41: OK | E41: 284000 | F41: =C41*E41 -> 90880000
B42: - 04 Satuan Biaya Tiket Pesawat Perjalanan Dinas Dalam Negeri (PP) Ekonomi JAKARTA - SEMARANG | C42: 16 | D42: OK | E42: 2182000 | F42: =C42*E42 -> 34912000
B43: - 07 Biaya Penginapan Perjalanan Dinas Pejabat Eselon III/Golongan IV (JAWA TENGAH) [8 ORG x 2 KL x 2 HR] | C43: 32 | D43: OH | E43: 954000 | F43: =C43*E43 -> 30528000
B44: - 10 Uang Harian Perjalanan Dinas Luar Kota (Jawa Tengah) [16 ORG x 3 HR] | C44: 48 | D44: OH | E44: 370000 | F44: =C44*E44 -> 17760000
B45: - 12 Biaya Taksi Perjalanan Dinas (D.K.I. Jakarta) [16 ORG x 2 KL x 3 KEG] | C45: 96 | D45: OK | E45: 256000 | F45: =C45*E45 -> 24576000
...

Sheet 4472.BDB.001
A1: RINCIAN ANGGARAN BELANJA
A3: Kementerian/Lembaga | B3: : Kementerian Pendidikan dan Kebudayaan
A4: Unit eselon II/Satker | B4: : Lembaga Layanan Pendidikan Tinggi Wilayah III DKI Jakarta
A5: Kegiatan | B5: : Pembinaan Kelembagaan Pendidikan Tinggi
A6: Sasaran Kegiatan | B6: : Tersedianya Program Studi dan Perguruan Tinggi yang Berkualitas
A7: Indikator kinerja kegiatan | B7: : Jumlah Layanan Fasilitasi Lembaga Pendidikan Tinggi Akademik dan Vokasi
A8: Klasifikasi Rincian Output | B8: : Fasilitasi dan Pembinaan Lembaga
A9: Indikator KRO | B9: : 1. Jumlah Lembaga Pendidikan Tinggi Akademik dan Vokasi yang mendapatkan layanan pembinaan peningkatan mutu
B10: 2. Lembaga Pendidikan Tinggi Akademik dan Vokasi yang mendapat layanan rekomendasi
A11: Volume | B11: : 262
A12: Satuan Ukur | B12: : Lembaga
A13: Alokasi Dana | B13: : Rp. 6.200.373.000
A15: KODE | B15: DESKRIPSI | C15: Volume | D15: SATUAN | E15: Harga Satuan | F15: Jumlah Biaya
A17: 4472.BDB.001 | B17: Lembaga Pendidikan Tinggi Akademik dan Vokasi yang mendapatkan layanan pembinaan peningkatan mutu | F17: 6200373000
A18: 051 | B18: Pembinaan dan Evaluasi Lapangan Pengendalian Perguruan Tinggi | F18: 527592000
A19: A | B19: Monitoring, Evaluasi, dan Penataan Legalitas PTS | F19: 527592000
A20: 521211 | B20: Belanja Bahan | F20: 71420000
B21: - 01 Makan Rapat Biasa D.K.I. JAKARTA [150 ORG x 5KL] | C21: 750 | D21: OK | E21: 57000 | F21: 42750000
B22: - 02 Snack Rapat Biasa D.K.I. JAKARTA [150 ORG x 5 KL] | C22: 750 | D22: OK | E22: 24000 | F22: 18000000
B23: - 03 Bahan Habis Pakai | C23: 1 | D23: KEG | E23: 670000 | F23: 670000
B24: - 05 Spanduk dan Media Publikasi Lainnya | C24: 5 | D24: KEG | E24: 1000000 | F24: 5000000
B25: - 06 Penggandaan dan Penjilidan Laporan | C25: 5 | D25: KEG | E25: 1000000 | F25: 5000000
A26: 521213 | B26: Belanja Honor Output Kegiatan | F26: 23750000
B27: - 01 Honorarium Penanggung Jawab Panitia Seminar/Rakor/Sosialisai/Diseminasi/FGD (1 ORG x 5 KL) | C27: 5 | D27: OK | E27: 450000 | F27: 2250000
B28: - 02 Honorarium Ketua/Wakil ketua Panitia Seminar/Rakor/Sosialisai/Diseminasi/FGD (1 ORG x 5 KL) | C28: 5 | D28: OK | E28: 400000 | F28: 2000000
B29: - 03 Honorarium Sekretaris Panitia Seminar/Rakor/Sosialisai/Diseminasi/FGD (1 ORG x 5 KL) | C29: 5 | D29: OK | E29: 300000 | F29: 1500000
B30: - 04 Honorarium Anggota Panitia Seminar/Rakor/Sosialisai/Diseminasi/FGD (12 ORG x 5 KL) | C30: 60 | D30: OK | E30: 300000 | F30: 18000000
A31: 522151 | B31: Belanja Jasa Profesi | F31: 70500000
B32: - 01 Honorarium Narasumber (Pejabat Eselon II) [4 ORG x 3 JAM x 5 KEG] | C32: 60 | D32: OJ | E32: 1000000 | F32: 60000000
B33: - 02 Honorarium Moderator [3 ORG x 5 KEG] | C33: 15 | D33: ORKAL | E33: 700000 | F33: 10500000
A34: 524111 | B34: Belanja Perjalanan Dinas Biasa | F34: 118722000
B35: - 01 Uang Harian Perjalanan Dinas Luar Kota (Jawa Barat) [8 ORG x 1 TIM x 1 HARI x 6 PT] | C35: 48 | D35: OH | E35: 430000 | F35: 20640000
B36: - 02 Satuan biaya transportasi jakarta ke kota bekasi [8 ORG x 1 TIM x 2 KL x 6 PT] | C36: 96 | D36: OK | E36: 284000 | F36: 27264000
B37: - 04 Satuan Biaya Tiket Pesawat Perjalanan Dinas Dalam Negeri (PP) Ekonomi JAKARTA - SEMARANG | C37: 8 | D37: OK | E37: 2182000 | F37: 17456000
B38: - 07 Biaya Penginapan Perjalanan Dinas Pejabat Eselon III/Golongan IV (JAWA TENGAH) [8 ORG x 2 KL x 2 HR] | C38: 32 | D38: OH | E38: 1201000 | F38: 38432000
B39: - 10 Uang Harian Perjalanan Dinas Luar Kota (Jawa Tengah) [5 ORG x 3 HR] | C39: 15 | D39: OH | E39: 370000 | F39: 5550000
B40: - 12 Biaya Taksi Perjalanan Dinas (D.K.I. Jakarta) [5 ORG x 2 KL x 3 KEG] | C40: 30 | D40: OK | E40: 274000 | F40: 8220000
B41: - 14 Biaya Taksi Perjalanan Dinas (Jawa Tengah) [5 ORG x 2 KL] | C41: 10 | D41: OK | E41: 116000 | F41: 1160000
A42: 524113 | B42: Belanja Perjalanan Dinas Dalam Kota | F42: 243200000
B43: - 01 Uang Harian Perjalanan Dinas Dalam Kota Lebih dari 8 Jam (D.K.I. Jakarta) [4 ORG x 10 TIM x 1 HR x 8 PT 2 x KL] | C43: 640 | D43: OH | E43: 210000 | F43: 134400000
...

Sheet 4472.BDB.002
A1: RINCIAN ANGGARAN BELANJA
A3: Kementerian/Lembaga | B3: : Kementerian Pendidikan, Kebudayaan, Riset, dan Teknologi
A4: Unit eselon II/Satker | B4: : Lembaga Layanan Pendidikan Tinggi Wilayah III DKI Jakarta
A5: Kegiatan | B5: : Pembinaan Kelembagaan Pendidikan Tinggi
A6: Sasaran Kegiatan | B6: : Tersedianya Program Studi dan Perguruan Tinggi yang Berkualitas
A7: Indikator kinerja kegiatan | B7: : Jumlah Layanan Fasilitasi Lembaga Pendidikan Tinggi Akademik dan Vokasi
A8: Klasifikasi Rincian Output | B8: : Fasilitasi dan Pembinaan Lembaga
A9: Indikator KRO | B9: : 1. Jumlah Lembaga Pendidikan Tinggi Akademik dan Vokasi yang mendapatkan layanan pembinaan peningkatan mutu
B10: 2. Lembaga Pendidikan Tinggi Akademik dan Vokasi yang mendapat layanan rekomendasi
A11: Volume | B11: : 125
A12: Satuan Ukur | B12: : Lembaga
A13: Alokasi Dana | B13: : Rp. 410.352.000,-
A16: KODE | B16: DESKRIPSI | C16: Volume | D16: SATUAN | E16: Harga Satuan | F16: Jumlah Biaya
A18: 4472.BDB.002 | B18: Lembaga Pendidikan Tinggi Akademik dan Vokasi yang mendapat layanan rekomendasi | C18: 125.0 Lembaga | D18: Lembaga | F18: 410352000
A19: 051 | B19: Evaluasi Dokumen usulan Rekomendasi | F19: 83990000
A20: A | B20: Koordinasi dan Presentasi Pendirian, Pembukaan, Perubahan, dan Penutupan PT/Prodi (100 Rekomendasi) | F20: 83990000
A21: 521211 | B21: Belanja Bahan | F21: 15940000
B22: - 01 Makan Rapat Biasa D.K.I. JAKARTA | C22: 150 | D22: OK | E22: 57000 | F22: 8550000
B23: - 02 Snack Rapat Biasa D.K.I. JAKARTA | C23: 150 | D23: OK | E23: 24000 | F23: 3600000
B24: - 03 Bahan Habis Pakai | C24: 1 | D24: Keg | E24: 1790000 | F24: 1790000
B25: - 04 Spanduk dan Media Publikasi Lainnya | C25: 1 | D25: KEG | E25: 1000000 | F25: 1000000
B26: - 05 Penggandaan dan Penjilidan Laporan | C26: 1 | D26: KEG | E26: 1000000 | F26: 1000000
A27: 521213 | B27: Belanja Honor Output Kegiatan | F27: 4750000
B28: - 01 Honorarium Penanggung Jawab Panitia Seminar/Rakor/Sosialisai/Diseminasi/FGD | C28: 1 | D28: OK | E28: 450000 | F28: 450000
B29: - 02 Honorarium Ketua/Wakil ketua Panitia Seminar/Rakor/Sosialisai/Diseminasi/FGD | C29: 1 | D29: OK | E29: 400000 | F29: 400000
B30: - 03 Honorarium Sekretaris Panitia Seminar/Rakor/Sosialisai/Diseminasi/FGD | C30: 1 | D30: OK | E30: 300000 | F30: 300000
B31: - 04 Honorarium Anggota Panitia Seminar/Rakor/Sosialisai/Diseminasi/FGD | C31: 12 | D31: OK | E31: 300000 | F31: 3600000
A32: 522151 | B32: Belanja Jasa Profesi | F32: 34800000
B33: - 01 Honorarium Narasumber (Pejabat Eselon II) [4 ORG x 4 JAM x 2 KEG] | C33: 32 | D33: OJ | E33: 1000000 | F33: 32000000
B34: - 02 Honorarium Moderator [2 ORG x 2 KL] | C34: 4 | D34: ORKAL | E34: 700000 | F34: 2800000
A35: 524113 | B35: Belanja Perjalanan Dinas Dalam Kota | F35: 28500000
B36: - 01 Uang Harian Perjalanan Dinas Dalam Kota Lebih dari 8 Jam (D.K.I. Jakarta) [25 ORG x 3 KL] | C36: 75 | D36: OH | E36: 210000 | F36: 15750000
B37: - 02 Uang Transport Kegiatan Dalam Kabupaten/Kota Pergi Pulang (PP) [25 ORG x 3 KL] | C37: 75 | D37: OK | E37: 170000 | F37: 12750000
A38: 052 | B38: Bimtek dan Workshop layanan rekomendasi | F38: 256698000
A39: A | B39: Pelatihan PTS yang mendapat pelayanan rekomendasi | F39: 256698000
A40: 521211 | B40: Belanja Bahan | F40: 82258000
B41: - 01 Makan Rapat Biasa D.K.I. JAKARTA [60 ORG x 15 KL ] | C41: 900 | D41: OK | E41: 57000 | F41: 51300000
B42: - 02 Snack Rapat Biasa D.K.I. JAKARTA [60 ORG x 15 KL ] | C42: 900 | D42: OK | E42: 24000 | F42: 21600000
B43: - 05 Bahan Habis Pakai | C43: 1 | D43: PKT | E43: 1358000 | F43: 1358000
B44: - 03 Penggandaan dan Penjilidan Laporan | C44: 4 | D44: KEG | E44: 1000000 | F44: 4000000
...

Sheet RPD
B3: Bulan
B4: 1 | C4: 1909270772 | D4: 3036504
B5: 2 | C5: 4834271443
B6: 3 | C6: 5791070997
B7: 4 | C7: 4551006618
B8: 5 | C8: 3666143276
B9: 6 | C9: 6944127204
B10: 7 | C10: 12764930661
B11: 8 | C11: 5417414958
B12: 9 | C12: 5848080529
B13: 10 | C13: 5848080526
B14: 11 | C14: 7920517546
B15: 12 | C15: 14565489470
C16: =SUM(C4:C15) -> 80060404000
C20: Prog | D20: Kegiatan | E20: Output | F20: Jenbel | G20: Pagu | H20: Jumlah | I20: Januari | J20: Februari | K20: Maret | L20: April | M20: Mei | N20: Juni | O20: Juli | P20: Agustus | Q20: September | R20: Oktober | S20: Nopember | T20: Desember
C21: DK | D21: 7733 | E21: BDB | F21: 52 | G21: 6610725000 | H21: 6610725000 | I21: 0 | J21: 0 | K21: 79697992 | L21: 61892293 | M21: 108601808 | N21: 135578995 | O21: 367070057 | P21: 389901096 | Q21: 376071507 | R21: 682499767 | S21: 944705399 | T21: 3464706086
C22: DK | D22: 7733 | E22: BEJ | F22: 51 | G22: 434342697000 | H22: 434342697000 | I22: 0 | J22: 5064371933 | K22: 76230199239 | L22: 57051813510 | M22: 41655786383 | N22: 35782627386 | O22: 0 | P22: 70433511100 | Q22: 15411131100 | R22: 45596163500 | S22: 87117092849 | T22: 0
C23: WA | D23: 7735 | E23: EBA | F23: 51 | G23: 120082512000 | H23: 120082512000 | I23: 2864683601 | J23: 7253375650 | K23: 8688964580 | L23: 6828363071 | M23: 5500707744 | N23: 10419018413 | O23: 19152593795 | P23: 8128328371 | Q23: 8774502099 | R23: 8774502093 | S23: 11884001507 | T23: 21813471076
C24: WA | D24: 7735 | E24: EBA | F24: 52 | G24: 7344918000 | H24: 7344918000 | I24: 41023058 | J24: 453174378 | K24: 580945003 | L24: 358407565 | M24: 427698925 | N24: 423658970 | O24: 819227940 | P24: 410864663 | Q24: 571501522 | R24: 1160076895 | S24: 1440383469 | T24: 657955612
C25: WA | D25: 7735 | E25: EBB | F25: 53 | G25: 184289000 | H25: 184289000 | I25: 0 | J25: 0 | K25: 0 | L25: 0 | M25: 0 | N25: 0 | O25: 0 | P25: 0 | Q25: 0 | R25: 0 | S25: 184289000 | T25: 0
C27: RENCANA PENARIKAN DANA TAHUN 2026
D28: Pagu | E28: Jumlah | F28: Januari | G28: Februari | H28: Maret | I28: April | J28: Mei | K28: Juni | L28: Juli | M28: Agustus | N28: September | O28: Oktober | P28: Nopember | Q28: Desember
C29: 7733.BDB.001.051 | D29: 52150000 | E29: =SUM(F29:Q29) -> 52150000 | G29: 4345000 | H29: 4345000 | I29: 4345000 | J29: 4345000 | K29: 4345000 | L29: 4345000 | M29: 4345000 | N29: 4345000 | O29: 4345000 | P29: 4345000 | Q29: 8700000
C30: 7733.BDB.001.052 | D30: 2355010000 | E30: =SUM(F30:Q30) -> 2355010000 | G30: 196250000 | H30: 196250000 | I30: 196250000 | J30: 196250000 | K30: 196250000 | L30: 196250000 | M30: 196250000 | N30: 196250000 | O30: 196250000 | P30: 196250000 | Q30: 392510000
C31: 7733.BDB.001.053 | D31: 622508000 | E31: =SUM(F31:Q31) -> 622508000 | G31: 51875000 | H31: 51875000 | I31: 51875000 | J31: 51875000 | K31: 51875000 | L31: 51875000 | M31: 51875000 | N31: 51875000 | O31: 51875000 | P31: 51875000 | Q31: 103758000
C32: 7733.BDB.001.054 | D32: 1565296000 | E32: =SUM(F32:Q32) -> 1565296000 | G32: 130441000 | H32: 130441000 | I32: 130441000 | J32: 130441000 | K32: 130441000 | L32: 130441000 | M32: 130441000 | N32: 130441000 | O32: 130441000 | P32: 130441000 | Q32: 260886000
C34: 7733.BDB.002.051 | D34: 260520000 | E34: =SUM(F34:Q34) -> 260520000 | G34: 21710000 | H34: 21710000 | I34: 21710000 | J34: 21710000 | K34: 21710000 | L34: 21710000 | M34: 21710000 | N34: 21710000 | O34: 21710000 | P34: 21710000 | Q34: 43420000
C36: 7733.BEJ.001.004 | D36: 407858073000 | E36: =SUM(F36:Q36) -> 407858073000 | F36: 33965422800 | G36: 33965422800 | H36: 33965422800 | I36: 33965422800 | J36: 33965422800 | K36: 33965422800 | L36: 33965422800 | M36: 33965422800 | N36: 33965422800 | O36: 33965422800 | P36: 33965422800 | Q36: 34238422200
C38: 7733.BEJ.001.004 | E38: =SUM(F38:Q38) -> 0
C40: 7735.EBA.Z07.051 | D40: 10000000 | E40: =SUM(F40:Q40) -> 10000000 | K40: 4000000 | L40: 6000000
C42: 7735.EBA.962.051 | D42: 193288000 | E42: =SUM(F42:Q42) -> 193288000 | G42: 16102998 | H42: 16102998 | I42: 16102998 | J42: 16102998 | K42: 16102998 | L42: 16102998 | M42: 16102998 | N42: 16102998 | O42: 16102998 | P42: 16102998 | Q42: 32258020
C44: 7735.EBA.994.001 | D44: 114082512000 | E44: =SUM(F44:Q44) -> 114082512000 | F44: 9506862000 | G44: 9506862000 | H44: 9506862000 | I44: 9506862000 | J44: 9506862000 | K44: 9506862000 | L44: 9506862000 | M44: 9506862000 | N44: 9506862000 | O44: 9506862000 | P44: 9506862000 | Q44: 9507030000
C45: 7735.EBA.994.002 | D45: 6399040000 | E45: =SUM(F45:Q45) -> 6399040000 | F45: 200000000 | G45: 533253000 | H45: 533253000 | I45: 533253000 | J45: 533253000 | K45: 533253000 | L45: 533253000 | M45: 533253000 | N45: 533253000 | O45: 533253000 | P45: 533253000 | Q45: 866510000
C47: 7735.EBB.951.997 | D47: 198600000 | E47: =SUM(F47:Q47) -> 198600000 | L47: 198600000
C48: Jumlah | D48: =SUM(D29:D47) -> 533596997000 | E48: =SUM(E29:E47) -> 533596997000
C49: Selisih | D49: =D48-E48 -> 0
C51: BERDASARKAN RPD (Rev. KPA saat ini)
D52: Pagu | E52: Jumlah | F52: Januari | G52: Februari | H52: Maret | I52: April | J52: Mei | K52: Juni | L52: Juli | M52: Agustus | N52: September | O52: Oktober | P52: Nopember | Q52: Desember
C53: 7733 - 51 | D53: 4.0785807e+08 | E53: =SUM(F53:Q53) -> 4.0785807e+08 | F53: =(F36+F38)/1000 -> 33965423 | G53: =(G36+G38)/1000 -> 33965423 | H53: =(H36+H38)/1000 -> 33965423 | I53: =(I36+I38)/1000 -> 33965423 | J53: =(J36+J38)/1000 -> 33965423 | K53: =(K36+K38)/1000 -> 33965423 | L53: =(L36+L38)/1000 -> 33965423 | M53: =(M36+M38)/1000 -> 33965423 | ... Q53: =(Q36+Q38)/1000 -> 34238422 | R53: 0
C54: 7733 - 52 | D54: 4855484 | E54: =SUM(F54:Q54) -> 4855484 | F54: =(F29+F30+F31+F32+F34)/1000 -> 0 | G54: =(G29+G30+G31+G32+G34)/1000 -> 404621 | H54: =(H29+H30+H31+H32+H34)/1000 -> 404621 | I54: =(I29+I30+I31+I32+I34)/1000 -> 404621 | J54: =(J29+J30+J31+J32+J34)/1000 -> 404621 | K54: =(K29+K30+K31+K32+K34)/1000 -> 404621 | L54: =(L29+L30+L31+L32+L34)/1000 -> 404621 | M54: =(M29+M30+M31+M32+M34)/1000 -> 404621 | ... Q54: =(Q29+Q30+Q31+Q32+Q34)/1000 -> 809274
...

Sheet RAB 7733.BDB.001
A1: RINCIAN ANGGARAN BIAYA
A3: Kementerian/Lembaga | B3: : Kementerian Pendidikan Tinggi, Sains dan Teknologi
A4: Unit eselon II/Satker | B4: : Lembaga Layanan Pendidikan Tinggi Wilayah III DKI Jakarta
A5: Kegiatan | B5: : Pembinaan Kelembagaan Pendidikan Tinggi
A6: Sasaran Kegiatan | B6: : Tersedianya program studi dan perguruan tinggi yang berkualitas
A7: Indikator kinerja kegiatan | B7: : Jumlah layanan fasilitasi lembaga pendidikan tinggi akademik dan vokasi
A8: Klasifikasi Rincian Output | B8: : Fasilitasi dan pembinaan lembaga
A9: Rincian Output | B9: : Lembaga Pendidikan Tinggi Akademik dan Vokasi yang Mendapatkan Layanan Pembinaan Peningkatan Mutu
A10: Volume RO | B10: : 245
A11: Satuan RO | B11: : Lembaga
A12: Alokasi Dana | B12: : Rp. 4.594.964.000
A15: Kode | B15: Uraian RO/Komponen/Subkomponen/Akun/Detil | C15: Volume Rincian Output | D15: Jenis Komponen (Utama/Pendukung) | E15: Rincian Perhitungan | H15: Harga Satuan | I15: Jumlah
E16: Sat. | F16: Jml | G16: jml
A17: 7733.BDB.001 | B17: Lembaga Pendidikan Tinggi Akademik dan Vokasi yang mendapatkan layanan pembinaan peningkatan mutu | C17: 246 | I17: =I18+I35+I124+I147 -> 4594964000
A18: 051 | B18: Pembinaan dan Evaluasi Lapangan Pengendalian Perguruan Tinggi | D18: Utama | I18: =I19 -> 52150000
A19: A | B19: Monitoring, Evaluasi, dan Penataan Legalitas PTS | I19: =I20+I24+I29+I32 -> 52150000
A20: 521211 | B20: Belanja Bahan | I20: =SUM(I21:I23) -> 8800000
B21: - 01 Makan Rapat Biasa D.K.I. JAKARTA [150 ORG x 5KL] | E21: OK | F21: 100 | G21: OK | H21: 57000 | I21: =F21*H21 -> 5700000
B22: - 02 Snack Rapat Biasa D.K.I. JAKARTA [150 ORG x 5 KL] | E22: OK | F22: 100 | G22: OK | H22: 24000 | I22: =F22*H22 -> 2400000
B23: - 03 Bahan Habis Pakai | E23: KEG | F23: 1 | G23: KEG | H23: =778000-108000+30000 -> 700000 | I23: =F23*H23 -> 700000
A24: 521213 | B24: Belanja Honor Output Kegiatan | I24: =SUM(I25:I28) -> 7750000
B25: - 01 Honorarium Penanggung Jawab Panitia Seminar/Rakor/Sosialisai/Diseminasi/FGD | E25: OK | F25: 1 | G25: OK | H25: 450000 | I25: =F25*H25 -> 450000
B26: - 02 Honorarium Ketua/Wakil ketua Panitia Seminar/Rakor/Sosialisai/Diseminasi/FGD | E26: OK | F26: 1 | G26: OK | H26: 400000 | I26: =F26*H26 -> 400000
B27: - 03 Honorarium Sekretaris Panitia Seminar/Rakor/Sosialisai/Diseminasi/FGD | E27: OK | F27: 1 | G27: OK | H27: 300000 | I27: =F27*H27 -> 300000
B28: - 04 Honorarium Anggota Panitia Seminar/Rakor/Sosialisai/Diseminasi/FGD | E28: OK | F28: 22 | G28: OK | H28: 300000 | I28: =F28*H28 -> 6600000
A29: 522151 | B29: Belanja Jasa Profesi | I29: =SUM(I30:I31) -> 12800000
B30: - 01 Honorarium Narasumber (Pejabat Eselon II) [4 ORG x 3 JAM x 5 KEG] | E30: OJ | F30: 10 | G30: OJ | H30: 1000000 | I30: =F30*H30 -> 10000000
B31: - 02 Honorarium Moderator [3 ORG x 5 KEG] | E31: ORKAL | F31: 4 | G31: ORKAL | H31: 700000 | I31: =F31*H31 -> 2800000
A32: 524113 | B32: Belanja Perjalanan Dinas Dalam Kota | I32: =SUM(I33:I34) -> 22800000
B33: - 01 Uang Harian Perjalanan Dinas Dalam Kota Lebih dari 8 Jam (D.K.I. Jakarta) [5 ORG x 12 TIM x 1 HR x 8 PTS x 2 x KL] | E33: OH | F33: 60 | G33: OH | H33: 210000 | I33: =F33*H33 -> 12600000
B34: - 02 Uang Transport Kegiatan Dalam Kabupaten/Kota Pergi Pulang (PP) [5 ORG x 12 TIM x 1 HR x 8 PTS x 2 x KL] | E34: OK | F34: 60 | G34: OK | H34: 170000 | I34: =F34*H34 -> 10200000
A35: 052 | B35: Workshop/Sosialisasi/Bimbingan Teknis Peningkatan Mutu Perguruan Tinggi | D35: Utama | I35: =I36+I58+I80+I102 -> 2355010000
A36: A | B36: Pembelajaran dan Prestasi Mahasiswa | I36: =I37+I41+I46+I50+I54 -> 622508000
A37: 521211 | B37: Belanja Bahan | I37: =SUM(I38:I40) -> 143060000
B38: - 01 Makan Rapat Biasa D.K.I. JAKARTA [110 ORG x 2 HR x 2 KL x 4 KEG ] | E38: OK | F38: 1760 | G38: OK | H38: 57000 | I38: =F38*H38 -> 100320000
B39: - 02 Snack Rapat Biasa D.K.I. JAKARTA[110 ORG x 2 HR x 2 KL x 4 KEG ] | E39: OK | F39: 1760 | G39: OK | H39: 24000 | I39: =F39*H39 -> 42240000
B40: - 03 Bahan Habis Pakai | E40: KEG | F40: 1 | G40: KEG | H40: 500000 | I40: =F40*H40 -> 500000
A41: 521213 | B41: Belanja Honor Output Kegiatan | I41: =SUM(I42:I45) -> 15400000
B42: - 01 Honorarium Penanggung Jawab Panitia Seminar/Rakor/Sosialisai/Diseminasi/FGD | E42: OK | F42: 4 | G42: OK | H42: 450000 | I42: =F42*H42 -> 1800000
B43: - 02 Honorarium Ketua/Wakil ketua Panitia Seminar/Rakor/Sosialisai/Diseminasi/FGD | E43: OK | F43: 4 | G43: OK | H43: 400000 | I43: =F43*H43 -> 1600000
...

Sheet RAB 7733.BDB.002
A1: RINCIAN ANGGARAN BIAYA
A3: Kementerian/Lembaga | B3: : Kementerian Pendidikan Tinggi, Sains dan Teknologi
A4: Unit eselon II/Satker | B4: : Lembaga Layanan Pendidikan Tinggi Wilayah III DKI Jakarta
A5: Kegiatan | B5: : Pembinaan Kelembagaan Pendidikan Tinggi
A6: Sasaran Kegiatan | B6: : Tersedianya program studi dan perguruan tinggi yang berkualitas
A7: Indikator kinerja kegiatan | B7: : Jumlah layanan fasilitasi lembaga pendidikan tinggi akademik dan vokasi
A8: Klasifikasi Rincian Output | B8: : Fasilitasi dan pembinaan lembaga
A9: Rincian Output | B9: : Lembaga Pendidikan Tinggi Akademik dan Vokasi yang mendapat layanan rekomendasi
A10: Volume RO | B10: : 125
A11: Satuan RO | B11: : Lembaga
A12: Alokasi Dana | B12: : Rp. 260.520.000
A15: Kode | B15: Uraian RO/Komponen/Subkomponen/Akun/Detil | C15: Volume Rincian Output | D15: Jenis Komponen (Utama/Pendukung) | E15: Rincian Perhitungan | H15: Harga Satuan | I15: Jumlah
E16: Sat. | F16: Jml | G16: jml
A17: 7733.BDB.002 | B17: Lembaga Pendidikan Tinggi Akademik dan Vokasi yang mendapat layanan rekomendasi | C17: 125 | I17: =I18 -> 260520000
A18: 051 | B18: Evaluasi Dokumen usulan Rekomendasi | D18: Utama | I18: =I19+I30+I48 -> 260520000
A19: A | B19: Fasilitasi Rekomendasi Perguruan Tinggi dan Program Studi (100 Rekomendasi) | I19: =I20+I24+I27 -> 92602000
A20: 521211 | B20: Belanja Bahan | I20: =SUM(I21:I23) -> 16022000
B21: - 01 Makan Rapat Biasa D.K.I. JAKARTA [15 ORG x 1 x 10 KL ] | E21: OK | F21: 150 | G21: OK | H21: 57000 | I21: =F21*H21 -> 8550000
B22: - 02 Snack Rapat Biasa D.K.I. JAKARTA [15 ORG x 2 x 10 KL ] | E22: OK | F22: 300 | G22: OK | H22: 24000 | I22: =F22*H22 -> 7200000
B23: - 06 Bahan Habis Pakai | E23: PKT | F23: 1 | G23: PKT | H23: 272000 | I23: =F23*H23 -> 272000
A24: 524111 | B24: Belanja Perjalanan Dinas Biasa | I24: =SUM(I25:I26) -> 49980000
