Workbook

Sheet Permohonan Dana
A1: PERMOHONAN DANA
A3: Dengan ini kami mengajukan permohonan dana, dengan perincian sebagai berikut:
A5: 1. | B5: Satker | C5: : | D5: 693205 Lembaga Layanan Pendidikan Tinggi Wilayah III
A6: 2. | B6: Program | C6: : | D6: Program Pendidikan Tinggi
A7: 3. | B7: Sasaran Program | C7: : | D7: Meningkatnya akses, kualitas pembelajaran, dan relevansi pendidikan tinggi
A9: 4. | B9: Klasifikasi Rincian Output (KRO) | C9: : | D9: Fasilitasi dan Pembinaan Lembaga
A10: 5. | B10: Rincian Output (RO) | C10: : | D10: Lembaga Pendidikan Tinggi Akademik dan Vokasi yang mendapatkan layanan pembinaan peningkatan mutu
A11: 6. | B11: Komponen | C11: : | D11: -
A12: 7. | B12: Kegiatan | C12: : | D12: Diseminasi Kebijakan SPIP Terintegrasi KPK dan Gerakan Anti Narkoba bagi Perguruan Tinggi Swasta di Lingkungan LLDikti Wilayah III dengan tema “ Integrity Strats on Campus : Sinergi Budaya Antikorupsi dan Kampus Bersih Narkoba”
A13: 8. | B13: Indikator Kinerja Utama (IKU) | C13: : | D13: Tiga dosa dan antikorupsi
A14: 9. | B14: Waktu Pelaksanaan | C14: : | D14: 46182
A15: 10. | B15: Tempat Pelaksanaan | C15: : | D15: Institut Pariwisata Tedja Indonesia
D16: 11.1 | E16: ='Rincian Biaya'!B5 -> Honorarium Narasumber/Pembahas | H16: ='Rincian Biaya'!M8 -> 2000000
D17: 11.2 | E17: ='Rincian Biaya'!B10 -> Honorarium Moderator | H17: ='Rincian Biaya'!M13 -> 700000
D18: 11.3 | E18: ='Rincian Biaya'!B15 -> Honorarium Panitia | H18: ='Rincian Biaya'!M24 -> 1175000
A19: 11. | B19: Kebutuhan Biaya | D19: 11.4 | E19: ='Rincian Biaya'!B26 -> Transport Kegiatan Dalam Kota | H19: ='Rincian Biaya'!M34 -> 1020000
D20: 11.5 | E20: ='Rincian Biaya'!B36 -> Uang Saku/ Uang Harian Kegiatan Dalam Kota | H20: ='Rincian Biaya'!M45 -> 910000
D21: 11.6 | E21: ='Rincian Biaya'!B48 -> Transport Kegiatan Dalam Kota Survei Lokasi Acara Kegiatan | H21: ='Rincian Biaya'!M52 -> 340000
D22: 11.7 | E22: ='Rincian Biaya'!B54 -> Transport Kegiatan Dalam Kota Persiapan Akhir | H22: ='Rincian Biaya'!M58 -> 340000
D23: 11.8 | E23: ='Rincian Biaya'!B62 -> Belanja Pendukung Lainnya (Belanja Bahan) | H23: ='Rincian Biaya'!F66 -> 24300000
E24: Jumlah | H24: =SUM(H16:I23) -> 30785000
A26: Sebagai kelengkapan pengajuan bersama ini kami lampirkan:
A27: 1. | B27: Rincian Kebutuhan Biaya
A28: 2. | B28: Surat Keputusan Pelaksanaan Kegiatan
A29: 3. | B29: Surat Tugas Kepanitiaan
A30: 4. | B30: Surat Undangan Kegiatan
A31: 5. | B31: Surat Pernyataan Kegiatan Luar Kantor
A32: 6. | B32: Kuitansi / Bukti Pembayaran
A33: 7. | B33: SPK / Surat Perjanjian
A34: 8. | B34: Dokumen Pendukung Lainnya
B35: ……………………………………………………………
B36: ……………………………………………………………
B37: ……………………………………………………………
H39: Jakarta, 8 Juni 2026
B40: Pejabat Pembuat Komitmen
H41: Pemohon
B44: Agung Permana N
B45: NIP. 198308022015041001 | H45: Taufan S. Pranggono, S.Kom., M.Si.
H46: NIP. 198303162010121006

Sheet Rincian Biaya
A1: RINCIAN ANGGARAN BIAYA
B2: Diseminasi Kebijakan SPIP Terintegrasi KPK dan Gerakan Anti Narkoba bagi Perguruan Tinggi Swasta di Lingkungan LLDikti Wilayah III
B3: dengan tema “ Integrity Strats on Campus : Sinergi Budaya Antikorupsi dan Kampus Bersih Narkoba”
A5: A. | B5: Honorarium Narasumber/Pembahas
A6: No | B6: Nama Pegawai | C6: Jabatan dalam Tugas | D6: NIK | E6: NPWP | F6: No. Rekening | G6: Nama Rekening | H6: Nama Bank | I6: Email | J6: Vol | K6: Satuan | L6: Biaya Satuan | M6: Total
A7: 1 | B7: M. Zainul Muttaqien | C7: Narasumber | D7: =_xlfn.IFNA(VLOOKUP(B7,#REF!,3,FALSE),"") -> #REF! | E7: =_xlfn.IFNA(VLOOKUP(B7,#REF!,4,FALSE),"") -> #REF! | F7: =_xlfn.IFNA(VLOOKUP(B7,#REF!,10,FALSE),"") -> #REF! | G7: =_xlfn.IFNA(VLOOKUP(B7,#REF!,9,FALSE),"") -> #REF! | H7: =_xlfn.IFNA(VLOOKUP(B7,#REF!,11,FALSE),"") -> #REF! | J7: 2 | K7: OJ | L7: 1000000 | M7: =J7*L7 -> 2000000
A8: Jumlah | M8: =SUM(M7:M7) -> 2000000
A10: B. Honorarium Moderator | B10: Honorarium Moderator
A11: No | B11: Nama Pegawai | C11: Jabatan dalam Tugas | D11: NIK | E11: NPWP | F11: No. Rekening | G11: Nama Rekening | H11: Nama Bank | I11: Email | J11: Vol | K11: Satuan | L11: Biaya Satuan | M11: Total
A12: 1 | B12: Dendy Rosman | C12: Moderator | D12: =_xlfn.IFNA(VLOOKUP(B12,#REF!,3,FALSE),"") -> #REF! | E12: =_xlfn.IFNA(VLOOKUP(B12,#REF!,4,FALSE),"") -> #REF! | F12: =_xlfn.IFNA(VLOOKUP(B12,#REF!,10,FALSE),"") -> #REF! | G12: =_xlfn.IFNA(VLOOKUP(B12,#REF!,9,FALSE),"") -> #REF! | H12: =_xlfn.IFNA(VLOOKUP(B12,#REF!,11,FALSE),"") -> #REF! | J12: 1 | K12: OJ | L12: 700000 | M12: =J12*L12 -> 700000
A13: Jumlah | M13: =SUM(M12:M12) -> 700000
A15: C. | B15: Honorarium Panitia
A16: No | B16: Nama Pegawai | C16: Jabatan dalam Tugas | D16: NIK | E16: NPWP | F16: No. Rekening | G16: Nama Rekening | H16: Nama Bank | I16: Email | J16: Vol | K16: Satuan | L16: Biaya Satuan | M16: Total
A17: 1 | B17: Dr. Hendri Tambunan, SE.,M.A | C17: Penanggungjawab | D17: =_xlfn.IFNA(VLOOKUP(B17,#REF!,3,FALSE),"") -> #REF! | E17: =_xlfn.IFNA(VLOOKUP(B17,#REF!,4,FALSE),"") -> #REF! | F17: =_xlfn.IFNA(VLOOKUP(B17,#REF!,10,FALSE),"") -> #REF! | G17: =_xlfn.IFNA(VLOOKUP(B17,#REF!,9,FALSE),"") -> #REF! | H17: =_xlfn.IFNA(VLOOKUP(B17,#REF!,11,FALSE),"") -> #REF! | J17: 1 | K17: OK | L17: 225000 | M17: =J17*L17 -> 225000
A18: 2 | B18: Taufan Setyo Pranggono | C18: Ketua | D18: =_xlfn.IFNA(VLOOKUP(B18,#REF!,3,FALSE),"") -> #REF! | E18: =_xlfn.IFNA(VLOOKUP(B18,#REF!,4,FALSE),"") -> #REF! | F18: =_xlfn.IFNA(VLOOKUP(B18,#REF!,10,FALSE),"") -> #REF! | G18: =_xlfn.IFNA(VLOOKUP(B18,#REF!,9,FALSE),"") -> #REF! | H18: =_xlfn.IFNA(VLOOKUP(B18,#REF!,11,FALSE),"") -> #REF! | J18: 1 | K18: OK | L18: 200000 | M18: =J18*L18 -> 200000
A19: 3 | B19: Yudha Satria | C19: Wakil Ketua | D19: =_xlfn.IFNA(VLOOKUP(B19,#REF!,3,FALSE),"") -> #REF! | E19: =_xlfn.IFNA(VLOOKUP(B19,#REF!,4,FALSE),"") -> #REF! | F19: =_xlfn.IFNA(VLOOKUP(B19,#REF!,10,FALSE),"") -> #REF! | G19: =_xlfn.IFNA(VLOOKUP(B19,#REF!,9,FALSE),"") -> #REF! | H19: =_xlfn.IFNA(VLOOKUP(B19,#REF!,11,FALSE),"") -> #REF! | J19: 1 | K19: OK | L19: 150000 | M19: =J19*L19 -> 150000
A20: 4 | B20: Nur Fadillah | C20: Sekretaris | D20: =_xlfn.IFNA(VLOOKUP(B20,#REF!,3,FALSE),"") -> #REF! | E20: =_xlfn.IFNA(VLOOKUP(B20,#REF!,4,FALSE),"") -> #REF! | F20: =_xlfn.IFNA(VLOOKUP(B20,#REF!,10,FALSE),"") -> #REF! | G20: =_xlfn.IFNA(VLOOKUP(B20,#REF!,9,FALSE),"") -> #REF! | H20: =_xlfn.IFNA(VLOOKUP(B20,#REF!,11,FALSE),"") -> #REF! | J20: 1 | K20: OK | L20: 150000 | M20: =J20*L20 -> 150000
A21: 5 | B21: Welfrid Phedra Sipahutar | C21: Anggota | D21: =_xlfn.IFNA(VLOOKUP(B21,#REF!,3,FALSE),"") -> #REF! | E21: =_xlfn.IFNA(VLOOKUP(B21,#REF!,4,FALSE),"") -> #REF! | F21: =_xlfn.IFNA(VLOOKUP(B21,#REF!,10,FALSE),"") -> #REF! | G21: =_xlfn.IFNA(VLOOKUP(B21,#REF!,9,FALSE),"") -> #REF! | H21: =_xlfn.IFNA(VLOOKUP(B21,#REF!,11,FALSE),"") -> #REF! | J21: 1 | K21: OK | L21: 150000 | M21: =J21*L21 -> 150000
A22: 6 | B22: Reviva Rosmawati | C22: Anggota | D22: =_xlfn.IFNA(VLOOKUP(B22,#REF!,3,FALSE),"") -> #REF! | E22: =_xlfn.IFNA(VLOOKUP(B22,#REF!,4,FALSE),"") -> #REF! | F22: =_xlfn.IFNA(VLOOKUP(B22,#REF!,10,FALSE),"") -> #REF! | G22: =_xlfn.IFNA(VLOOKUP(B22,#REF!,9,FALSE),"") -> #REF! | H22: =_xlfn.IFNA(VLOOKUP(B22,#REF!,11,FALSE),"") -> #REF! | J22: 1 | K22: OK | L22: 150000 | M22: =J22*L22 -> 150000
A23: 7 | B23: Prayitno | C23: Anggota | D23: =_xlfn.IFNA(VLOOKUP(B23,#REF!,3,FALSE),"") -> #REF! | E23: =_xlfn.IFNA(VLOOKUP(B23,#REF!,4,FALSE),"") -> #REF! | F23: =_xlfn.IFNA(VLOOKUP(B23,#REF!,10,FALSE),"") -> #REF! | G23: =_xlfn.IFNA(VLOOKUP(B23,#REF!,9,FALSE),"") -> #REF! | H23: =_xlfn.IFNA(VLOOKUP(B23,#REF!,11,FALSE),"") -> #REF! | J23: 1 | K23: OK | L23: 150000 | M23: =J23*L23 -> 150000
A24: Jumlah | M24: =SUM(M17:M23) -> 1175000
A26: D. | B26: Transport Kegiatan Dalam Kota
A27: No | B27: Nama Pegawai | C27: Jabatan dalam Tugas | D27: NIK | E27: NPWP | F27: No. Rekening | G27: Nama Rekening | H27: Nama Bank | I27: Email | J27: Vol | K27: Satuan | L27: Biaya Satuan | M27: Total
A28: 1 | B28: Taufan Setyo Pranggono | C28: Ketua | D28: =_xlfn.IFNA(VLOOKUP(B28,#REF!,3,FALSE),"") -> #REF! | E28: =_xlfn.IFNA(VLOOKUP(B28,#REF!,4,FALSE),"") -> #REF! | F28: =_xlfn.IFNA(VLOOKUP(B28,#REF!,10,FALSE),"") -> #REF! | G28: =_xlfn.IFNA(VLOOKUP(B28,#REF!,9,FALSE),"") -> #REF! | H28: =_xlfn.IFNA(VLOOKUP(B28,#REF!,11,FALSE),"") -> #REF! | J28: 1 | K28: OH | L28: 170000 | M28: =J28*L28 -> 170000
A29: 2 | B29: Yudha Satria | C29: Wakil Ketua | D29: =_xlfn.IFNA(VLOOKUP(B29,#REF!,3,FALSE),"") -> #REF! | E29: =_xlfn.IFNA(VLOOKUP(B29,#REF!,4,FALSE),"") -> #REF! | F29: =_xlfn.IFNA(VLOOKUP(B29,#REF!,10,FALSE),"") -> #REF! | G29: =_xlfn.IFNA(VLOOKUP(B29,#REF!,9,FALSE),"") -> #REF! | H29: =_xlfn.IFNA(VLOOKUP(B29,#REF!,11,FALSE),"") -> #REF! | J29: 1 | K29: OH | L29: 170000 | M29: =J29*L29 -> 170000
A30: 3 | B30: Nur Fadillah | C30: Sekretaris | D30: =_xlfn.IFNA(VLOOKUP(B30,#REF!,3,FALSE),"") -> #REF! | E30: =_xlfn.IFNA(VLOOKUP(B30,#REF!,4,FALSE),"") -> #REF! | F30: =_xlfn.IFNA(VLOOKUP(B30,#REF!,10,FALSE),"") -> #REF! | G30: =_xlfn.IFNA(VLOOKUP(B30,#REF!,9,FALSE),"") -> #REF! | H30: =_xlfn.IFNA(VLOOKUP(B30,#REF!,11,FALSE),"") -> #REF! | J30: 1 | K30: OH | L30: 170000 | M30: =J30*L30 -> 170000
A31: 4 | B31: Welfrid Phedra Sipahutar | C31: Anggota | D31: =_xlfn.IFNA(VLOOKUP(B31,#REF!,3,FALSE),"") -> #REF! | E31: =_xlfn.IFNA(VLOOKUP(B31,#REF!,4,FALSE),"") -> #REF! | F31: =_xlfn.IFNA(VLOOKUP(B31,#REF!,10,FALSE),"") -> #REF! | G31: =_xlfn.IFNA(VLOOKUP(B31,#REF!,9,FALSE),"") -> #REF! | H31: =_xlfn.IFNA(VLOOKUP(B31,#REF!,11,FALSE),"") -> #REF! | J31: 1 | K31: OH | L31: 170000 | M31: =J31*L31 -> 170000
A32: 5 | B32: Reviva Rosmawati | C32: Anggota | D32: =_xlfn.IFNA(VLOOKUP(B32,#REF!,3,FALSE),"") -> #REF! | E32: =_xlfn.IFNA(VLOOKUP(B32,#REF!,4,FALSE),"") -> #REF! | F32: =_xlfn.IFNA(VLOOKUP(B32,#REF!,10,FALSE),"") -> #REF! | G32: =_xlfn.IFNA(VLOOKUP(B32,#REF!,9,FALSE),"") -> #REF! | H32: =_xlfn.IFNA(VLOOKUP(B32,#REF!,11,FALSE),"") -> #REF! | J32: 1 | K32: OH | L32: 170000 | M32: =J32*L32 -> 170000
A33: 6 | B33: Prayitno | C33: Anggota | D33: =_xlfn.IFNA(VLOOKUP(B33,#REF!,3,FALSE),"") -> #REF! | E33: =_xlfn.IFNA(VLOOKUP(B33,#REF!,4,FALSE),"") -> #REF! | F33: =_xlfn.IFNA(VLOOKUP(B33,#REF!,10,FALSE),"") -> #REF! | G33: =_xlfn.IFNA(VLOOKUP(B33,#REF!,9,FALSE),"") -> #REF! | H33: =_xlfn.IFNA(VLOOKUP(B33,#REF!,11,FALSE),"") -> #REF! | J33: 1 | K33: OH | L33: 170000 | M33: =J33*L33 -> 170000
A34: Jumlah | M34: =SUM(M28:M33) -> 1020000
A36: E. | B36: Uang Saku/ Uang Harian Kegiatan Dalam Kota
A37: No | B37: Nama Pegawai | C37: Jabatan dalam Tugas | D37: NIK | E37: NPWP | F37: No. Rekening | G37: Nama Rekening | H37: Nama Bank | I37: Email | J37: Vol | K37: Satuan | L37: Biaya Satuan | M37: Total
A38: 1 | B38: Dr. Hendri Tambunan, SE.,M.A | C38: Penanggungjawab | D38: =_xlfn.IFNA(VLOOKUP(B38,#REF!,3,FALSE),"") -> #REF! | E38: =_xlfn.IFNA(VLOOKUP(B38,#REF!,4,FALSE),"") -> #REF! | F38: =_xlfn.IFNA(VLOOKUP(B38,#REF!,10,FALSE),"") -> #REF! | G38: =_xlfn.IFNA(VLOOKUP(B38,#REF!,9,FALSE),"") -> #REF! | H38: =_xlfn.IFNA(VLOOKUP(B38,#REF!,11,FALSE),"") -> #REF! | J38: 1 | K38: OH | L38: 130000 | M38: =J38*L38 -> 130000
A39: 2 | B39: Taufan Setyo Pranggono | C39: Ketua | D39: =_xlfn.IFNA(VLOOKUP(B39,#REF!,3,FALSE),"") -> #REF! | E39: =_xlfn.IFNA(VLOOKUP(B39,#REF!,4,FALSE),"") -> #REF! | F39: =_xlfn.IFNA(VLOOKUP(B39,#REF!,10,FALSE),"") -> #REF! | G39: =_xlfn.IFNA(VLOOKUP(B39,#REF!,9,FALSE),"") -> #REF! | H39: =_xlfn.IFNA(VLOOKUP(B39,#REF!,11,FALSE),"") -> #REF! | J39: 1 | K39: OH | L39: 130000 | M39: =J39*L39 -> 130000
A40: 3 | B40: Yudha Satria | C40: Wakil Ketua | D40: =_xlfn.IFNA(VLOOKUP(B40,#REF!,3,FALSE),"") -> #REF! | E40: =_xlfn.IFNA(VLOOKUP(B40,#REF!,4,FALSE),"") -> #REF! | F40: =_xlfn.IFNA(VLOOKUP(B40,#REF!,10,FALSE),"") -> #REF! | G40: =_xlfn.IFNA(VLOOKUP(B40,#REF!,9,FALSE),"") -> #REF! | H40: =_xlfn.IFNA(VLOOKUP(B40,#REF!,11,FALSE),"") -> #REF! | J40: 1 | K40: OH | L40: 130000 | M40: =J40*L40 -> 130000
A41: 4 | B41: Nur Fadillah | C41: Sekretaris | D41: =_xlfn.IFNA(VLOOKUP(B41,#REF!,3,FALSE),"") -> #REF! | E41: =_xlfn.IFNA(VLOOKUP(B41,#REF!,4,FALSE),"") -> #REF! | F41: =_xlfn.IFNA(VLOOKUP(B41,#REF!,10,FALSE),"") -> #REF! | G41: =_xlfn.IFNA(VLOOKUP(B41,#REF!,9,FALSE),"") -> #REF! | H41: =_xlfn.IFNA(VLOOKUP(B41,#REF!,11,FALSE),"") -> #REF! | J41: 1 | K41: OH | L41: 130000 | M41: =J41*L41 -> 130000
A42: 5 | B42: Welfrid Phedra Sipahutar | C42: Anggota | D42: =_xlfn.IFNA(VLOOKUP(B42,#REF!,3,FALSE),"") -> #REF! | E42: =_xlfn.IFNA(VLOOKUP(B42,#REF!,4,FALSE),"") -> #REF! | F42: =_xlfn.IFNA(VLOOKUP(B42,#REF!,10,FALSE),"") -> #REF! | G42: =_xlfn.IFNA(VLOOKUP(B42,#REF!,9,FALSE),"") -> #REF! | H42: =_xlfn.IFNA(VLOOKUP(B42,#REF!,11,FALSE),"") -> #REF! | J42: 1 | K42: OH | L42: 130000 | M42: =J42*L42 -> 130000
A43: 6 | B43: Reviva Rosmawati | C43: Anggota | D43: =_xlfn.IFNA(VLOOKUP(B43,#REF!,3,FALSE),"") -> #REF! | E43: =_xlfn.IFNA(VLOOKUP(B43,#REF!,4,FALSE),"") -> #REF! | F43: =_xlfn.IFNA(VLOOKUP(B43,#REF!,10,FALSE),"") -> #REF! | G43: =_xlfn.IFNA(VLOOKUP(B43,#REF!,9,FALSE),"") -> #REF! | H43: =_xlfn.IFNA(VLOOKUP(B43,#REF!,11,FALSE),"") -> #REF! | J43: 1 | K43: OH | L43: 130000 | M43: =J43*L43 -> 130000
A44: 7 | B44: Prayitno | C44: Anggota | D44: =_xlfn.IFNA(VLOOKUP(B44,#REF!,3,FALSE),"") -> #REF! | E44: =_xlfn.IFNA(VLOOKUP(B44,#REF!,4,FALSE),"") -> #REF! | F44: =_xlfn.IFNA(VLOOKUP(B44,#REF!,10,FALSE),"") -> #REF! | G44: =_xlfn.IFNA(VLOOKUP(B44,#REF!,9,FALSE),"") -> #REF! | H44: =_xlfn.IFNA(VLOOKUP(B44,#REF!,11,FALSE),"") -> #REF! | J44: 1 | K44: OH | L44: 130000 | M44: =J44*L44 -> 130000
A45: Jumlah | M45: =SUM(M38:M44) -> 910000
...

Sheet Panitia
A1: Lampiran :
A2: Surat Keputusan Lembaga Layanan Pendidikan Tinggi Wilayah III Jakarta | Q2: Notes :
A3: Nomor : ………………. Tanggal. ……………….. | Q3: 1. Honorarium Panitia satuannya adalah Orang/Kegiatan
A4: DAFTAR PEMBAYARAN HONORARIUM PANITIA | Q4: 2. Jumlah Kepanitian paling banyak 10% dari Jumlah Peserta Undangan Kegiatan
A5: PADA KEGIATAN Rapat Analisa Kebutuhan Tahap I Pengembangan Aplikasi Pelaporan BKD | Q5: 3. Perlakuan Pajak untuk Pembayaran Honorarium :
A6: DI LINGKUNGAN LEMBAGA LAYANAN PENDIDIKAN TINGGI WILAYAH III JAKARTA TAHUN ANGGARAN 2020 | Q6: - | R6: PNS Gol. IV dikenakan Tarif 15% dari Jumlah Bruto
A7: DI Ruang Kartini Kantor LLDIKTI Wilayah III PADA TANGGAL 7 Agustus 2020 | Q7: - | R7: PNS Gol. III dikenakan Tarif 5% dari Jumlah Bruto
Q8: - | R8: PNS Gol. II dikenakan Tarif 0% dari Jumlah Bruto
A9: No. | B9: Nama | C9: NIK | D9: NPWP | E9: Status / Gol | F9: Jabatan | G9: Honorarium | J9: PPH 21 | L9: Jumlah Diterima | M9: Tanda Tangan | Q9: - | R9: Non PNS punya NPWP dikenakan Tarif 5% dari setengah Jumlah Bruto
G10: Jml Keg | H10: Rp./Keg | I10: Jml Bruto | J10: Tarif * | K10: Jml Pajak | Q10: - | R10: Non PNS tidak punya NPWP dikenakan Tarif 6% dari setengah Jumlah Bruto
A11: A | B11: B | C11: C | D11: D | E11: E | F11: F | G11: G | H11: H | I11: I=GxH | J11: K | K11: L=IxK | L11: M | M11: N
A12: 1
B13: Jumlah Total | G13: 0 | I13: 0 | J13: 0 | K13: 0 | L13: 0
A14: Terbilang : | B14: Terbilang : | D14: #NAME?
A16: * Sesuai PMK No. 252/PMK/03/2008 Pasal 20 Ayat 1 Tentang Petunjuk Pelaksanaan Pemotongan Pajak atas Penghasilan Sehubungan Pekerjaan, Jasa, dan Kegiatan Orang Pribadi
K17: Jakarta, 11 Januari 2023
A18: Mengetahui/Menyetujui | E18: Lunas dibayar tanggal:
A19: an. Kuasa Pengguna Anggaran | E19: Bendahara Pengeluaran, | K19: Pembuat Daftar
A20: Pejabat Pembuat Komitmen
A23: M. Samsuri | E23: Elih Ermawati | K23: ……………...………
A24: NIP. 19790114 200312 1001 | E24: NIP. 19860915 200912 2006 | K24: NIP. …………………..

Sheet Moderator
A1: Lampiran :
A2: Surat Keputusan Lembaga Layanan Pendidikan Tinggi Wilayah III Jakarta | P2: Notes :
A3: Nomor : ………………. Tanggal. ……………….. | P3: 1. Honorarium Moderator satuannya adalah orang/Kali
P4: 2. SBU untuk sekali tampil sebagai moderator adalah sebesar Rp. 700.000,-
A5: DAFTAR PEMBAYARAN HONORARIUM MODERATOR | P5: 3. Perlakuan Pajak untuk Pembayaran Honorarium :
A6: PADA KEGIATAN Rapat Analisa Kebutuhan Tahap I Pengembangan Aplikasi Pelaporan BKD | P6: - | Q6: PNS Gol. IV dikenakan Tarif 15% dari Jumlah Bruto
A7: DI LINGKUNGAN LEMBAGA LAYANAN PENDIDIKAN TINGGI WILAYAH III JAKARTA TAHUN ANGGARAN 2020 | P7: - | Q7: PNS Gol. III dikenakan Tarif 5% dari Jumlah Bruto
A8: DI Ruang Kartini Kantor LLDIKTI Wilayah III PADA TANGGAL 7 Agustus 2020 | P8: - | Q8: PNS Gol. II dikenakan Tarif 0% dari Jumlah Bruto
P9: - | Q9: Non PNS punya NPWP dikenakan Tarif 5% dari setengah Jumlah Bruto
A10: No. | B10: Nama | C10: NIK | D10: NPWP | E10: Gol | F10: Honorarium | I10: PPH 21 | K10: Jumlah Diterima | L10: Tanda Tangan | P10: - | Q10: Non PNS tidak punya NPWP dikenakan Tarif 6% dari setengah Jumlah Bruto
F11: Jml Kali | G11: Rp./Kali | H11: Jml Bruto | I11: Tarif | J11: Jml Pajak
A12: A | B12: B | C12: C | D12: D | E12: E | F12: F | G12: G | H12: H=FxG | I12: I | J12: J=HxI | K12: K=H-J | L12: L
A13: 1 | C13: =VLOOKUP(B13,#REF!,3,0) -> #REF! | D13: =VLOOKUP(B13,#REF!,4,0) -> #REF! | E13: =VLOOKUP(B13,#REF!,5,0) -> #REF! | H13: =G13*F13 -> 0 | I13: 0 | J13: =H13*I13 -> 0 | K13: =H13-J13 -> 0 | L13: =A13&"…...……..…" -> 1…...……..…
B14: Jumlah Total | F14: 0 | H14: 0 | I14: 0 | J14: 0 | K14: 0
A15: Terbilang : | B15: Terbilang : | C15: #NAME?
A17: * Sesuai PMK No. 252/PMK/03/2008 Pasal 20 Ayat 1 Tentang Petunjuk Pelaksanaan Pemotongan Pajak atas Penghasilan Sehubungan Pekerjaan, Jasa, dan Kegiatan Orang Pribadi
K18: Jakarta, 11 Januari 2023
A19: Mengetahui/Menyetujui | E19: Lunas dibayar tanggal:
A20: an. Kuasa Pengguna Anggaran | E20: Bendahara Pengeluaran, | K20: Pembuat Daftar
A21: Pejabat Pembuat Komitmen
A25: M. Samsuri | E25: Elih Ermawati | K25: ……………...………
A26: NIP. 19790114 200312 1001 | E26: NIP. 19860915 200912 2006 | K26: NIP. …………………..

Sheet Narsum PNS
A1: Lampiran :
A2: Surat Keputusan Koordinator Kopertis Wilayah III Jakarta
A3: Nomor : ................. Tanggal. ...................
A5: DAFTAR PEMBAYARAN HONORARIUM NARASUMBER
A6: PADA KEGIATAN ..........................................................
A7: DILINGKUNGAN KOPERTIS WILAYAH III JAKARTA TAHUN 2017
A8: DI ........................... PADA TANGGAL ...........................
A10: No. | B10: Nama | C10: NPWP | D10: Status / Gol | E10: Honorarium | H10: PPH 21 | J10: Jumlah Diterima | K10: Tanda Tangan
E11: Jml Jam | F11: Rp./Jam | G11: Jml Bruto | H11: Tarif * | I11: Jml Pajak
A12: A | B12: B | C12: C | D12: D | E12: E | F12: F | G12: G=ExF | H12: H | I12: I=GxH | J12: J=G-I | K12: K
A13: 1 | B13: A (PNS BerNPWP Gol IV) | C13: 011111111111111 | D13: PNS/IV | E13: 2 | F13: 1000000 | G13: =F13*E13 -> 2000000 | H13: 0.15 | I13: =G13*H13 -> 300000 | J13: =G13-I13 -> 1700000 | K13: =A13&"…………...……..…" -> 1…………...……..…
A14: 2 | B14: B(PNS NonNPWP Gol IV) | C14: - | D14: PNS/IV | E14: 2 | F14: 1000000 | G14: =F14*E14 -> 2000000 | H14: 0.18 | I14: =G14*H14 -> 360000 | J14: =G14-I14 -> 1640000 | K14: =A14&"…………...……..…" -> 2…………...……..…
A15: 3 | B15: C (PNS BerNPWP Gol III) | C15: 022222222222222 | D15: PNS/III | E15: 2 | F15: 1000000 | G15: =F15*E15 -> 2000000 | H15: 0.05 | I15: =G15*H15 -> 100000 | J15: =G15-I15 -> 1900000 | K15: =A15&"…………...……..…" -> 3…………...……..…
A16: 4 | B16: D (PNS NonNPWP Gol III) | C16: - | D16: PNS/III | E16: 2 | F16: 1000000 | G16: =F16*E16 -> 2000000 | H16: 0.06 | I16: =G16*H16 -> 120000 | J16: =G16-I16 -> 1880000 | K16: =A16&"…………...……..…" -> 4…………...……..…
B17: Jumlah Total | E17: =SUM(E13:E16) -> 8 | G17: =SUM(G13:G16) -> 8000000 | H17: - | I17: =SUM(I13:I16) -> 880000 | J17: =SUM(J13:J16) -> 7120000
A18: Terbilang : | C18: #NAME?
A20: * Sesua PMK No. 252/KM/03/2008 Pasal 21 Ayat 1 Tentang Petunjuk Pelaksanaan Pemotongan Pajak atas Penghasilan Sehubungan Pekerjaan, Jasa, dan Kegiatan Orang Pribadi
J22: Jakarta, .............................
A23: Mengetahui/Menyetujui | E23: Lunas dibayar tanggal:
A24: an. Kuasa Pengguna Anggaran | E24: Bendahara Pengeluaran, | J24: Pembuat Daftar
A25: Pejabat Pembuat Komitmen
A29: Putut Pujogiri, SH | E29: Ahmad Mustaadi | J29: ...........................
A30: NIP. 19580430 198703 1001 | E30: NIP. 19660518 198902 1002 | J30: NIP. ............................

Sheet Narasumber
A1: Lampiran :
A2: Surat Keputusan Lembaga Layanan Pendidikan Tinggi Wilayah III Jakarta | Q2: Notes :
A3: Nomor : ………………. Tanggal. ……………….. | Q3: 1. Honorarium Narasumber satuannya adalah orang/Jam
Q4: 2. Satuan Jam yang digunakan untuk pembayaran Honor Narsum adalah paling sedikit 60 Menit
A5: DAFTAR PEMBAYARAN HONORARIUM NARASUMBER | Q5: 2. Ketentuan Honorarium Narasumber adalah :
A6: PADA KEGIATAN Rapat Analisa Kebutuhan Tahap I Pengembangan Aplikasi Pelaporan BKD | Q6: - | R6: PNS Gol. IV dikenakan Tarif 15% dari Jumlah Bruto
A7: DI LINGKUNGAN LEMBAGA LAYANAN PENDIDIKAN TINGGI WILAYAH III JAKARTA TAHUN ANGGARAN 2020 | Q7: - | R7: PNS Gol. III dikenakan Tarif 5% dari Jumlah Bruto
A8: DI Ruang Kartini Kantor LLDIKTI Wilayah III PADA TANGGAL 7 Agustus 2020 | Q8: 3. Perlakuan Pajak untuk Pembayaran Honorarium :
Q9: - | R9: PNS Gol. IV dikenakan Tarif 15% dari Jumlah Bruto
A10: No. | B10: Nama | C10: NIK | D10: NPWP | E10: Gol | F10: Honorarium | I10: Dasar Pengenaan Pajak (DPP) | K10: PPH 21 | M10: Jumlah Diterima | N10: Tanda Tangan | Q10: - | R10: PNS Gol. III dikenakan Tarif 5% dari Jumlah Bruto
F11: Jml Jam | G11: Rp./Jam | H11: Jml Bruto | I11: PNS (Rp.) | J11: Non PNS (Rp.) * | K11: Tarif ** | L11: Jml Pajak | Q11: - | R11: PNS Gol. II dikenakan Tarif 0% dari Jumlah Bruto
A12: A | B12: B | C12: C | D12: D | E12: E | F12: F | G12: G | H12: H=FxG | I12: I=H | J12: J=Hx50% | K12: K | L12: L=I/JxK | M12: M=H-L | N12: N | Q12: - | R12: Non PNS punya NPWP dikenakan Tarif 5% dari setengah Jumlah Bruto
A13: 1 | C13: =VLOOKUP(B13,#REF!,3,0) -> #REF! | D13: =VLOOKUP(B13,#REF!,4,0) -> #REF! | E13: =VLOOKUP(B13,#REF!,5,0) -> #REF! | H13: =G13*F13 -> 0 | I13: =H13 -> 0 | J13: 0 | K13: 0 | L13: =(I13+J13)*K13 -> 0 | M13: =H13-L13 -> 0 | N13: =A13&"………..…" -> 1………..… | Q13: - | R13: Non PNS tidak punya NPWP dikenakan Tarif 6% dari setengah Jumlah Bruto
B14: Jumlah Total | F14: 0 | H14: 0 | K14: 0 | L14: 0 | M14: 0
A15: Terbilang : | B15: Terbilang : | D15: #NAME?
A17: * Sesuai Tarif PPh 21 UU No. 36 Pasal 17 (1)a Tahun 2008 Tentang Pajak Penghasilan
A18: ** Sesua PMK No. 252/PMK/03/2008 Pasal 20 Ayat 1 Tentang Petunjuk Pelaksanaan Pemotongan Pajak atas Penghasilan Sehubungan Pekerjaan, Jasa, dan Kegiatan Orang Pribadi
M20: Jakarta, 11 Januari 2023
A21: Mengetahui/Menyetujui | F21: Lunas dibayar tanggal:
A22: an. Kuasa Pengguna Anggaran | F22: Bendahara Pengeluaran, | M22: Pembuat Daftar
A23: Pejabat Pembuat Komitmen
A27: M. Samsuri | F27: Elih Ermawati | M27: ……………...………
A28: NIP. 19790114 200312 1001 | F28: NIP. 19860915 200912 2006 | M28: NIP. …………………..

Sheet Instruktur
A1: Lampiran :
A2: Surat Keputusan Lembaga Layanan Pendidikan Tinggi Wilayah III Jakarta
A3: Nomor : ………………. Tanggal. ………………..
A5: DAFTAR PEMBAYARAN HONORARIUM INSTRUKTUR
A6: PADA KEGIATAN Rapat Analisa Kebutuhan Tahap I Pengembangan Aplikasi Pelaporan BKD
A7: DI LINGKUNGAN LEMBAGA LAYANAN PENDIDIKAN TINGGI WILAYAH III JAKARTA TAHUN ANGGARAN 2020
A8: DI Ruang Kartini Kantor LLDIKTI Wilayah III PADA TANGGAL 7 Agustus 2020
A10: No. | B10: Nama | C10: NIK | D10: NPWP | E10: Gol | F10: Honorarium | I10: Dasar Pengenaan Pajak (DPP) | K10: PPH 21 | M10: Jumlah Diterima | N10: Tanda Tangan
F11: Jml Jam | G11: Rp./Jam | H11: Jml Bruto | I11: PNS (Rp.) | J11: Non PNS (Rp.) * | K11: Tarif ** | L11: Jml Pajak
A12: A | B12: B | C12: C | D12: D | E12: E | F12: F | G12: G | H12: H=FxG | I12: I=H | J12: J=Hx50% | K12: K | L12: L=I/JxK | M12: M=H-L | N12: N
A13: 1 | C13: =VLOOKUP(B13,#REF!,3,0) -> #REF! | D13: =VLOOKUP(B13,#REF!,4,0) -> #REF! | E13: =VLOOKUP(B13,#REF!,5,0) -> #REF! | H13: =G13*F13 -> 0 | I13: =H13 -> 0 | J13: 0 | K13: 0 | L13: =(I13+J13)*K13 -> 0 | M13: =H13-L13 -> 0 | N13: =A13&"………..…" -> 1………..…
B14: Jumlah Total | F14: 0 | H14: 0 | K14: 0 | L14: 0 | M14: 0
A15: Terbilang : | B15: Terbilang : | D15: #NAME?
A17: * Sesuai Tarif PPh 21 UU No. 36 Pasal 17 (1)a Tahun 2008 Tentang Pajak Penghasilan
A18: ** Sesua PMK No. 252/PMK/03/2008 Pasal 20 Ayat 1 Tentang Petunjuk Pelaksanaan Pemotongan Pajak atas Penghasilan Sehubungan Pekerjaan, Jasa, dan Kegiatan Orang Pribadi
M20: Jakarta, 11 Januari 2023
A21: Mengetahui/Menyetujui | F21: Lunas dibayar tanggal:
A22: an. Kuasa Pengguna Anggaran | F22: Bendahara Pengeluaran, | M22: Pembuat Daftar
A23: Pejabat Pembuat Komitmen
A27: M. Samsuri | F27: Elih Ermawati | M27: ……………...………
A28: NIP. 19790114 200312 1001 | F28: NIP. 19860915 200912 2006 | M28: NIP. …………………..

Sheet Perjadin
A1: Lampiran :
A2: Surat Tugas Sekretarsi Lembaga Layanan Pendidikan Tinggi Wilayah III Jakarta
A3: Nomor : ……………………. Tanggal. ………………..
A5: DAFTAR PEMBAYARAN TRANSPORT DAN UANG HARIAN PERJALANAN DINAS
A6: PADA KEGIATAN Rapat Analisa Kebutuhan Tahap I Pengembangan Aplikasi Pelaporan BKD
A7: DI LINGKUNGAN LEMBAGA LAYANAN PENDIDIKAN TINGGI WILAYAH III JAKARTA TAHUN ANGGARAN 2020
A8: DI Ruang Kartini Kantor LLDIKTI Wilayah III PADA TANGGAL 7 Agustus 2020
A10: No | B10: Nama | C10: Jml Hari | E10: Jumlah Uang Harian (Rp.) | F10: Transport (Rp.) | G10: Jumlah Diterima (Rp.) | H10: Tanda Tangan
A12: A | B12: B | C12: C | D12: D | E12: E=CxD | F12: F | G12: G=E+F | H12: H
A13: 1 | C13: 0 | D13: 0 | E13: =C13*D13 -> 0 | F13: 0 | G13: =E13+F13 -> 0 | H13: =A13&"…...……" -> 1…...……
A14: 2 | C14: 0 | D14: 0 | E14: =C14*D14 -> 0 | F14: 0 | G14: =E14+F14 -> 0 | H14: =A14&"…...……" -> 2…...……
A15: 3 | C15: 0 | D15: 0 | E15: =C15*D15 -> 0 | F15: 0 | G15: =E15+F15 -> 0 | H15: =A15&"…...……" -> 3…...……
A16: 4 | C16: 0 | D16: 0 | E16: =C16*D16 -> 0 | F16: 0 | G16: =E16+F16 -> 0 | H16: =A16&"…...……" -> 4…...……
A17: 5 | C17: 0 | D17: 0 | E17: =C17*D17 -> 0 | F17: 0 | G17: =E17+F17 -> 0 | H17: =A17&"…...……" -> 5…...……
A18: 6 | C18: 0 | D18: 0 | E18: =C18*D18 -> 0 | F18: 0 | G18: =E18+F18 -> 0 | H18: =A18&"…...……" -> 6…...……
A19: 7 | C19: 0 | D19: 0 | E19: =C19*D19 -> 0 | F19: 0 | G19: =E19+F19 -> 0 | H19: =A19&"…...……" -> 7…...……
A20: 8 | C20: 0 | D20: 0 | E20: =C20*D20 -> 0 | F20: 0 | G20: =E20+F20 -> 0 | H20: =A20&"…...……" -> 8…...……
A21: 9 | C21: 0 | D21: 0 | E21: =C21*D21 -> 0 | F21: 0 | G21: =E21+F21 -> 0 | H21: =A21&"…...……" -> 9…...……
A22: 10 | C22: 0 | D22: 0 | E22: =C22*D22 -> 0 | F22: 0 | G22: =E22+F22 -> 0 | H22: =A22&"…...……" -> 10…...……
A23: 11 | C23: 0 | D23: 0 | E23: =C23*D23 -> 0 | F23: 0 | G23: =E23+F23 -> 0 | H23: =A23&"…...……" -> 11…...……
A24: 12 | C24: 0 | D24: 0 | E24: =C24*D24 -> 0 | F24: 0 | G24: =E24+F24 -> 0 | H24: =A24&"…...……" -> 12…...……
... A33: 21 | C33: 0 | D33: 0 | E33: =C33*D33 -> 0 | F33: 0 | G33: =E33+F33 -> 0 | H33: =A33&"…...……" -> 21…...……
A34: Jumlah | C34: 0 | D34: 0 | E34: 0 | F34: 0 | G34: 0
A35: Terbilang : | C35: #NAME?
G37: Jakarta, 11 Januari 2023
A38: Mengetahui/Menyetujui | D38: Lunas dibayar tanggal:
A39: an. Kuasa Pengguna Anggaran | D39: Bendahara Pengeluaran, | G39: Pembuat Daftar
A40: Pejabat Pembuat Komitmen
A44: M. Samsuri | D44: Elih Ermawati | G44: ……………...………
A45: NIP. 19790114 200312 1001 | D45: NIP. 19860915 200912 2006 | G45: NIP. …………………..

Sheet Transport
A1: Lampiran :
A2: Surat Tugas Sekretarsi Lembaga Layanan Pendidikan Tinggi Wilayah III Jakarta
A3: Nomor : ……………………. Tanggal. ………………..
A5: DAFTAR PEMBAYARAN TRANSPORT PERJALANAN DINAS
A6: PADA KEGIATAN Rapat Analisa Kebutuhan Tahap I Pengembangan Aplikasi Pelaporan BKD
A7: DI LINGKUNGAN LEMBAGA LAYANAN PENDIDIKAN TINGGI WILAYAH III JAKARTA TAHUN ANGGARAN 2020
A8: DI Ruang Kartini Kantor LLDIKTI Wilayah III PADA TANGGAL 7 Agustus 2020
A10: No | B10: Nama | C10: Jml Hari | D10: Transport (Rp.) | E10: Jumlah Diterima (Rp.) | F10: Tanda Tangan
A12: A | B12: B | C12: C | D12: D | E12: E=CxD | F12: F
A13: 1 | B13: Herlambang Brawijaya | C13: 1 | D13: 150000 | E13: =C13*D13 -> 150000 | F13: =A13&"…...……" -> 1…...……
A14: 2 | B14: Yudhistira | C14: 1 | D14: 150000 | E14: =C14*D14 -> 150000 | F14: 2………
A15: 3 | B15: Selamet Widodo | C15: 1 | D15: 150000 | E15: 150000 | F15: 3………
A16: 4 | B16: Verry Riyanto | C16: 1 | D16: 150000 | E16: 150000 | F16: 4………
A17: 5 | B17: Abdul Hamid | C17: 1 | D17: 150000 | E17: 150000 | F17: 5………
A18: 6 | B18: Mochamad Abdul Azis | C18: 1 | D18: 150000 | E18: 150000 | F18: 6………
A19: 7 | C19: 0 | D19: 0 | E19: =C19*D19 -> 0 | F19: =A19&"…...……" -> 7…...……
A20: 8 | C20: 0 | D20: 0 | E20: =C20*D20 -> 0 | F20: =A20&"…...……" -> 8…...……
A21: 9 | C21: 0 | D21: 0 | E21: =C21*D21 -> 0 | F21: =A21&"…...……" -> 9…...……
A22: 10 | C22: 0 | D22: 0 | E22: =C22*D22 -> 0 | F22: =A22&"…...……" -> 10…...……
A23: 11 | C23: 0 | D23: 0 | E23: =C23*D23 -> 0 | F23: =A23&"…...……" -> 11…...……
A24: 12 | C24: 0 | D24: 0 | E24: =C24*D24 -> 0 | F24: =A24&"…...……" -> 12…...……
A25: 13 | C25: 0 | D25: 0 | E25: =C25*D25 -> 0 | F25: =A25&"…...……" -> 13…...……
A26: 14 | C26: 0 | D26: 0 | E26: =C26*D26 -> 0 | F26: =A26&"…...……" -> 14…...……
A27: 15 | C27: 0 | D27: 0 | E27: =C27*D27 -> 0 | F27: =A27&"…...……" -> 15…...……
A28: 16 | C28: 0 | D28: 0 | E28: =C28*D28 -> 0 | F28: =A28&"…...……" -> 16…...……
A29: 17 | C29: 0 | D29: 0 | E29: =C29*D29 -> 0 | F29: =A29&"…...……" -> 17…...……
A30: 18 | C30: 0 | D30: 0 | E30: =C30*D30 -> 0 | F30: =A30&"…...……" -> 18…...……
... A33: 21 | C33: 0 | D33: 0 | E33: =C33*D33 -> 0 | F33: =A33&"…...……" -> 21…...……
A34: Jumlah | C34: 6 | D34: 900000 | E34: 900000
A35: Terbilang : | C35: #NAME?
E37: Jakarta, 11 Januari 2023
A38: Mengetahui/Menyetujui | C38: Lunas dibayar tanggal:
A39: an. Kuasa Pengguna Anggaran | C39: Bendahara Pengeluaran, | E39: Pembuat Daftar
A40: Pejabat Pembuat Komitmen
A44: M. Samsuri | C44: Elih Ermawati | E44: ……………...………
A45: NIP. 19790114 200312 1001 | C45: NIP. 19860915 200912 2006 | E45: NIP. …………………..

Sheet RDK
A1: Lampiran :
A2: Surat Tugas Sekretarsi Lembaga Layanan Pendidikan Tinggi Wilayah III Jakarta | I2: Notes :
A3: Nomor : ……………………. Tanggal. ……………….. | I3: Uang Saku RDK diberikan
A5: DAFTAR PEMBAYARAN RAPAT DILUAR JAM KERJA
A6: PADA KEGIATAN Rapat Analisa Kebutuhan Tahap I Pengembangan Aplikasi Pelaporan BKD
A7: DI LINGKUNGAN LEMBAGA LAYANAN PENDIDIKAN TINGGI WILAYAH III JAKARTA TAHUN ANGGARAN 2020
A8: DI Ruang Kartini Kantor LLDIKTI Wilayah III PADA TANGGAL 7 Agustus 2020
A10: No | B10: Nama | D10: Uang Saku Dalam Kantor (Rp.) | E10: Jumlah Diterima (Rp) | F10: Tanda Tangan
A12: A | B12: B | C12: C | D12: D | E12: E=CxD | F12: F
A13: 1 | C13: 3 | D13: 0 | E13: =C13*D13 -> 0 | F13: =A13&"…...……" -> 1…...……
A14: 2 | C14: 3 | D14: 0 | E14: =C14*D14 -> 0 | F14: =A14&"…...……" -> 2…...……
A15: 3 | C15: 3 | D15: 0 | E15: =C15*D15 -> 0 | F15: =A15&"…...……" -> 3…...……
A16: 4 | C16: 3 | D16: 0 | E16: =C16*D16 -> 0 | F16: =A16&"…...……" -> 4…...……
A17: 5 | C17: 3 | D17: 0 | E17: =C17*D17 -> 0 | F17: =A17&"…...……" -> 5…...……
A18: 6 | C18: 3 | D18: 0 | E18: =C18*D18 -> 0 | F18: =A18&"…...……" -> 6…...……
A19: 7 | C19: 3 | D19: 0 | E19: =C19*D19 -> 0 | F19: =A19&"…...……" -> 7…...……
A20: 8 | C20: 3 | D20: 0 | E20: =C20*D20 -> 0 | F20: =A20&"…...……" -> 8…...……
A21: 9 | C21: 3 | D21: 0 | E21: =C21*D21 -> 0 | F21: =A21&"…...……" -> 9…...……
A22: 10 | C22: 3 | D22: 0 | E22: =C22*D22 -> 0 | F22: =A22&"…...……" -> 10…...……
A23: 11 | C23: 3 | D23: 0 | E23: =C23*D23 -> 0 | F23: =A23&"…...……" -> 11…...……
A24: 12 | C24: 3 | D24: 0 | E24: =C24*D24 -> 0 | F24: =A24&"…...……" -> 12…...……
... A33: 21 | C33: 0 | D33: 0 | E33: =C33*D33 -> 0 | F33: =A33&"…...……" -> 21…...……
A34: Jumlah | C34: 0 | D34: 0 | E34: 0
A35: Terbilang : | C35: #NAME?
E37: Jakarta, 11 Januari 2023
A38: Mengetahui/Menyetujui | C38: Lunas dibayar tanggal:
A39: an. Kuasa Pengguna Anggaran | C39: Bendahara Pengeluaran, | E39: Pembuat Daftar
A40: Pejabat Pembuat Komitmen
A44: M. Samsuri | C44: Elih Ermawati | E44: ……………...………
A45: NIP. 19790114 200312 1001 | C45: NIP. 19860915 200912 2006 | E45: NIP. …………………..

Sheet Perjadin Akt II
A1: Lampiran :
A2: Surat Tugas Sekretaris Pelaksana Kopertis Wilayah III Jakarta
A3: Nomor : 640/K3/KP/2018 Tanggal. 30 April 2018
A5: DAFTAR PEMBAYARAN TRANSPORT DAN UANG HARIAN PERJALANAN DINAS
A6: PADA KEGIATAN SOSIALISASI PENGEMBANGAN TATA NILAI, BUDAYA KERJA
A7: DAN KODE ETIK BAGI DOSEN PNS YANG DITUGASKAN PADA PERGURUAN TINGGI SWASTA
A8: DILINGKUNGAN KOPERTIS WILAYAH III JAKARTA TAHUN 2018 ANGKATAN KE-II
A9: DI SWISS BELHOTEL KALIBATA, JAKARTA PADA TANGGAL 15 MEI 2018
A11: No | B11: Nama | C11: JML HARI | D11: UANG HARIAN / HARI | E11: JUMLAH UANG HARIAN | F11: TRANSPORT | G11: JUMLAH DITERIMA (RP) | H11: TANDA TANGAN
A13: A | B13: B | C13: C | D13: D | E13: E=(CxD) | F13: F | G13: G=(E+F) | H13: H
A14: 1 | B14: Tri Haryani | C14: 1 | D14: 0 | E14: =C14*D14 -> 0 | F14: 150000 | G14: =E14+F14 -> 150000 | H14: =A14&"…...……" -> 1…...……
A15: 2 | B15: Adi Sulistyo | C15: 1 | D15: 0 | E15: =C15*D15 -> 0 | F15: 150000 | G15: =E15+F15 -> 150000 | H15: =A15&"…...……" -> 2…...……
A16: 3 | B16: Putut Pujogiri | C16: 1 | D16: 0 | E16: =C16*D16 -> 0 | F16: 150000 | G16: =E16+F16 -> 150000 | H16: =A16&"…...……" -> 3…...……
A17: 4 | B17: Herlina | C17: 1 | D17: 130000 | E17: =C17*D17 -> 130000 | F17: 150000 | G17: =E17+F17 -> 280000 | H17: =A17&"…...……" -> 4…...……
A18: 5 | B18: Agung Permana | C18: 1 | D18: 130000 | E18: =C18*D18 -> 130000 | F18: 150000 | G18: =E18+F18 -> 280000 | H18: =A18&"…...……" -> 5…...……
A19: 6 | B19: Yulianti AS | C19: 1 | D19: 130000 | E19: =C19*D19 -> 130000 | F19: 150000 | G19: =E19+F19 -> 280000 | H19: =A19&"…...……" -> 6…...……
A20: 7 | B20: Rini Hartanti | C20: 1 | D20: 130000 | E20: =C20*D20 -> 130000 | F20: 150000 | G20: =E20+F20 -> 280000 | H20: =A20&"…...……" -> 7…...……
A21: 8 | B21: Sunarti | C21: 1 | D21: 130000 | E21: =C21*D21 -> 130000 | F21: 150000 | G21: =E21+F21 -> 280000 | H21: =A21&"…...……" -> 8…...……
A22: 9 | B22: Taufan Setyo Pranggono | C22: 1 | D22: 130000 | E22: =C22*D22 -> 130000 | F22: 150000 | G22: =E22+F22 -> 280000 | H22: =A22&"…...……" -> 9…...……
A23: 10 | B23: Siswanto | C23: 1 | D23: 130000 | E23: =C23*D23 -> 130000 | F23: 150000 | G23: =E23+F23 -> 280000 | H23: =A23&"…...……" -> 10…...……
A24: 11 | B24: Nur Fadillah | C24: 1 | D24: 130000 | E24: =C24*D24 -> 130000 | F24: 150000 | G24: =E24+F24 -> 280000 | H24: =A24&"…...……" -> 11…...……
A25: 12 | B25: Agus M. Ali | C25: 1 | D25: 130000 | E25: =C25*D25 -> 130000 | F25: 150000 | G25: =E25+F25 -> 280000 | H25: =A25&"…...……" -> 12…...……
... A32: 19 | B32: Achmadi | C32: 1 | D32: 130000 | E32: =C32*D32 -> 130000 | F32: 150000 | G32: =E32+F32 -> 280000 | H32: =A32&"…...……" -> 19…...……
A33: Jumlah | C33: =SUM(C14:C32) -> 19 | D33: =SUM(D14:D32) -> 2080000 | E33: =SUM(E14:E32) -> 2080000 | F33: =SUM(F14:F32) -> 2850000 | G33: =SUM(G14:G32) -> 4930000
A34: Terbilang : | C34: #NAME?
G36: Jakarta, 7 Mei 2018
A37: Mengetahui/Menyetujui | C37: Lunas dibayar tanggal:
A38: an. Kuasa Pengguna Anggaran | C38: Bendahara Pengeluaran, | G38: Pembuat Daftar
A39: Pejabat Pembuat Komitmen
A43: Irwan Agus | C43: Ahmad Mustaadi | G43: Elih Ermawati
A44: NIP. 19630817 198303 1003 | C44: NIP. 19660518 198902 1002 | G44: NIP. 19860915 200912 2006
