Workbook
Name ________TGL1: '[1]Lembar 1'!$H$39
Name ________TGL1: '[1]Lembar 1'!$H$39
Name ________TGL1: '[2]Lembar 1'!$H$39
Name ________TGL2: '[1]Lembar 1'!$Z$39
Name ________TGL2: '[1]Lembar 1'!$Z$39
Name ________TGL2: '[2]Lembar 1'!$Z$39
Name _______TGL1: #REF!
Name _______TGL1: #REF!
Name _______TGL1: #REF!
Name _______TGL1: #REF!
Name _______TGL2: #REF!
Name _______TGL2: #REF!
Name _______TGL2: #REF!
Name _______TGL2: #REF!
Name ______TGL1: #REF!
Name ______TGL1: #REF!
Name ______TGL1: #REF!
Name ______TGL1: #REF!
Name ______TGL2: #REF!
Name ______TGL2: #REF!
Name ______TGL2: #REF!
Name _____TGL1: '[1]Lembar 1'!$H$39
Name _____TGL1: '[1]Lembar 1'!$H$39
Name _____TGL1: '[2]Lembar 1'!$H$39
Name _____TGL2: '[1]Lembar 1'!$Z$39
Name _____TGL2: '[1]Lembar 1'!$Z$39
Name _____TGL2: '[2]Lembar 1'!$Z$39
Name ____TGL1: '[1]Lembar 1'!$H$39
Name ____TGL1: '[1]Lembar 1'!$H$39
Name ____TGL1: '[2]Lembar 1'!$H$39
Name ____TGL2: '[1]Lembar 1'!$Z$39
Name ____TGL2: '[1]Lembar 1'!$Z$39
Name ____TGL2: '[2]Lembar 1'!$Z$39
Name ___TGL1: '[1]Lembar 1'!$H$39
Name ___TGL1: '[1]Lembar 1'!$H$39
Name ___TGL1: '[2]Lembar 1'!$H$39
Name ___TGL2: '[1]Lembar 1'!$Z$39
Name ___TGL2: '[1]Lembar 1'!$Z$39
Name ___TGL2: '[2]Lembar 1'!$Z$39
Name __TGL1: '[1]Lembar 1'!$H$39
Name __TGL1: '[1]Lembar 1'!$H$39
Name __TGL1: '[2]Lembar 1'!$H$39
Name __TGL2: '[1]Lembar 1'!$Z$39
Name __TGL2: '[1]Lembar 1'!$Z$39
Name __TGL2: '[2]Lembar 1'!$Z$39
Name _TGL1: #REF!
Name _TGL1: #REF!
Name _TGL1: #REF!
Name _TGL1: #REF!
Name _TGL2: #REF!
Name _TGL2: #REF!
Name _TGL2: #REF!
Name _TGL2: #REF!
Name aaa: [3]Db!$A$2:$A$15
Name ALAMAT: #REF!
Name ALAMAT: #REF!
Name ALAMAT: #REF!
Name ALAMAT: #REF!
Name anjab: [4]sampel!#REF!
Name anjab: [4]sampel!#REF!

Sheet RefAnggaran
A1: Kementerian Negara | B1: Unit Eselon I | C1: Unit Satker | D1: Program | E1: Sasaran Program | F1: Klasifikasi Rincian Output | G1: Rincian Output | H1: Kegiatan
A2: Kemendikbudristekdikti | B2: Sekretaris Jenderal | C2: Lembaga Layanan penddidikan Tinggi | D2: Program Pendidikan Tinggi | E2: Terwujudnya tata kelola LLDIKTI Wilayah III yang berkualitas | F2: Fasilitasi dan Pembinaan Lembaga | G2: Lembaga Pendidikan Tinggi Akademik dan Vokasi yang mendapatkan layanan pembinaan peningkatan mutu
D3: Program Dukungan Manajemen | E3: Meningkatnya akses, kualitas pembelajaran, dan relevansi pendidikan tinggi | F3: Bantuan Pendidikan Tinggi | G3: Lembaga Pendidikan Tinggi Akademik dan Vokasi yang mendapat layanan rekomendasi
E4: Meningkatnya kualitas dosen dan tenaga kependidikan | F4: Layanan Dukungan Manajemen Internal | G4: Dosen Non PNS yang Menerima Tunjangan Profesi/Layanan Umum
G5: Layanan Perkantoran
A7: Jabatan dalam Tugas | B7: Jenis Belanja | C7: IKU LLDikti dan PT | D7: Belanja Honor Operasional Satuan Kerja | F7: Uang Harian
A8: Penanggungjawab | B8: ATK | C8: Kesiapan kerja lulusan | D8: Honorarium Penanggung Jawab(UAPPA/Barang-W) | F8: Uang Harian Biasa
A9: Ketua | B9: Spanduk | C9: Mahasiswa di luar kampus | D9: Honorarium Koordinator(UAPPA/Barang-W) | F9: Uang Harian Fullboard
A10: Wakil Ketua | B10: Seminar Kit | C10: Dosen di luar kampus | D10: Honorarium Anggota/Petugas(UAPPA/Barang-W) | F10: Uang Harian Fullday
A11: Sekretaris | B11: Penjilidan | C11: Kualifikasi dosen | D11: Honorarium Panitia Pengadaan Barang (Non Konstruksi)pagu pengadaan di atas Rp500 juta s.d. Rp1 miliar | F11: Transpor
A12: Anggota | C12: Penerapan riset dosen | D12: Honorarium Ketua/Wakil Ketua (UAKPA/Barang) | F12: Taksi
A13: Narasumber | C13: Kemitraan program studi | D13: Honorarium Pengurus/Penyimpan Bmn Tingkat Kuasa Pengguna Barang | F13: Tiket Pesawat
A14: Pembahas | C14: Pembelajaran dalam kelas | D14: Honorarium Pejabat Kuasa Pengguna Anggaran (pagu dana di atas Rp250 miliar s.d. Rp500 miliar) | F14: Akomodasi Hotel
A15: Moderator | C15: Akreditasi Internasional | D15: Honorarium Pejabat Pembuat Komitmen (pagu dana di atas Rp250 miliar s.d. Rp500 miliar)
C16: Keunggulan layanan | D16: Honorarium Pejabat Penguji Tagihan & Penandatangan Spm (pagu dana di atas Rp250 miliar s.d. Rp500 miliar)
C17: Arsitektur Perguruan Tinggi Swasta (PTS) | D17: Honorarium Bendahara Pengeluaran (pagu dana di atas Rp250 miliar s.d. Rp500 miliar)
C18: Kampus Merdeka | D18: Honorarium Staf Pengelola (pagu dana di atas Rp250 miliar s.d. Rp500 miliar)
C19: Tiga dosa dan antikorupsi | D19: Honorarium Pejabat Pengadaan Barang/Jasa
C20: Link and match PTS

Sheet User Pokja, PPK, KPA dan PUMK
A1: NO | B1: nama_unit_kerja | C1: User | D1: Pass | E1: Nama User
A2: 1 | B2: Kuasa Pengguna Anggaran | C2: kpa | D2: 123 | E2: Lukman
A3: 2 | B3: Kepala Bagian Umum | C3: kabag.tu | D3: 123 | E3: Noviyanto
A4: 3 | B4: Pejabat Pembuat Komitmen | C4: ppk | D4: 123 | E4: Asri Fika Agusti
A5: 4 | B5: Ketua Kelompok Kerja Keuangan | C5: pokja.pp | D5: 123 | E5: Elih Ermawati
A6: 5 | B6: Ketua Kelompok Kerja Hukum, Kepegawaian, dan Tata Laksana | C6: pokja.hkt | D6: 123 | E6: Taufan Setyo Pranggono
A7: 6 | B7: Ketua Kelompok Kerja Tata Usaha dan BMN | C7: pokja.tu | D7: 123 | E7: Yan Medya Putri
A8: 7 | B8: Ketua Kelompok Kerja Humas dan Kerjasama | C8: pokja.humas | D8: 123 | E8: Dhita Widya Putri
A9: 8 | B9: Ketua Kelompok Kerja Kelembagaan dan Penjaminan Mutu Eksternal | C9: pokja.kl | D9: 123 | E9: Mulhadi MH
A10: 9 | B10: Ketua Kelompok Kerja Sistem Informasi dan PDDitki | C10: pokja.si | D10: 123 | E10: Titah Widihastuti
A11: 10 | B11: Ketua Kelompok Kerja Pembelajaran dan Kemahasiswaan | C11: pokja.belmawa | D11: 123 | E11: Tri Munanto
A12: 11 | B12: Ketua Kelompok Kerja Pendidik dan Tenaga Kependidikan | C12: pokja.ptk | D12: 123 | E12: Prita Ekasari
A13: 12 | B13: Ketua Kelompok Kerja Riset dan Pengabdian Masyarakat | C13: pokja.riset | D13: 123 | E13: Adhy Purnama
... A28: 27 | B28: PIC Keuangan 6 | C28: pic6 | D28: 123 | E28: Prayitno

Sheet Akun Daf. Nominatif
A1: KODE | B1: DESKRIPSI
A2: 511111 | B2: Belanja Gaji Pokok PNS
A3: 511119 | B3: Belanja Pembulatan Gaji PNS
A4: 511121 | B4: Belanja Tunj. Suami/Istri PNS
A5: 511122 | B5: Belanja Tunj. Anak PNS
A6: 511123 | B6: Belanja Tunj. Struktural PNS
A7: 511124 | B7: Belanja Tunj. Fungsional PNS
A8: 511125 | B8: Belanja Tunj. PPh PNS
A9: 511126 | B9: Belanja Tunj. Beras PNS
A10: 511129 | B10: Belanja Uang Makan PNS
A11: 511151 | B11: Belanja Tunjangan Umum PNS
A12: 511153 | B12: Belanja Tunjangan Profesi Dosen
A13: 511154 | B13: Belanja Tunjangan Kehormatan Profesor
... A17: 521113 | B17: Belanja Penambah Daya Tahan Tubuh
A18: 521115 | B18: Belanja Honor Operasional Satuan Kerja | C18: Daftar Nominatif
A19: 521119 | B19: Belanja Barang Operasional Lainnya
A20: 521131 | B20: Belanja Barang Operasional - Penanganan Pandemi COVID-19
A21: 521211 | B21: Belanja Bahan
A22: 521213 | B22: Belanja Honor Output Kegiatan | C22: Daftar Nominatif
A23: 521219 | B23: Belanja Barang Non Operasional Lainnya
A24: 521811 | B24: Belanja Barang Persediaan Barang Konsumsi
A25: 522111 | B25: Belanja Langganan Listrik
A26: 522112 | B26: Belanja Langganan Telepon
A27: 522113 | B27: Belanja Langganan Air
A28: 522141 | B28: Belanja Sewa
A29: 522151 | B29: Belanja Jasa Profesi | C29: Daftar Nominatif
A30: 522191 | B30: Belanja Jasa Lainnya
A31: 522192 | B31: Belanja Jasa - Penanganan Pandemi COVID-19
A32: 523111 | B32: Belanja Pemeliharaan Gedung dan Bangunan
A33: 523121 | B33: Belanja Pemeliharaan Peralatan dan Mesin
A34: 524111 | B34: Belanja Perjalanan Dinas Biasa | C34: Daftar Nominatif
A35: 524113 | B35: Belanja Perjalanan Dinas Dalam Kota | C35: Daftar Nominatif
A36: 524114 | B36: Belanja Perjalanan Dinas Paket Meeting Dalam Kota | C36: Daftar Nominatif
A37: 524119 | B37: Belanja Perjalanan Dinas Paket Meeting Luar Kota | C37: Daftar Nominatif

Sheet Ref Pegawai
A1: no | B1: nama | C1: nip | D1: nik | E1: npwp | F1: status | G1: gol. ruang | H1: nama rek | I1: no rek | J1: Bank | K1: PPh 21 | L1: Email
A2: 1 | B2: Paristiyanti Nurwardani | C2: 196305071990022001 | D2: 3203014705630016 | E2: 259754364406000 | F2: PNS | G2: IV/d | H2: Ibu PARISTIYANTI NURWARDANI | I2: 1330097022735 | J2: Mandiri | K2: =(IF(LEFT(G2,3)="III","5%",IF(LEFT(G2,3)="NON","2,5%",IF(LEFT(G2,3)="IV/","15%","0%")))) -> 15% | L2: nurwardaniparistiyanti@gmail.com
A3: 1 | B3: Lukman | C3: 197805112003121002 | D3: 3174091105780011 | E3: 641361472017000 | F3: PNS | G3: IV/d | H3: Lukman | K3: =(IF(LEFT(G3,3)="III","5%",IF(LEFT(G3,3)="NON","2,5%",IF(LEFT(G3,3)="IV/","15%","0%")))) -> 15%
A4: 2 | B4: Noviyanto | C4: 198111262008121001 | D4: 3275112611810004 | E4: 253270904432000 | F4: PNS | G4: III/d | H4: NOVIYANTO | I4: 0172856645 | J4: BNI | K4: =(IF(LEFT(G4,3)="III","5%",IF(LEFT(G4,3)="NON","2,5%",IF(LEFT(G4,3)="IV/","15%","0%")))) -> 5% | L4: noviyanto26@gmail.com
A5: 3 | B5: Norsanty | C5: 196411031992032001 | D5: 3276054311640005 | E5: 686766484412000 | F5: PNS | G5: IV/a | H5: ibu NORSANTY | I5: 0436554114 | J5: BNI | K5: =(IF(LEFT(G5,3)="III","5%",IF(LEFT(G5,3)="NON","2,5%",IF(LEFT(G5,3)="IV/","15%","0%")))) -> 15%
A6: 4 | B6: Yulianti AS | C6: 196507041987032001 | D6: 3175094407650003 | E6: 184018083009000 | F6: PNS | G6: IV/a | H6: IBU YULIANTI IRIAWAN, SE | I6: 0008599050 | J6: BNI | K6: =(IF(LEFT(G6,3)="III","5%",IF(LEFT(G6,3)="NON","2,5%",IF(LEFT(G6,3)="IV/","15%","0%")))) -> 15% | L6: yulianti.iriawan@gmail.com
A7: 5 | B7: Sri Mastuti | C7: 196305161989022001 | D7: 3276105605630002 | E7: 688754316072000 | F7: PNS | G7: IV/b | H7: SRI MASTUTI, SKOM | I7: 0008484517 | J7: BNI | K7: =(IF(LEFT(G7,3)="III","5%",IF(LEFT(G7,3)="NON","2,5%",IF(LEFT(G7,3)="IV/","15%","0%")))) -> 15%
A8: 6 | B8: Taufan Setyo Pranggono | C8: 198303162010121006 | D8: 3275051603830019 | E8: 367289113432000 | F8: PNS | G8: III/c | H8: TAUFAN SETYO PRANGGONO, S.KOM | I8: 0221963721 | J8: BNI | K8: =(IF(LEFT(G8,3)="III","5%",IF(LEFT(G8,3)="NON","2,5%",IF(LEFT(G8,3)="IV/","15%","0%")))) -> 5% | L8: taufan.prast@gmail.com
A9: 7 | B9: Agus Muhammad Ali | C9: 197610072008121001 | D9: 3671010710760008 | E9: 253128854416000 | F9: PNS | G9: III/d | H9: Bpk AGUS MUHAMMAD ALI | I9: 0273029029 | J9: BNI | K9: =(IF(LEFT(G9,3)="III","5%",IF(LEFT(G9,3)="NON","2,5%",IF(LEFT(G9,3)="IV/","15%","0%")))) -> 5% | L9: agusnurfauzi1976@gmail.com
A10: 8 | B10: Tri Munanto | C10: 198601212010121003 | D10: 3174102101860003 | E10: 248877086013000 | F10: PNS | G10: III/c | H10: TRI MUNANTO | I10: 0146384615 | J10: BNI | K10: =(IF(LEFT(G10,3)="III","5%",IF(LEFT(G10,3)="NON","2,5%",IF(LEFT(G10,3)="IV/","15%","0%")))) -> 5% | L10: tri.munanto@gmail.com
A11: 9 | B11: Prita Ekasari | C11: 198410142009122008 | D11: 3275035410840016 | E11: 599515301407000 | F11: PNS | G11: III/d | H11: PRITA EKASARI | I11: 0197304242 | J11: BNI | K11: =(IF(LEFT(G11,3)="III","5%",IF(LEFT(G11,3)="NON","2,5%",IF(LEFT(G11,3)="IV/","15%","0%")))) -> 5% | L11: meprita.84@gmail.com
A12: 10 | B12: Lukman Hakim | C12: 198009062008121004 | D12: 3275090609800012 | E12: 253119184071000 | F12: PNS | G12: III/d | H12: LUKMAN HAKIM, S.AK | I12: 0172361108 | J12: BNI | K12: =(IF(LEFT(G12,3)="III","5%",IF(LEFT(G12,3)="NON","2,5%",IF(LEFT(G12,3)="IV/","15%","0%")))) -> 5% | L12: lukman_pdgd@yahoo.com
A13: 11 | B13: Elih Ermawati | C13: 198609152009122006 | D13: 3275085508860013 | E13: 697161602432000 | F13: PNS | G13: III/a | H13: ELIH ERMAWATI | I13: 0197302653 | J13: BNI | K13: =(IF(LEFT(G13,3)="III","5%",IF(LEFT(G13,3)="NON","2,5%",IF(LEFT(G13,3)="IV/","15%","0%")))) -> 5% | L13: elihadnin@gmail.com
A14: 12 | B14: Ikhsan Riyanda | C14: 198303202010121003 | D14: 3275032003830018 | E14: 263956575412000 | F14: PNS | G14: III/c | H14: IKHSAN RIYANDA, SE | I14: 0221957526 | J14: BNI | K14: =(IF(LEFT(G14,3)="III","5%",IF(LEFT(G14,3)="NON","2,5%",IF(LEFT(G14,3)="IV/","15%","0%")))) -> 5% | L14: ikhsanriyanda@yahoo.com
A15: 13 | B15: Titah Widihastuti | C15: 198312302010122003 | D15: 3175107012830004 | E15: 678780578009000 | F15: PNS | G15: III/c | H15: TITAH WIDIHASTUTI | I15: 0218584998 | J15: BNI | K15: =(IF(LEFT(G15,3)="III","5%",IF(LEFT(G15,3)="NON","2,5%",IF(LEFT(G15,3)="IV/","15%","0%")))) -> 5% | L15: titah.widihastuti@gmail.com
A16: 14 | B16: Raafita Agustiana | C16: 198508282010122004 | D16: 3578036808850002 | E16: 255713943615000 | F16: PNS | G16: III/c | H16: RAAFITA AGUSTIANA | I16: 0220706377 | J16: BNI | K16: =(IF(LEFT(G16,3)="III","5%",IF(LEFT(G16,3)="NON","2,5%",IF(LEFT(G16,3)="IV/","15%","0%")))) -> 5% | L16: raafita.tiana@gmail.com
A17: 15 | B17: Mulhadi HM | C17: 199204072015041001 | D17: 7308160704920001 | E17: 737792366005000 | F17: PNS | G17: III/b | H17: MULHADI HM | I17: 0361657840 | J17: BNI | K17: =(IF(LEFT(G17,3)="III","5%",IF(LEFT(G17,3)="NON","2,5%",IF(LEFT(G17,3)="IV/","15%","0%")))) -> 5% | L17: mulhadi92@gmail.com
A18: 16 | B18: Hidayat | C18: 198608012015041003 | D18: 3175090108860009 | E18: 678348889009000 | F18: PNS | G18: III/b | H18: HIDAYAT | I18: 0397801225 | J18: BNI | K18: =(IF(LEFT(G18,3)="III","5%",IF(LEFT(G18,3)="NON","2,5%",IF(LEFT(G18,3)="IV/","15%","0%")))) -> 5% | L18: denny.1886@gmail.com
A19: 17 | B19: Herlina | C19: 197004171992032002 | D19: 3175045704700003 | E19: 688766690005000 | F19: PNS | G19: IV/a | H19: HERLINA | I19: 0307865253 | J19: BNI | K19: =(IF(LEFT(G19,3)="III","5%",IF(LEFT(G19,3)="NON","2,5%",IF(LEFT(G19,3)="IV/","15%","0%")))) -> 15% | L19: Herlinaasoleh@gmail.com
... A49: 47 | B49: Sukiyana | C49: 196812081989021001 | D49: 3175080126800011 | E49: 688766344005000 | F49: PNS | G49: II/c | H49: SUKIYANA | I49: 0008226769 | J49: BNI | K49: =(IF(LEFT(G49,3)="III","5%",IF(LEFT(G49,3)="NON","2,5%",IF(LEFT(G49,3)="IV/","15%","0%")))) -> 0% | L49: sukiyana65@gmail.com
A50: 48 | B50: Virna Pradini Nazhar | C50: 198709042022032004 | D50: 3174094409870004 | E50: 757235478017000 | F50: PNS | G50: III/a | H50: VIRNA PRADINI NAZHAR | I50: 1378321697 | J50: BNI | K50: =(IF(LEFT(G50,3)="III","5%",IF(LEFT(G50,3)="NON","2,5%",IF(LEFT(G50,3)="IV/","15%","0%")))) -> 5%
A51: 49 | B51: Prima Satria | C51: 199110142022031004 | D51: 1306141410910000 | E51: 725386510202000 | F51: PNS | G51: III/a | H51: Sdr PRIMA SATRIA | I51: 0377194961 | J51: BNI | K51: =(IF(LEFT(G51,3)="III","5%",IF(LEFT(G51,3)="NON","2,5%",IF(LEFT(G51,3)="IV/","15%","0%")))) -> 5%
A52: 50 | B52: Almadinda | C52: 199911102022032004 | D52: 3175095011990004 | E52: 651879603009000 | F52: PNS | G52: II/c | H52: Sdri ALMADINDA | I52: 1378321642 | J52: BNI | K52: =(IF(LEFT(G52,3)="III","5%",IF(LEFT(G52,3)="NON","2,5%",IF(LEFT(G52,3)="IV/","15%","0%")))) -> 0%
A53: 51 | B53: Maulani Yasintha | C53: 199707092022032015 | D53: 3175104907970000 | E53: 651919276009000 | F53: PNS | G53: II/c | H53: MAULANI YASINTHA | I53: 1378321675 | J53: BNI | K53: =(IF(LEFT(G53,3)="III","5%",IF(LEFT(G53,3)="NON","2,5%",IF(LEFT(G53,3)="IV/","15%","0%")))) -> 0%
A54: 52 | B54: Antonius Pantun Andika Manurung | C54: 199507282022031010 | D54: 1271032807950006 | E54: 811142959124000 | F54: PNS | G54: II/c | H54: Sdr ANTONIUS PANTUN ANDIKA MANURUNG | I54: 1378321700 | J54: BNI | K54: =(IF(LEFT(G54,3)="III","5%",IF(LEFT(G54,3)="NON","2,5%",IF(LEFT(G54,3)="IV/","15%","0%")))) -> 0%
A55: 53 | B55: Regina Dwi Vania | C55: 199707182022032013 | D55: 3174045807970005 | E55: 869428920017000 | F55: PNS | G55: II/c | H55: REGINA DWI VANIA | I55: 1378321686 | J55: BNI | K55: =(IF(LEFT(G55,3)="III","5%",IF(LEFT(G55,3)="NON","2,5%",IF(LEFT(G55,3)="IV/","15%","0%")))) -> 0%
A56: 54 | B56: Maghfira Syalendri Alqodri | C56: 199610292022032016 | D56: 3171076910960002 | E56: 851647347008000 | F56: PNS | G56: III/a | H56: Sdri MAGHFIRA SYALENDRI ALQADRI | I56: 1374414747 | J56: BNI | K56: =(IF(LEFT(G56,3)="III","5%",IF(LEFT(G56,3)="NON","2,5%",IF(LEFT(G56,3)="IV/","15%","0%")))) -> 5%
A57: 55 | B57: Aprie Wellandira Suhardi | C57: 199804052022032015 | D57: 3174074504980003 | E57: 651878373012000 | F57: PNS | G57: III/a | H57: Sdri APRIE WELLANDIRA SUHARDI | I57: 1378321653 | J57: BNI | K57: =(IF(LEFT(G57,3)="III","5%",IF(LEFT(G57,3)="NON","2,5%",IF(LEFT(G57,3)="IV/","15%","0%")))) -> 5%
A58: 56 | B58: Naorah Putri A | C58: 199806032022032015 | D58: 3215034306980003 | E58: 768808131408000 | F58: PNS | G58: III/a | H58: Sdri NAORAH PUTRI ANGGELIA | I58: 1378321664 | J58: BNI | K58: =(IF(LEFT(G58,3)="III","5%",IF(LEFT(G58,3)="NON","2,5%",IF(LEFT(G58,3)="IV/","15%","0%")))) -> 5%
A59: 57 | B59: Tantri Rinjani | C59: 198609102010012029 | D59: 1672015009860004 | E59: 443839576309000 | F59: PNS | G59: III/c | H59: Ibu Tantri Rinjani | I59: 1596820914 | J59: BNI | K59: =(IF(LEFT(G59,3)="III","5%",IF(LEFT(G59,3)="NON","2,5%",IF(LEFT(G59,3)="IV/","15%","0%")))) -> 5%
A60: 58 | B60: Sutresna Wati | C60: 198807092015042001 | D60: 3275084900788010 | E60: 696020676432000 | F60: PNS | G60: III/b | H60: Sutresna Wati | I60: 0417595642 | J60: BNI | K60: =(IF(LEFT(G60,3)="III","5%",IF(LEFT(G60,3)="NON","2,5%",IF(LEFT(G60,3)="IV/","15%","0%")))) -> 5%
A61: 59 | B61: Siswanto | C61: 196701181992031003 | D61: 3275111801670001 | E61: 092521178407000 | F61: Non PNS | G61: Non PNS | H61: SISWANTO | I61: 0214922525 | J61: BNI | K61: =(IF(LEFT(G61,3)="III","5%",IF(LEFT(G61,3)="NON","2,5%",IF(LEFT(G61,3)="IV/","15%","0%")))) -> 2,5%
... A123: 121 | B123: Setia Abikusna | C123: - | D123: 3201021608720000 | E123: 573986015403000 | F123: Non PNS | G123: Non PNS | H123: Setia Abikusna | I123: 1185415609 | J123: BNI | K123: =(IF(LEFT(G123,3)="III","5%",IF(LEFT(G123,3)="NON","2,5%",IF(LEFT(G123,3)="IV/","15%","0%")))) -> 2,5%
K124: =(IF(LEFT(G124,3)="III","5%",IF(LEFT(G124,3)="NON","2,5%",IF(LEFT(G124,3)="IV/","15%","0%")))) -> 0%
K125: =(IF(LEFT(G125,3)="III","5%",IF(LEFT(G125,3)="NON","2,5%",IF(LEFT(G125,3)="IV/","15%","0%")))) -> 0%
K126: =(IF(LEFT(G126,3)="III","5%",IF(LEFT(G126,3)="NON","2,5%",IF(LEFT(G126,3)="IV/","15%","0%")))) -> 0%
K127: =(IF(LEFT(G127,3)="III","5%",IF(LEFT(G127,3)="NON","2,5%",IF(LEFT(G127,3)="IV/","15%","0%")))) -> 0%
K128: =(IF(LEFT(G128,3)="III","5%",IF(LEFT(G128,3)="NON","2,5%",IF(LEFT(G128,3)="IV/","15%","0%")))) -> 0%
K129: =(IF(LEFT(G129,3)="III","5%",IF(LEFT(G129,3)="NON","2,5%",IF(LEFT(G129,3)="IV/","15%","0%")))) -> 0%
K130: =(IF(LEFT(G130,3)="III","5%",IF(LEFT(G130,3)="NON","2,5%",IF(LEFT(G130,3)="IV/","15%","0%")))) -> 0%
...

Sheet 521111
A1: 521111 Belanja Keperluan Perkantoran
A3: No. | B3: Nama | C3: Uraian Belanja | D3: NPWP | E3: Atas Nama Rekening | F3: Nomor Rekening | G3: Bank | H3: Jumlah | I3: PPN | J3: PPH 22 | K3: PPH 23 | L3: Jumlah di Transfer | M3: Email
A5: A | B5: B | C5: C | D5: D | E5: E | F5: F | G5: G | H5: H | I5: I | J5: J | K5: K | L5: L = G - (H+J+K) | M5: M
A6: 1 | B6: CV. X | D6: =_xlfn.IFNA(VLOOKUP(B6,'Ref Pegawai'!$B$2:$J$123,4,FALSE),"") | F6: =_xlfn.IFNA(VLOOKUP(C6,'Ref Pegawai'!$B$2:$J$123,4,FALSE),"") | H6: 6000000 | I6: 600000 | J6: 9000 | L6: =H6-(I6+J6+K6) -> 5391000
A7: =+A6+1 -> 2 | B7: Toko X | D7: =_xlfn.IFNA(VLOOKUP(B7,'Ref Pegawai'!$B$2:$J$123,4,FALSE),"") | F7: =_xlfn.IFNA(VLOOKUP(C7,'Ref Pegawai'!$B$2:$J$123,4,FALSE),"") | H7: 7000000 | I7: 700000 | K7: =I7*2% -> 14000 | L7: =H7-(I7+J7+K7) -> 6286000
A8: =+A7+1 -> 3 | B8: CV. Y | D8: =_xlfn.IFNA(VLOOKUP(B8,'Ref Pegawai'!$B$2:$J$123,4,FALSE),"") | F8: =_xlfn.IFNA(VLOOKUP(C8,'Ref Pegawai'!$B$2:$J$123,4,FALSE),"") | H8: 8000000 | I8: 800000 | J8: =H8*1.5% -> 120000 | L8: =H8-(I8+J8+K8) -> 7080000
B10: Jumlah
B11: Terbilang :
L13: Jakarta, Februari 2023
A14: Mengetahui/Menyetujui | L14: Lunas dibayar tanggal:
A15: an. Kuasa Pengguna Anggaran | L15: Bendahara Pengeluaran,
A16: Pejabat Pembuat Komitmen
A20: Asri Fika Agusti | L20: Elih Ermawati
A21: NIP. 19708192009122006 | L21: NIP. 19860915 200912 2006

Sheet 521115
A1: Lampiran :
A2: Surat Keputusan Kepala LLDIKTI Wilayah III selaku KPA
A3: Nomor : XXX/LL3/KP.04.01/2023 Tgl 16 Januari 2023
A5: DAFTAR PEMBAYARAN HONORARIUM OPERASIONAL SATUAN KERJA
A6: BULAN XXXX 2023
A7: 521115 Belanja Honor Operasional Satuan Kerja
A9: No. | B9: Nama | C9: NIK | D9: NPWP | E9: Gol | F9: Honorarium | I9: Dasar Pengenaan Pajak (DPP) | J9: PPH 21 | L9: Jumlah Diterima | M9: Atas Nama Rekening | N9: Nomor Rekening | O9: Bank | P9: Email
F10: Jml Keg | G10: Rp./Jam | H10: Jml Bruto | I10: PNS / Non PNS | J10: Tarif ** | K10: Jml Pajak
A11: A | B11: B | C11: C | D11: D | E11: E | F11: F | G11: G | H11: H = F x G | I11: I=H | J11: J | K11: K= ( J x I ) | L11: L = ( H-K ) | M11: M | N11: N | O11: O | P11: P
A12: 1 | B12: Paristiyanti Nurwardani | C12: =_xlfn.IFNA(VLOOKUP(B12,'Ref Pegawai'!$B$2:$J$123,3,FALSE),"") -> 3203014705630016 | D12: =_xlfn.IFNA(VLOOKUP(B12,'Ref Pegawai'!$B$2:$J$123,4,FALSE),"") -> 259754364406000 | E12: =_xlfn.IFNA(VLOOKUP(B12,'Ref Pegawai'!$B$2:$J$123,6,FALSE),"") -> IV/d | F12: 1 | G12: 450000 | H12: =G12*F12 -> 450000 | I12: =+H12 -> 450000 | J12: =_xlfn.IFNA(VLOOKUP(E12,'Ref Pegawai'!$G$2:$K$123,5,FALSE),"") -> 15% | K12: =+J12*I12 -> 67500 | L12: =H12-K12 -> 382500 | M12: =PROPER(VLOOKUP(B12,[13]Ref!$B$2:$P$170,9,FALSE)) -> Paristiyanti Nurwardani | N12: =VLOOKUP(B12,[13]Ref!$B$2:$P$170,10,FALSE) -> 1330097022735 | O12: =PROPER(VLOOKUP(B12,[13]Ref!$B$2:$P$170,11,FALSE)) -> Mandiri | P12: =VLOOKUP(B12,'Ref Pegawai'!$B$2:$L$123,11,FALSE) -> nurwardaniparistiyanti@gmail.com
A13: =+A12+1 -> 2 | B13: Noviyanto | C13: =_xlfn.IFNA(VLOOKUP(B13,'Ref Pegawai'!$B$2:$J$123,3,FALSE),"") -> 3275112611810004 | D13: =_xlfn.IFNA(VLOOKUP(B13,'Ref Pegawai'!$B$2:$J$123,4,FALSE),"") -> 253270904432000 | E13: =_xlfn.IFNA(VLOOKUP(B13,'Ref Pegawai'!$B$2:$J$123,6,FALSE),"") -> III/d | F13: 1 | G13: 400000 | H13: =G13*F13 -> 400000 | I13: =+H13 -> 400000 | J13: =_xlfn.IFNA(VLOOKUP(E13,'Ref Pegawai'!$G$2:$K$123,5,FALSE),"") -> 5% | K13: =+J13*I13 -> 20000 | L13: =H13-K13 -> 380000 | M13: =PROPER(VLOOKUP(B13,[13]Ref!$B$2:$P$170,9,FALSE)) -> Noviyanto | N13: =VLOOKUP(B13,[13]Ref!$B$2:$P$170,10,FALSE) -> 0172856645 | O13: =PROPER(VLOOKUP(B13,[13]Ref!$B$2:$P$170,11,FALSE)) -> Bni | P13: =VLOOKUP(B13,'Ref Pegawai'!$B$2:$L$123,11,FALSE) -> noviyanto26@gmail.com
A14: =+A13+1 -> 3 | B14: Taufan Setyo Pranggono | C14: =_xlfn.IFNA(VLOOKUP(B14,'Ref Pegawai'!$B$2:$J$123,3,FALSE),"") -> 3275051603830019 | D14: =_xlfn.IFNA(VLOOKUP(B14,'Ref Pegawai'!$B$2:$J$123,4,FALSE),"") -> 367289113432000 | E14: =_xlfn.IFNA(VLOOKUP(B14,'Ref Pegawai'!$B$2:$J$123,6,FALSE),"") -> III/c | F14: 1 | G14: 300000 | H14: =G14*F14 -> 300000 | I14: =+H14 -> 300000 | J14: =_xlfn.IFNA(VLOOKUP(E14,'Ref Pegawai'!$G$2:$K$123,5,FALSE),"") -> 5% | K14: =+J14*I14 -> 15000 | L14: =H14-K14 -> 285000 | M14: =PROPER(VLOOKUP(B14,[13]Ref!$B$2:$P$170,9,FALSE)) -> Taufan Setyo Pranggono, S.Kom | N14: =VLOOKUP(B14,[13]Ref!$B$2:$P$170,10,FALSE) -> 0221963721 | O14: =PROPER(VLOOKUP(B14,[13]Ref!$B$2:$P$170,11,FALSE)) -> Bni | P14: =VLOOKUP(B14,'Ref Pegawai'!$B$2:$L$123,11,FALSE) -> taufan.prast@gmail.com
B16: Jumlah | F16: =SUM(F12:F15) -> 3 | G16: =SUBTOTAL(9,G12:G15) -> 1150000 | H16: =SUBTOTAL(9,H12:H15) -> 1150000 | I16: =SUBTOTAL(9,I12:I14) -> 1150000 | J16: 0 | K16: =SUBTOTAL(9,K12:K15) -> 102500 | L16: =SUBTOTAL(9,L12:L15) -> 1047500
B17: Terbilang :
A19: * Sesuai Tarif PPh 21 UU No. 36 Pasal 17 (1)a Tahun 2008 Tentang Pajak Penghasilan
A20: ** Sesua PMK No. 252/PMK/03/2008 Pasal 20 Ayat 1 Tentang Petunjuk Pelaksanaan Pemotongan Pajak atas Penghasilan Sehubungan Pekerjaan, Jasa, dan Kegiatan Orang Pribadi
M22: Jakarta, Februari 2023
A23: Mengetahui/Menyetujui | M23: Lunas dibayar tanggal:
A24: an. Kuasa Pengguna Anggaran | M24: Bendahara Pengeluaran,
A25: Pejabat Pembuat Komitmen
A29: Asri Fika Agusti | M29: Elih Ermawati
A30: NIP. 19708192009122006 | M30: NIP. 19860915 200912 2006

Sheet 521119
A1: 521119 Belanja Barang Operasional Lainnya
A3: No. | B3: Nama | C3: Uraian Belanja | D3: NPWP | E3: Atas Nama Rekening | F3: Nomor Rekening | G3: Bank | H3: Jumlah | I3: PPN | J3: PPH 22 | K3: PPH 23 | L3: Jumlah di Transfer | M3: Email
A5: A | B5: B | C5: C | D5: D | E5: E | F5: F | G5: G | H5: H | I5: I | J5: J | K5: K | L5: L = G - (H+J+K) | M5: M
A6: 1 | B6: CV. X | D6: =_xlfn.IFNA(VLOOKUP(B6,'Ref Pegawai'!$B$2:$J$123,4,FALSE),"") | F6: =_xlfn.IFNA(VLOOKUP(C6,'Ref Pegawai'!$B$2:$J$123,4,FALSE),"") | H6: 6000000 | I6: 600000 | J6: 9000 | L6: =H6-(I6+J6+K6) -> 5391000
A7: =+A6+1 -> 2 | B7: Toko X | D7: =_xlfn.IFNA(VLOOKUP(B7,'Ref Pegawai'!$B$2:$J$123,4,FALSE),"") | F7: =_xlfn.IFNA(VLOOKUP(C7,'Ref Pegawai'!$B$2:$J$123,4,FALSE),"") | H7: 7000000 | I7: 700000 | K7: =I7*2% -> 14000 | L7: =H7-(I7+J7+K7) -> 6286000
A8: =+A7+1 -> 3 | B8: CV. Y | D8: =_xlfn.IFNA(VLOOKUP(B8,'Ref Pegawai'!$B$2:$J$123,4,FALSE),"") | F8: =_xlfn.IFNA(VLOOKUP(C8,'Ref Pegawai'!$B$2:$J$123,4,FALSE),"") | H8: 8000000 | I8: 800000 | J8: =H8*1.5% -> 120000 | L8: =H8-(I8+J8+K8) -> 7080000
B10: Jumlah
B11: Terbilang :
L13: Jakarta, Februari 2023
A14: Mengetahui/Menyetujui | L14: Lunas dibayar tanggal:
A15: an. Kuasa Pengguna Anggaran | L15: Bendahara Pengeluaran,
A16: Pejabat Pembuat Komitmen
A20: Asri Fika Agusti | L20: Elih Ermawati
A21: NIP. 19708192009122006 | L21: NIP. 19860915 200912 2006

Sheet 521211
A1: 521211 Belanja Bahan
A3: No. | B3: Nama | C3: Uraian Belanja | D3: NPWP | E3: Atas Nama Rekening | F3: Nomor Rekening | G3: Bank | H3: Jumlah | I3: PPN | J3: PPH 22 | K3: PPH 23 | L3: Jumlah di Transfer | M3: Email
A5: A | B5: B | C5: C | D5: D | E5: E | F5: F | G5: G | H5: H | I5: I | J5: J | K5: K | L5: L = G - (H+J+K) | M5: M
A6: 1 | B6: CV. X | D6: =_xlfn.IFNA(VLOOKUP(B6,'Ref Pegawai'!$B$2:$J$123,4,FALSE),"") | F6: =_xlfn.IFNA(VLOOKUP(C6,'Ref Pegawai'!$B$2:$J$123,4,FALSE),"") | H6: 6000000 | I6: 600000 | J6: 9000 | L6: =H6-(I6+J6+K6) -> 5391000
A7: =+A6+1 -> 2 | B7: Toko X | D7: =_xlfn.IFNA(VLOOKUP(B7,'Ref Pegawai'!$B$2:$J$123,4,FALSE),"") | F7: =_xlfn.IFNA(VLOOKUP(C7,'Ref Pegawai'!$B$2:$J$123,4,FALSE),"") | H7: 7000000 | I7: 700000 | K7: =I7*2% -> 14000 | L7: =H7-(I7+J7+K7) -> 6286000
A8: =+A7+1 -> 3 | B8: CV. Y | D8: =_xlfn.IFNA(VLOOKUP(B8,'Ref Pegawai'!$B$2:$J$123,4,FALSE),"") | F8: =_xlfn.IFNA(VLOOKUP(C8,'Ref Pegawai'!$B$2:$J$123,4,FALSE),"") | H8: 8000000 | I8: 800000 | J8: =H8*1.5% -> 120000 | L8: =H8-(I8+J8+K8) -> 7080000
B10: Jumlah
B11: Terbilang :
L13: Jakarta, Februari 2023
A14: Mengetahui/Menyetujui | L14: Lunas dibayar tanggal:
A15: an. Kuasa Pengguna Anggaran | L15: Bendahara Pengeluaran,
A16: Pejabat Pembuat Komitmen
A20: Asri Fika Agusti | L20: Elih Ermawati
A21: NIP. 19708192009122006 | L21: NIP. 19860915 200912 2006

Sheet 521213
A1: Lampiran :
A2: Surat Keputusan Kepala LLDIKTI Wilayah III selaku KPA
A3: Nomor : XXX/LL3/KP.04.01/2023 Tgl 16 Januari 2023
A5: DAFTAR PEMBAYARAN HONORARIUM PANITIA
A6: KEGIATAN xxxxxxxxxxxxxxxxxxxxxxxxxxxxxxxxxxxxxxxxxxxxxxxxxxxxxx
A7: DI LINGKUNGAN LEMBAGA LAYANAN PENDIDIKAN TINGGI WILAYAH III JAKARTA TAHUN ANGGARAN 2023
A8: DI LEMBAGA LAYANAN PENDIDIKAN TINGGI WIL III, BEKASI TANGGAL 26 JANUARI 2023
A9: 521213 Belanja Honor Output Kegiatan
A11: No. | B11: Nama | C11: Jabatan Dalam Tugas | D11: NIK | E11: NPWP | F11: Gol | G11: Honorarium | J11: Dasar Pengenaan Pajak (DPP) | K11: PPH 21 | M11: Jumlah Diterima | N11: Atas Nama Rekening | O11: Nomor Rekening | P11: Bank | Q11: Email
G12: Jml Keg | H12: Rp./Jam | I12: Jml Bruto | J12: PNS / Non PNS | K12: Tarif ** | L12: Jml Pajak
A13: A | B13: B | D13: C | E13: D | F13: E | G13: F | H13: G | I13: H = F x G | J13: I=H | K13: J | L13: K= ( J x I ) | M13: L = ( H-K ) | N13: M | O13: N | P13: O | Q13: P
A14: 1 | B14: Paristiyanti Nurwardani | C14: Penanggungjawab | D14: =_xlfn.IFNA(VLOOKUP(B14,'Ref Pegawai'!$B$2:$J$123,3,FALSE),"") -> 3203014705630016 | E14: =_xlfn.IFNA(VLOOKUP(B14,'Ref Pegawai'!$B$2:$J$123,4,FALSE),"") -> 259754364406000 | F14: =_xlfn.IFNA(VLOOKUP(B14,'Ref Pegawai'!$B$2:$J$123,6,FALSE),"") -> IV/d | G14: 1 | H14: 450000 | I14: =H14*G14 -> 450000 | J14: =+I14 -> 450000 | K14: =_xlfn.IFNA(VLOOKUP(F14,'Ref Pegawai'!$G$2:$K$123,5,FALSE),"") -> 15% | L14: =+K14*J14 -> 67500 | M14: =I14-L14 -> 382500 | N14: =PROPER(VLOOKUP(B14,[13]Ref!$B$2:$P$170,9,FALSE)) -> Paristiyanti Nurwardani | O14: =VLOOKUP(B14,[13]Ref!$B$2:$P$170,10,FALSE) -> 1330097022735 | P14: =PROPER(VLOOKUP(B14,[13]Ref!$B$2:$P$170,11,FALSE)) -> Mandiri | Q14: =VLOOKUP(B14,'Ref Pegawai'!$B$2:$L$123,11,FALSE) -> nurwardaniparistiyanti@gmail.com
A15: =+A14+1 -> 2 | B15: Noviyanto | C15: Ketua | D15: =_xlfn.IFNA(VLOOKUP(B15,'Ref Pegawai'!$B$2:$J$123,3,FALSE),"") -> 3275112611810004 | E15: =_xlfn.IFNA(VLOOKUP(B15,'Ref Pegawai'!$B$2:$J$123,4,FALSE),"") -> 253270904432000 | F15: =_xlfn.IFNA(VLOOKUP(B15,'Ref Pegawai'!$B$2:$J$123,6,FALSE),"") -> III/d | G15: 1 | H15: 400000 | I15: =H15*G15 -> 400000 | J15: =+I15 -> 400000 | K15: =_xlfn.IFNA(VLOOKUP(F15,'Ref Pegawai'!$G$2:$K$123,5,FALSE),"") -> 5% | L15: =+K15*J15 -> 20000 | M15: =I15-L15 -> 380000 | N15: =PROPER(VLOOKUP(B15,[13]Ref!$B$2:$P$170,9,FALSE)) -> Noviyanto | O15: =VLOOKUP(B15,[13]Ref!$B$2:$P$170,10,FALSE) -> 0172856645 | P15: =PROPER(VLOOKUP(B15,[13]Ref!$B$2:$P$170,11,FALSE)) -> Bni | Q15: =VLOOKUP(B15,'Ref Pegawai'!$B$2:$L$123,11,FALSE) -> noviyanto26@gmail.com
A16: =+A15+1 -> 3 | B16: Taufan Setyo Pranggono | C16: Wakil Ketua | D16: =_xlfn.IFNA(VLOOKUP(B16,'Ref Pegawai'!$B$2:$J$123,3,FALSE),"") -> 3275051603830019 | E16: =_xlfn.IFNA(VLOOKUP(B16,'Ref Pegawai'!$B$2:$J$123,4,FALSE),"") -> 367289113432000 | F16: =_xlfn.IFNA(VLOOKUP(B16,'Ref Pegawai'!$B$2:$J$123,6,FALSE),"") -> III/c | G16: 1 | H16: 300000 | I16: =H16*G16 -> 300000 | J16: =+I16 -> 300000 | K16: =_xlfn.IFNA(VLOOKUP(F16,'Ref Pegawai'!$G$2:$K$123,5,FALSE),"") -> 5% | L16: =+K16*J16 -> 15000 | M16: =I16-L16 -> 285000 | N16: =PROPER(VLOOKUP(B16,[13]Ref!$B$2:$P$170,9,FALSE)) -> Taufan Setyo Pranggono, S.Kom | O16: =VLOOKUP(B16,[13]Ref!$B$2:$P$170,10,FALSE) -> 0221963721 | P16: =PROPER(VLOOKUP(B16,[13]Ref!$B$2:$P$170,11,FALSE)) -> Bni | Q16: =VLOOKUP(B16,'Ref Pegawai'!$B$2:$L$123,11,FALSE) -> taufan.prast@gmail.com
B18: Jumlah | G18: =SUM(G14:G17) -> 3 | H18: =SUBTOTAL(9,H14:H17) -> 1150000 | I18: =SUBTOTAL(9,I14:I17) -> 1150000 | J18: =SUBTOTAL(9,J14:J16) -> 1150000 | K18: 0 | L18: =SUBTOTAL(9,L14:L17) -> 102500 | M18: =SUBTOTAL(9,M14:M17) -> 1047500
B19: Terbilang : | D19: " | E19: Delapan Juta Empat Ratus Ribu Rupiah
A21: * Sesuai Tarif PPh 21 UU No. 36 Pasal 17 (1)a Tahun 2008 Tentang Pajak Penghasilan
A22: ** Sesua PMK No. 252/PMK/03/2008 Pasal 20 Ayat 1 Tentang Petunjuk Pelaksanaan Pemotongan Pajak atas Penghasilan Sehubungan Pekerjaan, Jasa, dan Kegiatan Orang Pribadi
N24: Jakarta, Februari 2023
A25: Mengetahui/Menyetujui | N25: Lunas dibayar tanggal:
A26: an. Kuasa Pengguna Anggaran | N26: Bendahara Pengeluaran,
A27: Pejabat Pembuat Komitmen
A31: Asri Fika Agusti | N31: Elih Ermawati
A32: NIP. 19708192009122006 | N32: NIP. 19860915 200912 2006

Sheet 521811
A1: 521811 Belanja Barang Persediaan Barang Konsumsi
A3: No. | B3: Nama | C3: Uraian Belanja | D3: NPWP | E3: Atas Nama Rekening | F3: Nomor Rekening | G3: Bank | H3: Jumlah | I3: PPN | J3: PPH 22 | K3: PPH 23 | L3: Jumlah di Transfer | M3: Email
A5: A | B5: B | C5: C | D5: D | E5: E | F5: F | G5: G | H5: H | I5: I | J5: J | K5: K | L5: L = G - (H+J+K) | M5: M
A6: 1 | B6: CV. X | D6: =_xlfn.IFNA(VLOOKUP(B6,'Ref Pegawai'!$B$2:$J$123,4,FALSE),"") | F6: =_xlfn.IFNA(VLOOKUP(C6,'Ref Pegawai'!$B$2:$J$123,4,FALSE),"") | H6: 6000000 | I6: 600000 | J6: 9000 | L6: =H6-(I6+J6+K6) -> 5391000
A7: =+A6+1 -> 2 | B7: Toko X | D7: =_xlfn.IFNA(VLOOKUP(B7,'Ref Pegawai'!$B$2:$J$123,4,FALSE),"") | F7: =_xlfn.IFNA(VLOOKUP(C7,'Ref Pegawai'!$B$2:$J$123,4,FALSE),"") | H7: 7000000 | I7: 700000 | K7: =I7*2% -> 14000 | L7: =H7-(I7+J7+K7) -> 6286000
A8: =+A7+1 -> 3 | B8: CV. Y | D8: =_xlfn.IFNA(VLOOKUP(B8,'Ref Pegawai'!$B$2:$J$123,4,FALSE),"") | F8: =_xlfn.IFNA(VLOOKUP(C8,'Ref Pegawai'!$B$2:$J$123,4,FALSE),"") | H8: 8000000 | I8: 800000 | J8: =H8*1.5% -> 120000 | L8: =H8-(I8+J8+K8) -> 7080000
B10: Jumlah
B11: Terbilang :
L13: Jakarta, Februari 2023
A14: Mengetahui/Menyetujui | L14: Lunas dibayar tanggal:
A15: an. Kuasa Pengguna Anggaran | L15: Bendahara Pengeluaran,
A16: Pejabat Pembuat Komitmen
A20: Asri Fika Agusti | L20: Elih Ermawati
A21: NIP. 19708192009122006 | L21: NIP. 19860915 200912 2006

Sheet 522141
A1: 522141 Belanja Sewa
A3: No. | B3: Nama | C3: Uraian Belanja | D3: NPWP | E3: Atas Nama Rekening | F3: Nomor Rekening | G3: Bank | H3: Jumlah | I3: PPN | J3: PPH 22 | K3: PPH 23 | L3: Jumlah di Transfer | M3: Email
A5: A | B5: B | C5: C | D5: D | E5: E | F5: F | G5: G | H5: H | I5: I | J5: J | K5: K | L5: L = G - (H+J+K) | M5: M
A6: 1 | B6: CV. X | D6: =_xlfn.IFNA(VLOOKUP(B6,'Ref Pegawai'!$B$2:$J$123,4,FALSE),"") | F6: =_xlfn.IFNA(VLOOKUP(C6,'Ref Pegawai'!$B$2:$J$123,4,FALSE),"") | H6: 6000000 | I6: 600000 | J6: 9000 | L6: =H6-(I6+J6+K6) -> 5391000
A7: =+A6+1 -> 2 | B7: Toko X | D7: =_xlfn.IFNA(VLOOKUP(B7,'Ref Pegawai'!$B$2:$J$123,4,FALSE),"") | F7: =_xlfn.IFNA(VLOOKUP(C7,'Ref Pegawai'!$B$2:$J$123,4,FALSE),"") | H7: 7000000 | I7: 700000 | K7: =I7*2% -> 14000 | L7: =H7-(I7+J7+K7) -> 6286000
A8: =+A7+1 -> 3 | B8: CV. Y | D8: =_xlfn.IFNA(VLOOKUP(B8,'Ref Pegawai'!$B$2:$J$123,4,FALSE),"") | F8: =_xlfn.IFNA(VLOOKUP(C8,'Ref Pegawai'!$B$2:$J$123,4,FALSE),"") | H8: 8000000 | I8: 800000 | J8: =H8*1.5% -> 120000 | L8: =H8-(I8+J8+K8) -> 7080000
B10: Jumlah
B11: Terbilang :
L13: Jakarta, Februari 2023
A14: Mengetahui/Menyetujui | L14: Lunas dibayar tanggal:
A15: an. Kuasa Pengguna Anggaran | L15: Bendahara Pengeluaran,
A16: Pejabat Pembuat Komitmen
A20: Asri Fika Agusti | L20: Elih Ermawati
A21: NIP. 19708192009122006 | L21: NIP. 19860915 200912 2006

Sheet 522151
A1: Lampiran :
A2: Surat Keputusan Kepala LLDIKTI Wilayah III selaku KPA
A3: Nomor : XXX/LL3/KP.04.01/2023 Tgl 16 Januari 2023
A5: DAFTAR PEMBAYARAN HONORARIUM NARASUMBER DAN MODERATOR
A6: KEGIATAN xxxxxxxxxxxxxxxxxxxxxxxxxxxxxxxxxxxxxxxxxxxxxxxxxxxxxx
A7: DI LINGKUNGAN LEMBAGA LAYANAN PENDIDIKAN TINGGI WILAYAH III JAKARTA TAHUN ANGGARAN 2023
A8: DI LEMBAGA LAYANAN PENDIDIKAN TINGGI WIL III, BEKASI TANGGAL 26 JANUARI 2023
A9: 522151 Belanja Jasa Profesi
A11: No. | B11: Nama | C11: Jabatan Dalam Tugas | D11: NIK | E11: NPWP | F11: Gol | G11: Honorarium | J11: Dasar Pengenaan Pajak (DPP) | K11: PPH 21 | M11: Jumlah Diterima | N11: Atas Nama Rekening | O11: Nomor Rekening | P11: Bank | Q11: Email
G12: Jml Jam | H12: Rp./Jam | I12: Jml Bruto | J12: PNS / Non PNS | K12: Tarif ** | L12: Jml Pajak
A13: A | B13: B | D13: C | E13: D | F13: E | G13: F | H13: G | I13: H = F x G | J13: I=H | K13: J | L13: K= ( J x I ) | M13: L = ( H-K ) | N13: M | O13: N | P13: O | Q13: P
A14: 1 | B14: Lisye Nurzaman | C14: Narasumber | D14: =_xlfn.IFNA(VLOOKUP(B14,'Ref Pegawai'!$B$2:$J$123,3,FALSE),"") -> 3603176801700003 | E14: =_xlfn.IFNA(VLOOKUP(B14,'Ref Pegawai'!$B$2:$J$123,4,FALSE),"") -> 093100444451001 | F14: =_xlfn.IFNA(VLOOKUP(B14,'Ref Pegawai'!$B$2:$J$123,6,FALSE),"") -> Non PNS | G14: 3 | H14: 1000000 | I14: =H14*G14 -> 3000000 | J14: =+I14 -> 3000000 | K14: =_xlfn.IFNA(VLOOKUP(F14,'Ref Pegawai'!$G$2:$K$123,5,FALSE),"") -> 2,5% | L14: =+K14*J14 -> 75000 | M14: =I14-L14 -> 2925000 | N14: =PROPER(VLOOKUP(B14,[13]Ref!$B$2:$P$170,9,FALSE)) -> Lisye Nurzaman | O14: =VLOOKUP(B14,[13]Ref!$B$2:$P$170,10,FALSE) -> 8840445870 | P14: =PROPER(VLOOKUP(B14,[13]Ref!$B$2:$P$170,11,FALSE)) -> Bca | Q14: =VLOOKUP(B14,'Ref Pegawai'!$B$2:$L$123,11,FALSE) -> 0
A15: =+A14+1 -> 2 | B15: Prof. Dr. E.S. Margianti, S.E., M.M. | C15: Narasumber | D15: =_xlfn.IFNA(VLOOKUP(B15,'Ref Pegawai'!$B$2:$J$123,3,FALSE),"") -> 3276024305540010 | E15: =_xlfn.IFNA(VLOOKUP(B15,'Ref Pegawai'!$B$2:$J$123,4,FALSE),"") -> 055741540412001 | F15: =_xlfn.IFNA(VLOOKUP(B15,'Ref Pegawai'!$B$2:$J$123,6,FALSE),"") -> Non PNS | G15: 3 | H15: 900000 | I15: =H15*G15 -> 2700000 | J15: =+I15 -> 2700000 | K15: =_xlfn.IFNA(VLOOKUP(F15,'Ref Pegawai'!$G$2:$K$123,5,FALSE),"") -> 2,5% | L15: =+K15*J15 -> 67500 | M15: =I15-L15 -> 2632500 | N15: =PROPER(VLOOKUP(B15,[13]Ref!$B$2:$P$170,9,FALSE)) -> Eko Sri Margianti | O15: =VLOOKUP(B15,[13]Ref!$B$2:$P$170,10,FALSE) -> 50220016237 | P15: =PROPER(VLOOKUP(B15,[13]Ref!$B$2:$P$170,11,FALSE)) -> Dki | Q15: =VLOOKUP(B15,'Ref Pegawai'!$B$2:$L$123,11,FALSE) -> 0
A16: =+A15+1 -> 3 | B16: Sutresna Wati | C16: Moderator | D16: =_xlfn.IFNA(VLOOKUP(B16,'Ref Pegawai'!$B$2:$J$123,3,FALSE),"") -> 3275084900788010 | E16: =_xlfn.IFNA(VLOOKUP(B16,'Ref Pegawai'!$B$2:$J$123,4,FALSE),"") -> 696020676432000 | F16: =_xlfn.IFNA(VLOOKUP(B16,'Ref Pegawai'!$B$2:$J$123,6,FALSE),"") -> III/b | G16: 3 | H16: 900000 | I16: =H16*G16 -> 2700000 | J16: =+I16 -> 2700000 | K16: =_xlfn.IFNA(VLOOKUP(F16,'Ref Pegawai'!$G$2:$K$123,5,FALSE),"") -> 5% | L16: =+K16*J16 -> 135000 | M16: =I16-L16 -> 2565000 | N16: =PROPER(VLOOKUP(B16,[13]Ref!$B$2:$P$170,9,FALSE)) -> Sutresna Wati | O16: =VLOOKUP(B16,[13]Ref!$B$2:$P$170,10,FALSE) -> 0417595642 | P16: =PROPER(VLOOKUP(B16,[13]Ref!$B$2:$P$170,11,FALSE)) -> Bni | Q16: =VLOOKUP(B16,'Ref Pegawai'!$B$2:$L$123,11,FALSE) -> 0
B18: Jumlah | G18: =SUM(G14:G17) -> 9 | H18: =SUBTOTAL(9,H14:H17) -> 2800000 | I18: =SUBTOTAL(9,I14:I17) -> 8400000 | J18: =SUBTOTAL(9,J14:J16) -> 8400000 | K18: 0 | L18: =SUBTOTAL(9,L14:L17) -> 277500 | M18: =SUBTOTAL(9,M14:M17) -> 8122500
B19: Terbilang : | D19: " | E19: Delapan Juta Empat Ratus Ribu Rupiah
A21: * Sesuai Tarif PPh 21 UU No. 36 Pasal 17 (1)a Tahun 2008 Tentang Pajak Penghasilan
A22: ** Sesua PMK No. 252/PMK/03/2008 Pasal 20 Ayat 1 Tentang Petunjuk Pelaksanaan Pemotongan Pajak atas Penghasilan Sehubungan Pekerjaan, Jasa, dan Kegiatan Orang Pribadi
N24: Jakarta, Februari 2023
A25: Mengetahui/Menyetujui | N25: Lunas dibayar tanggal:
A26: an. Kuasa Pengguna Anggaran | N26: Bendahara Pengeluaran,
A27: Pejabat Pembuat Komitmen
A31: Asri Fika Agusti | N31: Elih Ermawati
A32: NIP. 19708192009122006 | N32: NIP. 19860915 200912 2006

Sheet 523111
A1: 523111 Belanja Pemeliharaan Gedung dan Bangunan
A3: No. | B3: Nama | C3: Uraian Belanja | D3: NPWP | E3: Atas Nama Rekening | F3: Nomor Rekening | G3: Bank | H3: Jumlah | I3: PPN | J3: PPH 22 | K3: PPH 23 | L3: Jumlah di Transfer | M3: Email
A5: A | B5: B | C5: C | D5: D | E5: E | F5: F | G5: G | H5: H | I5: I | J5: J | K5: K | L5: L = G - (H+J+K) | M5: M
A6: 1 | B6: CV. X | D6: =_xlfn.IFNA(VLOOKUP(B6,'Ref Pegawai'!$B$2:$J$123,4,FALSE),"") | F6: =_xlfn.IFNA(VLOOKUP(C6,'Ref Pegawai'!$B$2:$J$123,4,FALSE),"") | H6: 6000000 | I6: 600000 | J6: 9000 | L6: =H6-(I6+J6+K6) -> 5391000
A7: =+A6+1 -> 2 | B7: Toko X | D7: =_xlfn.IFNA(VLOOKUP(B7,'Ref Pegawai'!$B$2:$J$123,4,FALSE),"") | F7: =_xlfn.IFNA(VLOOKUP(C7,'Ref Pegawai'!$B$2:$J$123,4,FALSE),"") | H7: 7000000 | I7: 700000 | K7: =I7*2% -> 14000 | L7: =H7-(I7+J7+K7) -> 6286000
A8: =+A7+1 -> 3 | B8: CV. Y | D8: =_xlfn.IFNA(VLOOKUP(B8,'Ref Pegawai'!$B$2:$J$123,4,FALSE),"") | F8: =_xlfn.IFNA(VLOOKUP(C8,'Ref Pegawai'!$B$2:$J$123,4,FALSE),"") | H8: 8000000 | I8: 800000 | J8: =H8*1.5% -> 120000 | L8: =H8-(I8+J8+K8) -> 7080000
B10: Jumlah
B11: Terbilang :
L13: Jakarta, Februari 2023
A14: Mengetahui/Menyetujui | L14: Lunas dibayar tanggal:
A15: an. Kuasa Pengguna Anggaran | L15: Bendahara Pengeluaran,
A16: Pejabat Pembuat Komitmen
A20: Asri Fika Agusti | L20: Elih Ermawati
A21: NIP. 19708192009122006 | L21: NIP. 19860915 200912 2006

Sheet 523121
A1: 523121 Belanja Pemeliharaan Peralatan dan Mesin
A3: No. | B3: Nama | C3: Uraian Belanja | D3: NPWP | E3: Atas Nama Rekening | F3: Nomor Rekening | G3: Bank | H3: Jumlah | I3: PPN | J3: PPH 22 | K3: PPH 23 | L3: Jumlah di Transfer | M3: Email
A5: A | B5: B | C5: C | D5: D | E5: E | F5: F | G5: G | H5: H | I5: I | J5: J | K5: K | L5: L = G - (H+J+K) | M5: M
A6: 1 | B6: CV. X | D6: =_xlfn.IFNA(VLOOKUP(B6,'Ref Pegawai'!$B$2:$J$123,4,FALSE),"") | F6: =_xlfn.IFNA(VLOOKUP(C6,'Ref Pegawai'!$B$2:$J$123,4,FALSE),"") | H6: 6000000 | I6: 600000 | J6: 9000 | L6: =H6-(I6+J6+K6) -> 5391000
A7: =+A6+1 -> 2 | B7: Toko X | D7: =_xlfn.IFNA(VLOOKUP(B7,'Ref Pegawai'!$B$2:$J$123,4,FALSE),"") | F7: =_xlfn.IFNA(VLOOKUP(C7,'Ref Pegawai'!$B$2:$J$123,4,FALSE),"") | H7: 7000000 | I7: 700000 | K7: =I7*2% -> 14000 | L7: =H7-(I7+J7+K7) -> 6286000
A8: =+A7+1 -> 3 | B8: CV. Y | D8: =_xlfn.IFNA(VLOOKUP(B8,'Ref Pegawai'!$B$2:$J$123,4,FALSE),"") | F8: =_xlfn.IFNA(VLOOKUP(C8,'Ref Pegawai'!$B$2:$J$123,4,FALSE),"") | H8: 8000000 | I8: 800000 | J8: =H8*1.5% -> 120000 | L8: =H8-(I8+J8+K8) -> 7080000
B10: Jumlah
B11: Terbilang :
L13: Jakarta, Februari 2023
A14: Mengetahui/Menyetujui | L14: Lunas dibayar tanggal:
A15: an. Kuasa Pengguna Anggaran | L15: Bendahara Pengeluaran,
A16: Pejabat Pembuat Komitmen
A20: Asri Fika Agusti | L20: Elih Ermawati
A21: NIP. 19708192009122006 | L21: NIP. 19860915 200912 2006

Sheet 524111
B1: Lampiran :
B2: Surat Tugas Kepala LLDIKTI Wilayah III selaku KPA
B3: Nomor : XXXXXXXXXXXXXX Tgl 16 Januari 2023
B5: DAFTAR PEMBAYARAN TRANSPORT DAN UANG HARIAN PERJALANAN DINAS
B6: KEGIATAN xxxxxxxxxxxxxxxxxxxxxxxxxxxxxxxxxxxxxxxxxxxxxxxxxxxxxx
B7: DI LINGKUNGAN LEMBAGA LAYANAN PENDIDIKAN TINGGI WILAYAH III JAKARTA TAHUN ANGGARAN 2022
B8: DI LEMBAGA LAYANAN PENDIDIKAN TINGGI WIL III, BEKASI TANGGAL 26 JANUARI 2023
B9: 524111 Belanja Perjalanan Dinas Biasa
B11: No | C11: Nama | D11: Transport (Rp.) | E11: Uang Harian Biasa | H11: Uang Harian Fullboard | K11: Uang Harian Fullday | N11: Taksi PP | O11: Tiket Pesawat | P11: Akomodasi Hotel | Q11: Jumlah Diterima (Rp.) | R11: Atas Nama Rekening | S11: Nomor Rekening | T11: Bank | U11: Email
E12: Jml Hari | F12: Satuan | G12: Jumlah | H12: Jml Hari | I12: Satuan | J12: Jumlah | K12: Jml Hari | L12: Satuan | M12: Jumlah
B13: A | C13: B | D13: C | E13: D | F13: E | G13: F = D x E | H13: G | I13: H | J13: I = G x H | K13: J | L13: K | M13: L = J x K | N13: C | O13: C | Q13: M = C + F + I + L | R13: N | S13: O | T13: P | U13: Q
B14: 1 | C14: Noviyanto | D14: 600000 | E14: 1 | F14: 430000 | G14: =E14*F14 -> 430000 | H14: 2 | I14: 150000 | J14: =H14*I14 -> 300000 | K14: 1 | L14: 105000 | M14: =K14*L14 -> 105000 | N14: 550000 | O14: 2500000 | Q14: =D14+G14+J14+M14+N14+O14+P14 -> 4485000 | R14: =PROPER(VLOOKUP(C14,'Ref Pegawai'!$B$2:$J$123,8,FALSE)) -> 0172856645 | S14: =PROPER(VLOOKUP(C14,'Ref Pegawai'!$B$2:$J$123,8,FALSE)) -> 0172856645 | T14: =PROPER(VLOOKUP(C14,'Ref Pegawai'!$B$2:$J$123,9,FALSE)) -> Bni | U14: =VLOOKUP(C14,'Ref Pegawai'!$B$2:$L$123,11,FALSE) -> noviyanto26@gmail.com
B15: =B14+1 -> 2 | C15: Taufan Setyo Pranggono | D15: 600000 | E15: 1 | F15: 430000 | G15: =E15*F15 -> 430000 | H15: 2 | I15: 150000 | J15: =H15*I15 -> 300000 | K15: 1 | L15: 105000 | M15: =K15*L15 -> 105000 | N15: 550000 | O15: 2500000 | Q15: =D15+G15+J15+M15+N15+O15+P15 -> 4485000 | R15: =PROPER(VLOOKUP(C15,'Ref Pegawai'!$B$2:$J$123,8,FALSE)) -> 0221963721 | S15: =PROPER(VLOOKUP(C15,'Ref Pegawai'!$B$2:$J$123,8,FALSE)) -> 0221963721 | T15: =PROPER(VLOOKUP(C15,'Ref Pegawai'!$B$2:$J$123,9,FALSE)) -> Bni | U15: =VLOOKUP(C15,'Ref Pegawai'!$B$2:$L$123,11,FALSE) -> taufan.prast@gmail.com
B16: =B15+1 -> 3 | C16: Agung Permana N | D16: 600000 | E16: 1 | F16: 430000 | G16: =E16*F16 -> 430000 | H16: 2 | I16: 150000 | J16: =H16*I16 -> 300000 | K16: 1 | L16: 105000 | M16: =K16*L16 -> 105000 | N16: 550000 | O16: 2500000 | Q16: =D16+G16+J16+M16+N16+O16+P16 -> 4485000 | R16: =PROPER(VLOOKUP(C16,'Ref Pegawai'!$B$2:$J$123,8,FALSE)) -> 0397880661 | S16: =PROPER(VLOOKUP(C16,'Ref Pegawai'!$B$2:$J$123,8,FALSE)) -> 0397880661 | T16: =PROPER(VLOOKUP(C16,'Ref Pegawai'!$B$2:$J$123,9,FALSE)) -> Bni | U16: =VLOOKUP(C16,'Ref Pegawai'!$B$2:$L$123,11,FALSE) -> endragu@gmail.com
B17: =B16+1 -> 4 | C17: Lukman Hakim | D17: 600000 | E17: 1 | F17: 430000 | G17: =E17*F17 -> 430000 | H17: 2 | I17: 150000 | J17: =H17*I17 -> 300000 | K17: 1 | L17: 105000 | M17: =K17*L17 -> 105000 | N17: 550000 | O17: 2500000 | Q17: =D17+G17+J17+M17+N17+O17+P17 -> 4485000 | R17: =PROPER(VLOOKUP(C17,'Ref Pegawai'!$B$2:$J$123,8,FALSE)) -> 0172361108 | S17: =PROPER(VLOOKUP(C17,'Ref Pegawai'!$B$2:$J$123,8,FALSE)) -> 0172361108 | T17: =PROPER(VLOOKUP(C17,'Ref Pegawai'!$B$2:$J$123,9,FALSE)) -> Bni | U17: =VLOOKUP(C17,'Ref Pegawai'!$B$2:$L$123,11,FALSE) -> lukman_pdgd@yahoo.com
B18: =B17+1 -> 5 | Q18: =D18+G18+J18+M18+N18+O18+P18 -> 0
B19: =B18+1 -> 6 | Q19: =D19+G19+J19+M19+N19+O19+P19 -> 0
B20: =B19+1 -> 7
B45: Jumlah | D45: =SUM(D14:D44) -> 2400000 | E45: =SUM(E14:E44) -> 4 | F45: =SUM(F14:F44) -> 1720000 | G45: =SUM(G14:G44) -> 1720000 | H45: =SUM(H14:H44) -> 8 | I45: =SUM(I14:I44) -> 600000 | J45: =SUM(J14:J44) -> 1200000 | K45: =SUM(K14:K44) -> 4 | ... O45: =SUM(O14:O44) -> 10000000 | Q45: =SUM(Q14:Q44) -> 17940000
B46: Terbilang :
S48: Jakarta, Februari 2023
B49: Mengetahui/Menyetujui | S49: Lunas dibayar tanggal:
B50: an. Kuasa Pengguna Anggaran | S50: Bendahara Pengeluaran,
B51: Pejabat Pembuat Komitmen
B55: Asri Fika Agusti | S55: Elih Ermawati
B56: NIP. 19708192009122006 | S56: NIP. 19860915 200912 2006

Sheet 524113
B1: Lampiran :
B2: Surat Tugas Kepala LLDIKTI Wilayah III selaku KPA
B3: Nomor : XXXXXXXXXXXXXX Tgl 16 Januari 2023
B5: DAFTAR PEMBAYARAN TRANSPORT DAN UANG HARIAN PERJALANAN DINAS
B6: KEGIATAN xxxxxxxxxxxxxxxxxxxxxxxxxxxxxxxxxxxxxxxxxxxxxxxxxxxxxx
B7: DI LINGKUNGAN LEMBAGA LAYANAN PENDIDIKAN TINGGI WILAYAH III JAKARTA TAHUN ANGGARAN 2022
B8: DI LEMBAGA LAYANAN PENDIDIKAN TINGGI WIL III, BEKASI TANGGAL 26 JANUARI 2023
B9: 524113 Belanja Perjalanan Dinas Dalam Kota
B11: No | C11: Nama | D11: Transport (Rp.) | E11: Uang Harian Biasa | H11: Uang Harian Fullboard | K11: Uang Harian Fullday | N11: Akomodasi Hotel | O11: Jumlah Diterima (Rp.) | P11: Atas Nama Rekening | Q11: Nomor Rekening | R11: Bank | S11: Email
E12: Jml Hari | F12: Satuan | G12: Jumlah | H12: Jml Hari | I12: Satuan | J12: Jumlah | K12: Jml Hari | L12: Satuan | M12: Jumlah
B13: A | C13: B | D13: C | E13: D | F13: E | G13: F = D x E | H13: G | I13: H | J13: I = G x H | K13: J | L13: K | M13: L = J x K | O13: M = C + F + I + L | P13: N | Q13: O | R13: P | S13: Q
B14: 1 | C14: Noviyanto | D14: 600000 | E14: 1 | F14: 430000 | G14: =E14*F14 -> 430000 | H14: 2 | I14: 150000 | J14: =H14*I14 -> 300000 | K14: 1 | L14: 105000 | M14: =K14*L14 -> 105000 | O14: =D14+G14+J14+M14+N14 -> 1435000 | P14: =PROPER(VLOOKUP(C14,'Ref Pegawai'!$B$2:$J$123,8,FALSE)) -> 0172856645 | Q14: =PROPER(VLOOKUP(C14,'Ref Pegawai'!$B$2:$J$123,8,FALSE)) -> 0172856645 | R14: =PROPER(VLOOKUP(C14,'Ref Pegawai'!$B$2:$J$123,9,FALSE)) -> Bni | S14: =VLOOKUP(C14,'Ref Pegawai'!$B$2:$L$123,11,FALSE) -> noviyanto26@gmail.com
B15: =B14+1 -> 2 | C15: Taufan Setyo Pranggono | D15: 600000 | E15: 1 | F15: 430000 | G15: =E15*F15 -> 430000 | H15: 2 | I15: 150000 | J15: =H15*I15 -> 300000 | K15: 1 | L15: 105000 | M15: =K15*L15 -> 105000 | O15: =D15+G15+J15+M15+N15 -> 1435000 | P15: =PROPER(VLOOKUP(C15,'Ref Pegawai'!$B$2:$J$123,8,FALSE)) -> 0221963721 | Q15: =PROPER(VLOOKUP(C15,'Ref Pegawai'!$B$2:$J$123,8,FALSE)) -> 0221963721 | R15: =PROPER(VLOOKUP(C15,'Ref Pegawai'!$B$2:$J$123,9,FALSE)) -> Bni | S15: =VLOOKUP(C15,'Ref Pegawai'!$B$2:$L$123,11,FALSE) -> taufan.prast@gmail.com
B16: =B15+1 -> 3 | C16: Agung Permana N | D16: 600000 | E16: 1 | F16: 430000 | G16: =E16*F16 -> 430000 | H16: 2 | I16: 150000 | J16: =H16*I16 -> 300000 | K16: 1 | L16: 105000 | M16: =K16*L16 -> 105000 | O16: =D16+G16+J16+M16+N16 -> 1435000 | P16: =PROPER(VLOOKUP(C16,'Ref Pegawai'!$B$2:$J$123,8,FALSE)) -> 0397880661 | Q16: =PROPER(VLOOKUP(C16,'Ref Pegawai'!$B$2:$J$123,8,FALSE)) -> 0397880661 | R16: =PROPER(VLOOKUP(C16,'Ref Pegawai'!$B$2:$J$123,9,FALSE)) -> Bni | S16: =VLOOKUP(C16,'Ref Pegawai'!$B$2:$L$123,11,FALSE) -> endragu@gmail.com
B17: =B16+1 -> 4 | C17: Lukman Hakim | D17: 600000 | E17: 1 | F17: 430000 | G17: =E17*F17 -> 430000 | H17: 2 | I17: 150000 | J17: =H17*I17 -> 300000 | K17: 1 | L17: 105000 | M17: =K17*L17 -> 105000 | O17: =D17+G17+J17+M17+N17 -> 1435000 | P17: =PROPER(VLOOKUP(C17,'Ref Pegawai'!$B$2:$J$123,8,FALSE)) -> 0172361108 | Q17: =PROPER(VLOOKUP(C17,'Ref Pegawai'!$B$2:$J$123,8,FALSE)) -> 0172361108 | R17: =PROPER(VLOOKUP(C17,'Ref Pegawai'!$B$2:$J$123,9,FALSE)) -> Bni | S17: =VLOOKUP(C17,'Ref Pegawai'!$B$2:$L$123,11,FALSE) -> lukman_pdgd@yahoo.com
B18: =B17+1 -> 5
B19: =B18+1 -> 6
B44: Jumlah | D44: =SUM(D14:D43) -> 2400000 | E44: =SUM(E14:E43) -> 4 | F44: =SUM(F14:F43) -> 1720000 | G44: =SUM(G14:G43) -> 1720000 | H44: =SUM(H14:H43) -> 8 | I44: =SUM(I14:I43) -> 600000 | J44: =SUM(J14:J43) -> 1200000 | K44: =SUM(K14:K43) -> 4 | ... M44: =SUM(M14:M43) -> 420000 | O44: =SUM(O14:O43) -> 5740000
B45: Terbilang :
Q47: Jakarta, Februari 2023
B48: Mengetahui/Menyetujui | Q48: Lunas dibayar tanggal:
B49: an. Kuasa Pengguna Anggaran | Q49: Bendahara Pengeluaran,
B50: Pejabat Pembuat Komitmen
B54: Asri Fika Agusti | Q54: Elih Ermawati
B55: NIP. 19708192009122006 | Q55: NIP. 19860915 200912 2006

Sheet 524114
B1: Lampiran :
B2: Surat Tugas Kepala LLDIKTI Wilayah III selaku KPA
B3: Nomor : XXXXXXXXXXXXXX Tgl 16 Januari 2023
B5: DAFTAR PEMBAYARAN TRANSPORT DAN UANG HARIAN PERJALANAN DINAS
B6: KEGIATAN xxxxxxxxxxxxxxxxxxxxxxxxxxxxxxxxxxxxxxxxxxxxxxxxxxxxxx
B7: DI LINGKUNGAN LEMBAGA LAYANAN PENDIDIKAN TINGGI WILAYAH III JAKARTA TAHUN ANGGARAN 2022
B8: DI LEMBAGA LAYANAN PENDIDIKAN TINGGI WIL III, BEKASI TANGGAL 26 JANUARI 2023
B9: 524114 Belanja Perjalanan Dinas Paket Meeting Dalam Kota
B11: No | C11: Nama | D11: Transport (Rp.) | E11: Uang Harian Biasa | H11: Uang Harian Fullboard | K11: Uang Harian Fullday | N11: Akomodasi Hotel | O11: Jumlah Diterima (Rp.) | P11: Atas Nama Rekening | Q11: Nomor Rekening | R11: Bank | S11: Email
E12: Jml Hari | F12: Satuan | G12: Jumlah | H12: Jml Hari | I12: Satuan | J12: Jumlah | K12: Jml Hari | L12: Satuan | M12: Jumlah
B13: A | C13: B | D13: C | E13: D | F13: E | G13: F = D x E | H13: G | I13: H | J13: I = G x H | K13: J | L13: K | M13: L = J x K | O13: M = C + F + I + L | P13: N | Q13: O | R13: P | S13: Q
B14: 1 | C14: Noviyanto | D14: 600000 | E14: 1 | F14: 430000 | G14: =E14*F14 -> 430000 | H14: 2 | I14: 150000 | J14: =H14*I14 -> 300000 | K14: 1 | L14: 105000 | M14: =K14*L14 -> 105000 | O14: =D14+G14+J14+M14+N14 -> 1435000 | P14: =PROPER(VLOOKUP(C14,'Ref Pegawai'!$B$2:$J$123,8,FALSE)) -> 0172856645 | Q14: =PROPER(VLOOKUP(C14,'Ref Pegawai'!$B$2:$J$123,8,FALSE)) -> 0172856645 | R14: =PROPER(VLOOKUP(C14,'Ref Pegawai'!$B$2:$J$123,9,FALSE)) -> Bni | S14: =VLOOKUP(C14,'Ref Pegawai'!$B$2:$L$123,11,FALSE) -> noviyanto26@gmail.com
B15: =B14+1 -> 2 | C15: Taufan Setyo Pranggono | D15: 600000 | E15: 1 | F15: 430000 | G15: =E15*F15 -> 430000 | H15: 2 | I15: 150000 | J15: =H15*I15 -> 300000 | K15: 1 | L15: 105000 | M15: =K15*L15 -> 105000 | O15: =D15+G15+J15+M15+N15 -> 1435000 | P15: =PROPER(VLOOKUP(C15,'Ref Pegawai'!$B$2:$J$123,8,FALSE)) -> 0221963721 | Q15: =PROPER(VLOOKUP(C15,'Ref Pegawai'!$B$2:$J$123,8,FALSE)) -> 0221963721 | R15: =PROPER(VLOOKUP(C15,'Ref Pegawai'!$B$2:$J$123,9,FALSE)) -> Bni | S15: =VLOOKUP(C15,'Ref Pegawai'!$B$2:$L$123,11,FALSE) -> taufan.prast@gmail.com
B16: =B15+1 -> 3 | C16: Agung Permana N | D16: 600000 | E16: 1 | F16: 430000 | G16: =E16*F16 -> 430000 | H16: 2 | I16: 150000 | J16: =H16*I16 -> 300000 | K16: 1 | L16: 105000 | M16: =K16*L16 -> 105000 | O16: =D16+G16+J16+M16+N16 -> 1435000 | P16: =PROPER(VLOOKUP(C16,'Ref Pegawai'!$B$2:$J$123,8,FALSE)) -> 0397880661 | Q16: =PROPER(VLOOKUP(C16,'Ref Pegawai'!$B$2:$J$123,8,FALSE)) -> 0397880661 | R16: =PROPER(VLOOKUP(C16,'Ref Pegawai'!$B$2:$J$123,9,FALSE)) -> Bni | S16: =VLOOKUP(C16,'Ref Pegawai'!$B$2:$L$123,11,FALSE) -> endragu@gmail.com
B17: =B16+1 -> 4 | C17: Lukman Hakim | D17: 600000 | E17: 1 | F17: 430000 | G17: =E17*F17 -> 430000 | H17: 2 | I17: 150000 | J17: =H17*I17 -> 300000 | K17: 1 | L17: 105000 | M17: =K17*L17 -> 105000 | O17: =D17+G17+J17+M17+N17 -> 1435000 | P17: =PROPER(VLOOKUP(C17,'Ref Pegawai'!$B$2:$J$123,8,FALSE)) -> 0172361108 | Q17: =PROPER(VLOOKUP(C17,'Ref Pegawai'!$B$2:$J$123,8,FALSE)) -> 0172361108 | R17: =PROPER(VLOOKUP(C17,'Ref Pegawai'!$B$2:$J$123,9,FALSE)) -> Bni | S17: =VLOOKUP(C17,'Ref Pegawai'!$B$2:$L$123,11,FALSE) -> lukman_pdgd@yahoo.com
B18: =B17+1 -> 5
B19: =B18+1 -> 6
B44: Jumlah | D44: =SUM(D14:D43) -> 2400000 | E44: =SUM(E14:E43) -> 4 | F44: =SUM(F14:F43) -> 1720000 | G44: =SUM(G14:G43) -> 1720000 | H44: =SUM(H14:H43) -> 8 | I44: =SUM(I14:I43) -> 600000 | J44: =SUM(J14:J43) -> 1200000 | K44: =SUM(K14:K43) -> 4 | ... M44: =SUM(M14:M43) -> 420000 | O44: =SUM(O14:O43) -> 5740000
B45: Terbilang :
Q47: Jakarta, Februari 2023
B48: Mengetahui/Menyetujui | Q48: Lunas dibayar tanggal:
B49: an. Kuasa Pengguna Anggaran | Q49: Bendahara Pengeluaran,
B50: Pejabat Pembuat Komitmen
B54: Asri Fika Agusti | Q54: Elih Ermawati
B55: NIP. 19708192009122006 | Q55: NIP. 19860915 200912 2006

Sheet 524119
B1: Lampiran :
B2: Surat Tugas Kepala LLDIKTI Wilayah III selaku KPA
B3: Nomor : XXXXXXXXXXXXXX Tgl 16 Januari 2023
B5: DAFTAR PEMBAYARAN TRANSPORT DAN UANG HARIAN PERJALANAN DINAS
B6: KEGIATAN xxxxxxxxxxxxxxxxxxxxxxxxxxxxxxxxxxxxxxxxxxxxxxxxxxxxxx
B7: DI LINGKUNGAN LEMBAGA LAYANAN PENDIDIKAN TINGGI WILAYAH III JAKARTA TAHUN ANGGARAN 2022
B8: DI LEMBAGA LAYANAN PENDIDIKAN TINGGI WIL III, BEKASI TANGGAL 26 JANUARI 2023
B9: 524119 Belanja Perjalanan Dinas Paket Meeting Luar Kota
B11: No | C11: Nama | D11: Transport (Rp.) | E11: Uang Harian Biasa | H11: Uang Harian Fullboard | K11: Uang Harian Fullday | N11: Taksi PP | O11: Tiket Pesawat | P11: Akomodasi Hotel | Q11: Jumlah Diterima (Rp.) | R11: Atas Nama Rekening | S11: Nomor Rekening | T11: Bank | U11: Email
E12: Jml Hari | F12: Satuan | G12: Jumlah | H12: Jml Hari | I12: Satuan | J12: Jumlah | K12: Jml Hari | L12: Satuan | M12: Jumlah
B13: A | C13: B | D13: C | E13: D | F13: E | G13: F = D x E | H13: G | I13: H | J13: I = G x H | K13: J | L13: K | M13: L = J x K | N13: C | O13: C | Q13: M = C + F + I + L | R13: N | S13: O | T13: P | U13: Q
B14: 1 | C14: Noviyanto | D14: 600000 | E14: 1 | F14: 430000 | G14: =E14*F14 -> 430000 | H14: 2 | I14: 150000 | J14: =H14*I14 -> 300000 | K14: 1 | L14: 105000 | M14: =K14*L14 -> 105000 | N14: 550000 | O14: 2500000 | Q14: =D14+G14+J14+M14+N14+O14 -> 4485000 | R14: =PROPER(VLOOKUP(C14,'Ref Pegawai'!$B$2:$J$123,8,FALSE)) -> 0172856645 | S14: =PROPER(VLOOKUP(C14,'Ref Pegawai'!$B$2:$J$123,8,FALSE)) -> 0172856645 | T14: =PROPER(VLOOKUP(C14,'Ref Pegawai'!$B$2:$J$123,9,FALSE)) -> Bni | U14: =VLOOKUP(C14,'Ref Pegawai'!$B$2:$L$123,11,FALSE) -> noviyanto26@gmail.com
B15: =B14+1 -> 2 | C15: Taufan Setyo Pranggono | D15: 600000 | E15: 1 | F15: 430000 | G15: =E15*F15 -> 430000 | H15: 2 | I15: 150000 | J15: =H15*I15 -> 300000 | K15: 1 | L15: 105000 | M15: =K15*L15 -> 105000 | N15: 550000 | O15: 2500000 | Q15: =D15+G15+J15+M15+N15+O15 -> 4485000 | R15: =PROPER(VLOOKUP(C15,'Ref Pegawai'!$B$2:$J$123,8,FALSE)) -> 0221963721 | S15: =PROPER(VLOOKUP(C15,'Ref Pegawai'!$B$2:$J$123,8,FALSE)) -> 0221963721 | T15: =PROPER(VLOOKUP(C15,'Ref Pegawai'!$B$2:$J$123,9,FALSE)) -> Bni | U15: =VLOOKUP(C15,'Ref Pegawai'!$B$2:$L$123,11,FALSE) -> taufan.prast@gmail.com
B16: =B15+1 -> 3 | C16: Agung Permana N | D16: 600000 | E16: 1 | F16: 430000 | G16: =E16*F16 -> 430000 | H16: 2 | I16: 150000 | J16: =H16*I16 -> 300000 | K16: 1 | L16: 105000 | M16: =K16*L16 -> 105000 | N16: 550000 | O16: 2500000 | Q16: =D16+G16+J16+M16+N16+O16 -> 4485000 | R16: =PROPER(VLOOKUP(C16,'Ref Pegawai'!$B$2:$J$123,8,FALSE)) -> 0397880661 | S16: =PROPER(VLOOKUP(C16,'Ref Pegawai'!$B$2:$J$123,8,FALSE)) -> 0397880661 | T16: =PROPER(VLOOKUP(C16,'Ref Pegawai'!$B$2:$J$123,9,FALSE)) -> Bni | U16: =VLOOKUP(C16,'Ref Pegawai'!$B$2:$L$123,11,FALSE) -> endragu@gmail.com
B17: =B16+1 -> 4 | C17: Lukman Hakim | D17: 600000 | E17: 1 | F17: 430000 | G17: =E17*F17 -> 430000 | H17: 2 | I17: 150000 | J17: =H17*I17 -> 300000 | K17: 1 | L17: 105000 | M17: =K17*L17 -> 105000 | N17: 550000 | O17: 2500000 | Q17: =D17+G17+J17+M17+N17+O17 -> 4485000 | R17: =PROPER(VLOOKUP(C17,'Ref Pegawai'!$B$2:$J$123,8,FALSE)) -> 0172361108 | S17: =PROPER(VLOOKUP(C17,'Ref Pegawai'!$B$2:$J$123,8,FALSE)) -> 0172361108 | T17: =PROPER(VLOOKUP(C17,'Ref Pegawai'!$B$2:$J$123,9,FALSE)) -> Bni | U17: =VLOOKUP(C17,'Ref Pegawai'!$B$2:$L$123,11,FALSE) -> lukman_pdgd@yahoo.com
B18: =B17+1 -> 5
B19: =B18+1 -> 6
B20: =B19+1 -> 7
B45: Jumlah | D45: =SUM(D14:D44) -> 2400000 | E45: =SUM(E14:E44) -> 4 | F45: =SUM(F14:F44) -> 1720000 | G45: =SUM(G14:G44) -> 1720000 | H45: =SUM(H14:H44) -> 8 | I45: =SUM(I14:I44) -> 600000 | J45: =SUM(J14:J44) -> 1200000 | K45: =SUM(K14:K44) -> 4 | ... O45: =SUM(O14:O44) -> 10000000 | Q45: =SUM(Q14:Q44) -> 17940000
B46: Terbilang :
S48: Jakarta, Februari 2023
B49: Mengetahui/Menyetujui | S49: Lunas dibayar tanggal:
B50: an. Kuasa Pengguna Anggaran | S50: Bendahara Pengeluaran,
B51: Pejabat Pembuat Komitmen
B55: Asri Fika Agusti | S55: Elih Ermawati
B56: NIP. 19708192009122006 | S56: NIP. 19860915 200912 2006

Sheet Perjadin Kolektif-1
A1: Lampiran Surat Perjalanan Dinas
A2: Surat Tugas Kepala LLDIKTI Wilayah III selaku KPA
A3: Nomor : XXX /LL3/TU.02.05/2022 Tanggal. 1 Januari 2023
A5: DAFTAR TIM PADA KEGIATAN XXXXXXXXXXXXXXXXXXXXXXXXXXXXXXXXXXX
A6: DI LINGKUNGAN LEMBAGA LAYANAN PENDIDIKAN TINGGI (LLDIKTI) WILAYAH III
A7: PADA PERIODE XXXXXXXXXXXXXXXXXXXXXXXXXXXXX
A9: No | B9: Nama Pelaksana SPD | C9: NIP | D9: Pangkat | E9: Gol. | F9: Jabatan | G9: Tempat Kedudukan Asal | H9: Tingkat Biaya Perjalanan Dinas | I9: Alat Angkut yang Digunakan | J9: Nomor Surat Tugas | K9: Tanggal Surat Tugas | L9: Tanggal Keberangkatan dari Tempat Kedudukan Asal | M9: Tanggal Tiba Kembali Kedudukan Asal | N9: Lama Perjalanan Dinas (Hari) | O9: Keterangan
A10: 1 | B10: Kardinah Indrianna Meutia, S.Pi., MM | C10: =_xlfn.IFNA(VLOOKUP(B10,'Ref Pegawai'!$B$2:$J$123,2,FALSE),"") -> - | D10: =_xlfn.IFNA(VLOOKUP(B10,'Ref Pegawai'!$B$2:$J$123,5,FALSE),"") -> Non PNS | E10: =_xlfn.IFNA(VLOOKUP(B10,'Ref Pegawai'!$B$2:$J$123,5,FALSE),"") -> Non PNS | F10: Nara Sumber | G10: DKI Jakarta | H10: Tingkat C | I10: Angkutan Umum | J10: XXX /LL3/TU.02.05/2023 | K10: XX Januari 2023 | L10: XX Januari 2023 | M10: 01 Januari 2023 | N10: 2 | O10: Bekasi
A11: =+A10+1 -> 2 | B11: Ika Triana, S.Pd., MM. | C11: =_xlfn.IFNA(VLOOKUP(B11,'Ref Pegawai'!$B$2:$J$123,2,FALSE),"") -> - | D11: =_xlfn.IFNA(VLOOKUP(B11,'Ref Pegawai'!$B$2:$J$123,5,FALSE),"") -> Non PNS | E11: =_xlfn.IFNA(VLOOKUP(B11,'Ref Pegawai'!$B$2:$J$123,5,FALSE),"") -> Non PNS | F11: Nara Sumber | G11: DKI Jakarta | H11: Tingkat C | I11: Angkutan Umum | J11: XXX /LL3/TU.02.05/2023 | K11: XX Januari 2023 | L11: XX Januari 2023 | M11: 01 Januari 2023 | N11: 2 | O11: Bekasi
A12: =+A11+1 -> 3 | B12: Taufan Setyo Pranggono | C12: =_xlfn.IFNA(VLOOKUP(B12,'Ref Pegawai'!$B$2:$J$123,2,FALSE),"") -> 198303162010121006 | D12: =_xlfn.IFNA(VLOOKUP(B12,'Ref Pegawai'!$B$2:$J$123,5,FALSE),"") -> PNS | E12: =_xlfn.IFNA(VLOOKUP(B12,'Ref Pegawai'!$B$2:$J$123,6,FALSE),"") -> III/c | F12: Ketua | G12: DKI Jakarta | H12: Tingkat C | I12: Angkutan Umum | J12: XXX /LL3/TU.02.05/2023 | K12: XX Januari 2023 | L12: XX Januari 2023 | M12: 01 Januari 2023 | N12: 2 | O12: Bekasi
A13: =+A12+1 -> 4 | B13: Agus Muhammad Ali | C13: =_xlfn.IFNA(VLOOKUP(B13,'Ref Pegawai'!$B$2:$J$123,2,FALSE),"") -> 197610072008121001 | D13: =_xlfn.IFNA(VLOOKUP(B13,'Ref Pegawai'!$B$2:$J$123,5,FALSE),"") -> PNS | E13: =_xlfn.IFNA(VLOOKUP(B13,'Ref Pegawai'!$B$2:$J$123,6,FALSE),"") -> III/d | F13: Sekretaris | G13: DKI Jakarta | H13: Tingkat C | I13: Angkutan Umum | J13: XXX /LL3/TU.02.05/2023 | K13: XX Januari 2023 | L13: XX Januari 2023 | M13: 01 Januari 2023 | N13: 2 | O13: Bekasi
A14: =+A13+1 -> 5 | B14: Risma Testir | C14: =_xlfn.IFNA(VLOOKUP(B14,'Ref Pegawai'!$B$2:$J$123,2,FALSE),"") -> 199412132019032022 | D14: =_xlfn.IFNA(VLOOKUP(B14,'Ref Pegawai'!$B$2:$J$123,5,FALSE),"") -> PNS | E14: =_xlfn.IFNA(VLOOKUP(B14,'Ref Pegawai'!$B$2:$J$123,6,FALSE),"") -> II/c | F14: Anggota | G14: DKI Jakarta | H14: Tingkat C | I14: Angkutan Umum | J14: XXX /LL3/TU.02.05/2023 | K14: XX Januari 2023 | L14: XX Januari 2023 | M14: 01 Januari 2023 | N14: 2 | O14: Bekasi
M18: Jakarta, Februari 2023
M19: Pejabat Pembuat Komitmen
M24: Asri Fika Agusti
M25: NIP. 19708192009122006

Sheet SPD-Terlampir
B1: Lembaga Layanan Pendidikan Tinggi Wilayah III Jakarta
B2: Kementerian Pendidikan, Kebudayaan, Riset dan Teknologi | E2: Lembar Ke: | F2: 1 (satu)
B3: Republik Indonesia | E3: Kode No:
E4: Nomor: | F4: /L3/PP/KWT/2023
F5: 2014.994.002.I.524111
B6: SURAT PERJALANAN DINAS (SPD)
B8: 1. | C8: Pejabat Pembuat Komitmen | E8: "terlampir"
